Workbook
Name OLE_LINK1: 'CUADRO 2-EJECUCION DE GASTOS'!#REF!

Sheet CUADRO 1-EJECUCION DE INGRESOS
H1: =+NOW() -> 43522.607 | I1: =+NOW() -> 43522.607
A3: ADMINISTRADORA DE LOS RECURSOS DEL SISTEMA GENERAL DE SEGURIDAD SOCIAL EN SALUD
A4: PRESUPUESTO DE INGRESOS 2019
A5: UNIDAD DE RECURSOS ADMINISTRADOS - URA
A6: CUADRO No. 1
A9: CÓDIGO RUBRO | B9: CONCEPTO DEL RUBRO | C9: AFORO INICIAL | D9: MODIFICACIÓN PRESUPUESTAL | E9: AFORO DEFINITIVO | F9: Ingresos Acumulados Desde 01/01/2019 hasta 01/01/2019 | G9: Ingresos Desde 01/01/2019 hasta 31/01/2019 | H9: Ingresos Acumulados Desde 01/01/2019 hasta 31/01/2019 | I9: EJECUCIÓN ACUMULADA (%)
A10: URA
A11: 0-0-0-0 | B11: DISPONIBILIDAD INICIAL | C11: =+VLOOKUP(A11,ingresos!$A$1:$B$81,2,) -> 422831681000 | D11: =+VLOOKUP(A11,ingresos!$A$1:$F$81,3,FALSE) -> 0 | E11: =+VLOOKUP(A11,ingresos!$A$1:$F$81,4,FALSE) -> 422831681000 | F11: 0 | G11: =+VLOOKUP(A11,ingresos!$A$1:$E$100,5,FALSE) -> 422831681000 | H11: =+G11+F11 -> 422831681000 | I11: =IFERROR(H11/E11*100,0) -> 100
A12: 1-0-0-0 | B12: INGRESOS CORRIENTES | C12: =+C13+C27 -> 52054407755223 | D12: =+D13+D27 -> 0 | E12: =+E13+E27 -> 52054407755223 | F12: 0 | G12: =+G13+G27 -> 4.2522704e+12 | H12: =+G12+F12 -> 4.2522704e+12 | I12: =IFERROR(H12/E12*100,0) -> 8.1688959
A13: 1-2-0-0 | B13: Aportes e Impuestos | C13: =+C14+C26 -> 19781797637181 | D13: =+D14 -> 0 | E13: =+E14+E26 -> 19781797637181 | F13: 0 | G13: =+G14+G26 -> 1.5037638e+12 | H13: =+G13+F13 -> 1.5037638e+12 | I13: =IFERROR(H13/E13*100,0) -> 7.6017552
A14: 1-2-1-0 | B14: Aportes de la Nación | C14: =+C15+C18+C19+C20+C21+C25+C24+C26 -> 19781797637181 | D14: =+D15+D18+D19+D20+D21+D24+D25 -> 0 | E14: =+E15+E18+E19+E20+E21+E25+E24+E26 -> 19781797637181 | F14: 0 | G14: =+G15+G18+G19+G20+G21+G25+G24+G26 -> 1.5037638e+12 | H14: =+G14+F14 -> 1.5037638e+12 | I14: =IFERROR(H14/E14*100,0) -> 7.6017552
A15: 1-2-1-1 | B15: Aportes de la Nación para el Aseguramiento en Salud | C15: =+SUM(C16:C17) -> 17803782346000 | D15: =+D16+D17 -> 0 | E15: =+E16+E17 -> 17803782346000 | F15: 0 | G15: =+SUM(G16:G17) -> 1241981862167 | H15: =+G15+F15 -> 1241981862167 | I15: =IFERROR(H15/E15*100,0) -> 6.9759439
A16: 1-2-1-1-01 | B16: Aportes de la Nación para el Aseguramiento en Salud Cierre | C16: =+VLOOKUP(A16,ingresos!$A$1:$B$81,2,) -> 13686804885516 | D16: =+VLOOKUP(A16,ingresos!$A$1:$F$81,3,FALSE) -> 0 | E16: =+VLOOKUP(A16,ingresos!$A$1:$F$81,4,FALSE) -> 13686804885516 | F16: 0 | G16: =+VLOOKUP(A16,ingresos!$A$1:$E$100,5,FALSE) -> 9.5478383e+11 | H16: =+G16+F16 -> 9.5478383e+11 | I16: =IFERROR(H16/E16*100,0) -> 6.9759439
A17: 1-2-1-1-02 | B17: Imporenta | C17: =+VLOOKUP(A17,ingresos!$A$1:$B$81,2,) -> 4116977460484 | D17: =+VLOOKUP(A17,ingresos!$A$1:$F$81,3,FALSE) -> 0 | E17: =+VLOOKUP(A17,ingresos!$A$1:$F$81,4,FALSE) -> 4116977460484 | F17: 0 | G17: =+VLOOKUP(A17,ingresos!$A$1:$E$100,5,FALSE) -> 2.8719804e+11 | H17: =+G17+F17 -> 2.8719804e+11 | I17: =IFERROR(H17/E17*100,0) -> 6.9759439
A18: 1-2-1-2 | B18: Compensación Regalías para el Régimen Subsidiado | C18: =+VLOOKUP(A18,ingresos!$A$1:$B$81,2,) -> 226673765000 | D18: =+VLOOKUP(A18,ingresos!$A$1:$F$81,3,FALSE) -> 0 | E18: =+VLOOKUP(A18,ingresos!$A$1:$F$81,4,FALSE) -> 226673765000 | F18: 0 | G18: =+VLOOKUP(A18,ingresos!$A$1:$E$100,5,FALSE) -> 0 | H18: =+G18+F18 -> 0 | I18: =IFERROR(H18/E18*100,0) -> 0
A19: 1-2-1-3 | B19: Impuesto sobre la renta para la equidad CREE | C19: =+VLOOKUP(A19,ingresos!$A$1:$B$81,2,) -> 0 | D19: =+VLOOKUP(A19,ingresos!$A$1:$F$81,3,FALSE) -> 0 | E19: =+VLOOKUP(A19,ingresos!$A$1:$F$81,4,FALSE) -> 0 | F19: 0 | G19: =+VLOOKUP(A19,ingresos!$A$1:$E$100,5,FALSE) -> 0 | H19: =+G19+F19 -> 0 | I19: =IFERROR(H19/E19*100,0) -> 0
A20: 1-2-1-4 | B20: SGP FONSAET | C20: =+VLOOKUP(A20,ingresos!$A$1:$B$81,2,) -> 95551523562 | D20: =+VLOOKUP(A20,ingresos!$A$1:$F$81,3,FALSE) -> 0 | E20: =+VLOOKUP(A20,ingresos!$A$1:$F$81,4,FALSE) -> 95551523562 | F20: 0 | G20: =+VLOOKUP(A20,ingresos!$A$1:$E$100,5,FALSE) -> 0 | H20: =+G20+F20 -> 0 | I20: =IFERROR(H20/E20*100,0) -> 0
A21: 1-2-1-5 | B21: PRIMA FONSAT Y CONTRIBUCION SOAT | C21: =+SUM(C22:C23) -> 1640527441000 | D21: =+D22+D23 -> 0 | E21: =+E22+E23 -> 1640527441000 | F21: 0 | G21: =+SUM(G22:G23) -> 2.455599e+11 | H21: =+G21+F21 -> 2.455599e+11 | I21: =IFERROR(H21/E21*100,0) -> 14.968351
A22: 1-2-1-5-01 | B22: % Prima (FONSAT) Decreto Ley 1335 de 2009 | C22: =+VLOOKUP(A22,ingresos!$A$1:$B$81,2,) -> 363281118360 | D22: =+VLOOKUP(A22,ingresos!$A$1:$F$81,3,FALSE) -> 0 | E22: =+VLOOKUP(A22,ingresos!$A$1:$F$81,4,FALSE) -> 363281118360 | F22: 0 | G22: =+VLOOKUP(A22,ingresos!$A$1:$E$100,5,FALSE) -> 7.770565e+10 | H22: =+G22+F22 -> 7.770565e+10 | I22: =IFERROR(H22/E22*100,0) -> 21.38995
A23: 1-2-1-5-02 | B23: Contribución Seguro Obligatorio de Accidentes de Tránsito - SOAT- Decreto Ley 1335 de 2009 | C23: =+VLOOKUP(A23,ingresos!$A$1:$B$81,2,) -> 1277246322640 | D23: =+VLOOKUP(A23,ingresos!$A$1:$F$81,3,FALSE) -> 0 | E23: =+VLOOKUP(A23,ingresos!$A$1:$F$81,4,FALSE) -> 1277246322640 | F23: 0 | G23: =+VLOOKUP(A23,ingresos!$A$1:$E$100,5,FALSE) -> 167854247950 | H23: =+G23+F23 -> 167854247950 | I23: =IFERROR(H23/E23*100,0) -> 13.141885
A24: 1-2-1-7 | B24: Impuesto social a las municiones y explosivos | C24: =+VLOOKUP(A24,ingresos!$A$1:$B$81,2,) -> 6410791000 | D24: =+VLOOKUP(A24,ingresos!$A$1:$F$81,3,FALSE) -> 0 | E24: =+VLOOKUP(A24,ingresos!$A$1:$F$81,4,FALSE) -> 6410791000 | F24: 0 | G24: =+VLOOKUP(A24,ingresos!$A$1:$E$100,5,FALSE) -> 15439498040 | H24: =+G24+F24 -> 15439498040 | I24: =IFERROR(H24/E24*100,0) -> 240.83608
A25: 1-2-1-8 | B25: Impuesto social a las armas | C25: =+VLOOKUP(A25,ingresos!$A$1:$B$81,2,) -> 8851770619 | D25: =+VLOOKUP(A25,ingresos!$A$1:$F$81,3,FALSE) -> 0 | E25: =+VLOOKUP(A25,ingresos!$A$1:$F$81,4,FALSE) -> 8851770619 | F25: 0 | G25: =+VLOOKUP(A25,ingresos!$A$1:$E$100,5,FALSE) -> 782571447 | H25: =+G25+F25 -> 782571447 | I25: =IFERROR(H25/E25*100,0) -> 8.8408464
A26: 1-2-9-0 | B26: Otros aportes e impuestos de la nación | C26: =+VLOOKUP(A26,ingresos!$A$1:$B$81,2,) -> 0 | D26: =+VLOOKUP(A26,ingresos!$A$1:$F$81,3,FALSE) -> 0 | E26: =+VLOOKUP(A26,ingresos!$A$1:$F$81,4,FALSE) -> 0 | F26: 0 | G26: =+VLOOKUP(A26,ingresos!$A$1:$E$100,5,FALSE) -> 0 | H26: =+G26+F26 -> 0 | I26: =IFERROR(H26/E26*100,0) -> 0
A27: 1-3-0-0 | B27: Otros Ingresos Corrientes | C27: =+C28+C56 -> 32272610118042 | D27: =+D28 -> 0 | E27: =+E28+E56 -> 32272610118042 | F27: 0 | G27: =+G28+G56 -> 2.7485066e+12 | H27: =+G27+F27 -> 2.7485066e+12 | I27: =IFERROR(H27/E27*100,0) -> 8.5165301
A28: 1-3-5-0 | B28: Ingresos Sistema General de Seguridad Social en Salud | C28: =+C29+C32+C35+C40+C50+C53 -> 22105255788877 | D28: =+D29+D32+D35+D40+D50+D53 -> 0 | E28: =+E29+E32+E35+E40+E50+E53 -> 22105255788877 | F28: 0 | G28: =+G29+G32+G35+G40+G50+G53 -> 1.918439e+12 | H28: =+G28+F28 -> 1.918439e+12 | I28: =IFERROR(H28/E28*100,0) -> 8.6786555
A29: 1-3-5-1 | B29: Cotizaciones al SGSSS | C29: =+SUM(C30:C31) -> 20346328129563 | D29: =+SUM(D30:D31) -> 0 | E29: =+SUM(E30:E31) -> 20346328129563 | F29: 0 | G29: =+SUM(G30:G31) -> 1706496864866 | H29: =+G29+F29 -> 1706496864866 | I29: =IFERROR(H29/E29*100,0) -> 8.3872473
A30: 1-3-5-1-01 | B30: Régimen Contributivo CSF | C30: =+VLOOKUP(A30,ingresos!$A$1:$B$81,2,) -> 6807438619821 | D30: =+VLOOKUP(A30,ingresos!$A$1:$F$81,3,FALSE) -> 0 | E30: =+VLOOKUP(A30,ingresos!$A$1:$F$81,4,FALSE) -> 6807438619821 | F30: 0 | G30: =+VLOOKUP(A30,ingresos!$A$1:$E$100,5,FALSE) -> 716197711248 | H30: =+G30+F30 -> 716197711248 | I30: =IFERROR(H30/E30*100,0) -> 10.52081
A31: 1-3-5-1-02 | B31: Régimen Contributivo SSF | C31: =+VLOOKUP(A31,ingresos!$A$1:$B$81,2,) -> 13538889509742 | D31: =+VLOOKUP(A31,ingresos!$A$1:$F$81,3,FALSE) -> 0 | E31: =+VLOOKUP(A31,ingresos!$A$1:$F$81,4,FALSE) -> 13538889509742 | F31: 0 | G31: =+VLOOKUP(A31,ingresos!$A$1:$E$100,5,FALSE) -> 990299153618 | H31: =+G31+F31 -> 990299153618 | I31: =IFERROR(H31/E31*100,0) -> 7.3144784
A32: 1-3-5-2 | B32: Aporte Solidaridad de Regímenes de Excepcion y Especiales | C32: =+SUM(C33:C34) -> 1000356775894 | D32: =+SUM(D33:D34) -> 0 | E32: =+SUM(E33:E34) -> 1000356775894 | F32: 0 | G32: =+SUM(G33:G34) -> 6.2818952e+10 | H32: =+G32+F32 -> 6.2818952e+10 | I32: =IFERROR(H32/E32*100,0) -> 6.2796548
A33: 1-3-5-2-01 | B33: Cotizaciones afiliados REX con ingresos adicionales | C33: =+VLOOKUP(A33,ingresos!$A$1:$B$81,2,) -> 594961177882 | D33: =+VLOOKUP(A33,ingresos!$A$1:$F$81,3,FALSE) -> 0 | E33: =+VLOOKUP(A33,ingresos!$A$1:$F$81,4,FALSE) -> 594961177882 | F33: 0 | G33: =+VLOOKUP(A33,ingresos!$A$1:$E$100,5,FALSE) -> 40622846969 | H33: =+G33+F33 -> 40622846969 | I33: =IFERROR(H33/E33*100,0) -> 6.8278147
A34: 1-3-5-2-02 | B34: Aporte Solidario entidades REX | C34: =+VLOOKUP(A34,ingresos!$A$1:$B$81,2,) -> 405395598012 | D34: =+VLOOKUP(A34,ingresos!$A$1:$F$81,3,FALSE) -> 0 | E34: =+VLOOKUP(A34,ingresos!$A$1:$F$81,4,FALSE) -> 405395598012 | F34: 0 | G34: =+VLOOKUP(A34,ingresos!$A$1:$E$100,5,FALSE) -> 2.2196105e+10 | H34: =+G34+F34 -> 2.2196105e+10 | I34: =IFERROR(H34/E34*100,0) -> 5.4751717
A35: 1-3-5-3 | B35: Aportes Cajas de Compensación Familiar | C35: =+SUM(C36:C39) -> 499207099674 | D35: =+SUM(D36:D39) -> 0 | E35: =+SUM(E36:E39) -> 499207099674 | F35: 0 | G35: =+SUM(G36:G39) -> 5.0320072e+10 | H35: =+G35+F35 -> 5.0320072e+10 | I35: =IFERROR(H35/E35*100,0) -> 10.079999
A36: 1-3-5-3-01 | B36: Aportes CCF Artículo 217 Ley 100 de 1993 CSF | C36: =+VLOOKUP(A36,ingresos!$A$1:$B$81,2,) -> 466578060617 | D36: =+VLOOKUP(A36,ingresos!$A$1:$F$81,3,FALSE) -> 0 | E36: =+VLOOKUP(A36,ingresos!$A$1:$F$81,4,FALSE) -> 466578060617 | F36: 0 | G36: =+VLOOKUP(A36,ingresos!$A$1:$E$100,5,FALSE) -> 4.660073e+10 | H36: =+G36+F36 -> 4.660073e+10 | I36: =IFERROR(H36/E36*100,0) -> 9.9877672
A37: 1-3-5-3-02 | B37: Aportes CCF Artículo 217 Ley 100 de 1993 SSF | C37: =+VLOOKUP(A37,ingresos!$A$1:$B$81,2,) -> 28877831435 | D37: =+VLOOKUP(A37,ingresos!$A$1:$F$81,3,FALSE) -> 0 | E37: =+VLOOKUP(A37,ingresos!$A$1:$F$81,4,FALSE) -> 28877831435 | F37: 0 | G37: =+VLOOKUP(A37,ingresos!$A$1:$E$100,5,FALSE) -> 3204560767 | H37: =+G37+F37 -> 3204560767 | I37: =IFERROR(H37/E37*100,0) -> 11.096958
A38: 1-3-5-3-03 | B38: Aportes CCF Balance | C38: =+VLOOKUP(A38,ingresos!$A$1:$B$81,2,) -> 3751207622 | D38: =+VLOOKUP(A38,ingresos!$A$1:$F$81,3,FALSE) -> 0 | E38: =+VLOOKUP(A38,ingresos!$A$1:$F$81,4,FALSE) -> 3751207622 | F38: 0 | G38: =+VLOOKUP(A38,ingresos!$A$1:$E$100,5,FALSE) -> 514780895 | H38: =+G38+F38 -> 514780895 | I38: =IFERROR(H38/E38*100,0) -> 13.723071
A39: 1-3-5-3-04 | B39: Otros Aportes CCF | C39: =+VLOOKUP(A39,ingresos!$A$1:$B$81,2,) -> 0 | D39: =+VLOOKUP(A39,ingresos!$A$1:$F$81,3,FALSE) -> 0 | E39: =+VLOOKUP(A39,ingresos!$A$1:$F$81,4,FALSE) -> 0 | F39: 0 | G39: =+VLOOKUP(A39,ingresos!$A$1:$E$100,5,FALSE) -> 0 | H39: =+G39+F39 -> 0 | I39: =IFERROR(H39/E39*100,0) -> 0
A40: 1-3-5-5 | B40: Reintegros / Recuperaciones | C40: =+SUM(C41:C49) -> 0 | D40: =+SUM(D41:D49) -> 0 | E40: =+SUM(E41:E49) -> 0 | F40: 0 | G40: =+SUM(G41:G49) -> 8.1696375e+10 | H40: =+G40+F40 -> 8.1696375e+10 | I40: =IFERROR(H40/E40*100,0) -> 0
A41: 1-3-5-5-01 | B41: UPC Régimen Contributivo Vigencias anteriores | C41: =+VLOOKUP(A41,ingresos!$A$1:$B$81,2,) -> 0 | D41: =+VLOOKUP(A41,ingresos!$A$1:$F$81,3,FALSE) -> 0 | E41: =+VLOOKUP(A41,ingresos!$A$1:$F$81,4,FALSE) -> 0 | F41: 0 | G41: =+VLOOKUP(A41,ingresos!$A$1:$E$100,5,FALSE) -> 7.3991137e+09 | H41: =+G41+F41 -> 7.3991137e+09 | I41: =IFERROR(H41/E41*100,0) -> 0
A42: 1-3-5-5-02 | B42: P&P Vigencias anteriores | C42: =+VLOOKUP(A42,ingresos!$A$1:$B$81,2,) -> 0 | D42: =+VLOOKUP(A42,ingresos!$A$1:$F$81,3,FALSE) -> 0 | E42: =+VLOOKUP(A42,ingresos!$A$1:$F$81,4,FALSE) -> 0 | F42: 0 | G42: =+VLOOKUP(A42,ingresos!$A$1:$E$100,5,FALSE) -> 0 | H42: =+G42+F42 -> 0 | I42: =IFERROR(H42/E42*100,0) -> 0
A43: 1-3-5-5-03 | B43: Licencias de Maternidad y Paternidad Vigencias anteriores | C43: =+VLOOKUP(A43,ingresos!$A$1:$B$81,2,) -> 0 | D43: =+VLOOKUP(A43,ingresos!$A$1:$F$81,3,FALSE) -> 0 | E43: =+VLOOKUP(A43,ingresos!$A$1:$F$81,4,FALSE) -> 0 | F43: 0 | G43: =+VLOOKUP(A43,ingresos!$A$1:$E$100,5,FALSE) -> 0 | H43: =+G43+F43 -> 0 | I43: =IFERROR(H43/E43*100,0) -> 0
...

Sheet CUADRO 2-EJECUCION DE GASTOS
M1: =+TODAY() -> 43522 | N1: =+NOW() -> 43522.607
A3: ADMINISTRADORA DE LOS RECURSOS DEL SISTEMA GENERAL DE SEGURIDAD SOCIAL EN SALUD
A4: PRESUPUESTO DE GASTOS 2019
A5: UNIDAD DE RECURSOS ADMINISTRADOS - URA
A6: CUADRO No. 2
A9: CÓDIGO RUBRO | B9: CONCEPTO DEL RUBRO | C9: APROPIACIÓN DEFINITIVA | D9: EJECUCION PRESUPUESTAL ACUMULADA DESDE 01/01/2019 HASTA 31/01/2019 | G9: EJECUCION PRESUPUESTAL DESDE 01/01/2019 HASTA 31/01/2019 | J9: EJECUCION PRESUPUESTAL ACUMULADA DESDE 01/01/2019 HASTA 31/01/2019 | M9: %
D10: T. CDP | E10: T. RP | F10: T. PAGOS-OP | G10: CDP | H10: RP | I10: PAGOS-OP | J10: T. CDP | K10: T. RP | L10: T. PAGOS-OP | M10: RP | N10: OP
B11: URA
A12: A-3-0-0-0 | B12: TRANSFERENCIAS | C12: =+C13+C18+C24 -> 52382816715223 | D12: 0 | E12: 0 | F12: 0 | G12: =+G13+G18+G24 -> 4.1486636e+12 | H12: =+H13+H18+H24 -> 3.9911398e+12 | I12: =+I13+I18+I24 -> 3.9911398e+12 | J12: =+G12+D12 -> 4.1486636e+12 | K12: =+H12+E12 -> 3.9911398e+12 | L12: =+I12+F12 -> 3.9911398e+12 | M12: =+IFERROR(K12*100/C12,0) -> 7.6191776 | N12: =+IFERROR(L12*100/C12,0) -> 7.6191776
A13: A-3-2-0-0 | B13: TRANSFERENCIAS AL SECTOR PUBLICO | C13: =+C14+C16 -> 231725030430 | D13: 0 | E13: 0 | F13: 0 | G13: =+G14+G16 -> 145380000000 | H13: =+H14+H16 -> 4.166544e+09 | I13: =+I14+I16 -> 4.166544e+09 | J13: =+G13+D13 -> 145380000000 | K13: =+H13+E13 -> 4.166544e+09 | L13: =+I13+F13 -> 4.166544e+09 | M13: =+IFERROR(K13*100/C13,0) -> 1.7980552 | N13: =+IFERROR(L13*100/C13,0) -> 1.7980552
A14: A-3-2-1-0 | B14: Transferencias Entidades de Administración Pública Central | C14: =+C15 -> 86345030430 | D14: =+D15 -> 0 | E14: =+E15 -> 0 | F14: =+F15 -> 0 | G14: =+G15 -> 0 | H14: =+H15 -> 0 | I14: =+I15 -> 0 | J14: =+J15 -> 0 | ... L14: =+L15 -> 0 | M14: =+IFERROR(K14*100/C14,0) -> 0 | N14: =+IFERROR(L14*100/C14,0) -> 0
A15: A-3-2-1-01 | B15: Contribución IVC Superintendencia Nacional de Salud | C15: =+VLOOKUP(A15,gasto!$A$4:$F$68,3,FALSE) -> 86345030430 | D15: 0 | E15: 0 | F15: 0 | G15: =+VLOOKUP(A15,gasto!$A$4:$F$68,4,FALSE) -> 0 | H15: =+VLOOKUP(A15,gasto!$A$4:$F$68,5,FALSE) -> 0 | I15: =+VLOOKUP(A15,gasto!$A$4:$F$68,6,FALSE) -> 0 | J15: =+G15+D15 -> 0 | K15: =+H15+E15 -> 0 | L15: =+I15+F15 -> 0 | M15: =+IFERROR(K15*100/C15,0) -> 0 | N15: =+IFERROR(L15*100/C15,0) -> 0
A16: A-3-2-2-0 | B16: Empresas Públicas Nacionales no financieras -ADRES | C16: =+C17 -> 145380000000 | D16: =+D17 -> 0 | E16: =+E17 -> 0 | F16: =+F17 -> 0 | G16: =+G17 -> 145380000000 | H16: =+H17 -> 4.166544e+09 | I16: =+I17 -> 4.166544e+09 | J16: =+J17 -> 145380000000 | ... L16: =+L17 -> 4.166544e+09 | M16: =+IFERROR(K16*100/C16,0) -> 2.8659678 | N16: =+IFERROR(L16*100/C16,0) -> 2.8659678
A17: A-3-2-2-0-01 | B17: Aportes hasta del 0,5% recursos CSF para el desarrollo objeto ADRES | C17: =+VLOOKUP(A17,gasto!$A$4:$F$68,3,FALSE) -> 145380000000 | D17: 0 | E17: 0 | F17: 0 | G17: =+VLOOKUP(A17,gasto!$A$4:$F$68,4,FALSE) -> 145380000000 | H17: =+VLOOKUP(A17,gasto!$A$4:$F$68,5,FALSE) -> 4.166544e+09 | I17: =+VLOOKUP(A17,gasto!$A$4:$F$68,6,FALSE) -> 4.166544e+09 | J17: =+G17+D17 -> 145380000000 | K17: =+H17+E17 -> 4.166544e+09 | L17: =+I17+F17 -> 4.166544e+09 | M17: =+IFERROR(K17*100/C17,0) -> 2.8659678 | N17: =+IFERROR(L17*100/C17,0) -> 2.8659678
A18: A-3-6-0-0 | B18: OTRAS TRANSFERENCIAS | C18: =+C19+C22 -> 180000000000 | D18: 0 | E18: 0 | F18: 0 | G18: =+G19+G22 -> 1656232 | H18: =+H19+H22 -> 0 | I18: =+I19+I22 -> 0 | J18: =+G18+D18 -> 1656232 | K18: =+H18+E18 -> 0 | L18: =+I18+F18 -> 0 | M18: =+IFERROR(K18*100/C18,0) -> 0 | N18: =+IFERROR(L18*100/C18,0) -> 0
A19: A-3-6-1-0 | B19: Sentencias y Conciliaciones URA | C19: =+SUM(C20:C21) -> 20000000000 | D19: =+SUM(D20:D21) -> 0 | E19: =+SUM(E20:E21) -> 0 | F19: =+SUM(F20:F21) -> 0 | G19: =+SUM(G20:G21) -> 1656232 | H19: =+SUM(H20:H21) -> 0 | I19: =+SUM(I20:I21) -> 0 | J19: =+SUM(J20:J21) -> 1656232 | ... L19: =+SUM(L20:L21) -> 0 | M19: =+IFERROR(K19*100/C19,0) -> 0 | N19: =+IFERROR(L19*100/C19,0) -> 0
A20: A-3-6-1-1 | B20: Sentencias URA | C20: =+VLOOKUP(A20,gasto!$A$4:$F$68,3,FALSE) -> 20000000000 | D20: 0 | E20: 0 | F20: 0 | G20: =+VLOOKUP(A20,gasto!$A$4:$F$68,4,FALSE) -> 1656232 | H20: =+VLOOKUP(A20,gasto!$A$4:$F$68,5,FALSE) -> 0 | I20: =+VLOOKUP(A20,gasto!$A$4:$F$68,6,FALSE) -> 0 | J20: =+G20+D20 -> 1656232 | K20: =+H20+E20 -> 0 | L20: =+I20+F20 -> 0 | M20: =+IFERROR(K20*100/C20,0) -> 0 | N20: =+IFERROR(L20*100/C20,0) -> 0
A21: A-3-6-1-2 | B21: Conciliaciones URA | C21: =+VLOOKUP(A21,gasto!$A$4:$F$68,3,FALSE) -> 0 | D21: 0 | E21: 0 | F21: 0 | G21: =+VLOOKUP(A21,gasto!$A$4:$F$68,4,FALSE) -> 0 | H21: =+VLOOKUP(A21,gasto!$A$4:$F$68,5,FALSE) -> 0 | I21: =+VLOOKUP(A21,gasto!$A$4:$F$68,6,FALSE) -> 0 | J21: =+G21+D21 -> 0 | K21: =+H21+E21 -> 0 | L21: =+I21+F21 -> 0 | M21: =+IFERROR(K21*100/C21,0) -> 0 | N21: =+IFERROR(L21*100/C21,0) -> 0
A22: A-3-6-3-0 | B22: Destinatarios de otras transferencias Corrientes - Compensación Chance | C22: =+C23 -> 160000000000 | D22: =+D23 -> 0 | E22: =+E23 -> 0 | F22: =+F23 -> 0 | G22: =+G23 -> 0 | H22: =+H23 -> 0 | I22: =+I23 -> 0 | J22: =+J23 -> 0 | ... L22: =+L23 -> 0 | M22: =+IFERROR(K22*100/C22,0) -> 0 | N22: =+IFERROR(L22*100/C22,0) -> 0
A23: A-3-6-3-0-01 | B23: Otras transferencias - Compensación del Chance Decreto 2550/12 | C23: =+VLOOKUP(A23,gasto!$A$4:$F$68,3,FALSE) -> 160000000000 | D23: 0 | E23: 0 | F23: 0 | G23: =+VLOOKUP(A23,gasto!$A$4:$F$68,4,FALSE) -> 0 | H23: =+VLOOKUP(A23,gasto!$A$4:$F$68,5,FALSE) -> 0 | I23: =+VLOOKUP(A23,gasto!$A$4:$F$68,6,FALSE) -> 0 | J23: =+G23+D23 -> 0 | K23: =+H23+E23 -> 0 | L23: =+I23+F23 -> 0 | M23: =+IFERROR(K23*100/C23,0) -> 0 | N23: =+IFERROR(L23*100/C23,0) -> 0
A24: A-3-9-0-0 | B24: ADMINISTRACIÓN DE RECURSOS DEL SGSSS | C24: =+C25+C30+C33+C36+C37+C38+C42+C45+C52+C56+C66+C77+C79+C81 -> 51971091684793 | D24: 0 | E24: 0 | F24: 0 | G24: =+G25+G30+G33+G36+G37+G38+G42+G45+G52+G56+G66+G77+G79+G81 -> 4.003282e+12 | H24: =+H25+H30+H33+H36+H37+H38+H42+H45+H52+H56+H66+H77+H79+H81 -> 3.9869733e+12 | I24: =+I25+I30+I33+I36+I37+I38+I42+I45+I52+I56+I66+I77+I79+I81 -> 3.9869733e+12 | J24: =+G24+D24 -> 4.003282e+12 | K24: =+H24+E24 -> 3.9869733e+12 | L24: =+I24+F24 -> 3.9869733e+12 | M24: =+IFERROR(K24*100/C24,0) -> 7.6715211 | N24: =+IFERROR(L24*100/C24,0) -> 7.6715211
A25: A-3-9-1-0 | B25: UPC Régimen Contributivo | C25: =+SUM(C26:C29) -> 23057892632980 | D25: =+SUM(D26:D29) -> 0 | E25: =+SUM(E26:E29) -> 0 | F25: =+SUM(F26:F29) -> 0 | G25: =+SUM(G26:G29) -> 1825601270168 | H25: =+SUM(H26:H29) -> 1825601270168 | I25: =+SUM(I26:I29) -> 1825601270168 | J25: =+SUM(J26:J29) -> 1825601270168 | ... L25: =+SUM(L26:L29) -> 1825601270168 | M25: =+IFERROR(K25*100/C25,0) -> 7.917468 | N25: =+IFERROR(L25*100/C25,0) -> 7.917468
A26: A-3-9-1-0-01 | B26: UPC Régimen Contributivo SSF | C26: =+VLOOKUP(A26,gasto!$A$4:$F$68,3,FALSE) -> 12399109660289 | D26: 0 | E26: 0 | F26: 0 | G26: =+VLOOKUP(A26,gasto!$A$4:$F$68,4,FALSE) -> 910942673794 | H26: =+VLOOKUP(A26,gasto!$A$4:$F$68,5,FALSE) -> 910942673794 | I26: =+VLOOKUP(A26,gasto!$A$4:$F$68,6,FALSE) -> 910942673794 | J26: =+G26+D26 -> 910942673794 | K26: =+H26+E26 -> 910942673794 | L26: =+I26+F26 -> 910942673794 | M26: =+IFERROR(K26*100/C26,0) -> 7.3468394 | N26: =+IFERROR(L26*100/C26,0) -> 7.3468394
A27: A-3-9-1-0-02 | B27: UPC Régimen Contributivo CSF | C27: =+VLOOKUP(A27,gasto!$A$4:$F$68,3,FALSE) -> 10647939289644 | D27: 0 | E27: 0 | F27: 0 | G27: =+VLOOKUP(A27,gasto!$A$4:$F$68,4,FALSE) -> 914297953268 | H27: =+VLOOKUP(A27,gasto!$A$4:$F$68,5,FALSE) -> 914297953268 | I27: =+VLOOKUP(A27,gasto!$A$4:$F$68,6,FALSE) -> 914297953268 | J27: =+G27+D27 -> 914297953268 | K27: =+H27+E27 -> 914297953268 | L27: =+I27+F27 -> 914297953268 | M27: =+IFERROR(K27*100/C27,0) -> 8.5866188 | N27: =+IFERROR(L27*100/C27,0) -> 8.5866188
A28: A-3-9-1-0-03 | B28: Devolución aportes y cotizaciones no conciliadas vigencia anterior | C28: =+VLOOKUP(A28,gasto!$A$4:$F$68,3,FALSE) -> 10223147816 | D28: 0 | E28: 0 | F28: 0 | G28: =+VLOOKUP(A28,gasto!$A$4:$F$68,4,FALSE) -> 360643106 | H28: =+VLOOKUP(A28,gasto!$A$4:$F$68,5,FALSE) -> 360643106 | I28: =+VLOOKUP(A28,gasto!$A$4:$F$68,6,FALSE) -> 360643106 | J28: =+G28+D28 -> 360643106 | K28: =+H28+E28 -> 360643106 | L28: =+I28+F28 -> 360643106 | M28: =+IFERROR(K28*100/C28,0) -> 3.527711 | N28: =+IFERROR(L28*100/C28,0) -> 3.527711
A29: A-3-9-1-0-04 | B29: Rendimientos Financieros de los Saldos no Compensados de los Aportes Patronales según Art. 12 Decreto 1636 de 2016 | C29: =+VLOOKUP(A29,gasto!$A$4:$F$68,3,FALSE) -> 620535231 | D29: 0 | E29: 0 | F29: 0 | G29: =+VLOOKUP(A29,gasto!$A$4:$F$68,4,FALSE) -> 0 | H29: =+VLOOKUP(A29,gasto!$A$4:$F$68,5,FALSE) -> 0 | I29: =+VLOOKUP(A29,gasto!$A$4:$F$68,6,FALSE) -> 0 | J29: =+G29+D29 -> 0 | K29: =+H29+E29 -> 0 | L29: =+I29+F29 -> 0 | M29: =+IFERROR(K29*100/C29,0) -> 0 | N29: =+IFERROR(L29*100/C29,0) -> 0
A30: A-3-9-2-0 | B30: Per capita Programas de Promoción y Prevención R.C | C30: =+SUM(C31:C32) -> 646778600953 | D30: =+SUM(D31:D32) -> 0 | E30: =+SUM(E31:E32) -> 0 | F30: =+SUM(F31:F32) -> 0 | G30: =+SUM(G31:G32) -> 41852875331 | H30: =+SUM(H31:H32) -> 41852875331 | I30: =+SUM(I31:I32) -> 41852875331 | J30: =+SUM(J31:J32) -> 41852875331 | ... L30: =+SUM(L31:L32) -> 41852875331 | M30: =+IFERROR(K30*100/C30,0) -> 6.470974 | N30: =+IFERROR(L30*100/C30,0) -> 6.470974
A31: A-3-9-2-0-01 | B31: Per capita Programas de Promoción y Prevención R.C SSF | C31: =+VLOOKUP(A31,gasto!$A$4:$F$68,3,FALSE) -> 510526042986 | D31: 0 | E31: 0 | F31: 0 | G31: =+VLOOKUP(A31,gasto!$A$4:$F$68,4,FALSE) -> 31541610651 | H31: =+VLOOKUP(A31,gasto!$A$4:$F$68,5,FALSE) -> 31541610651 | I31: =+VLOOKUP(A31,gasto!$A$4:$F$68,6,FALSE) -> 31541610651 | J31: =+G31+D31 -> 31541610651 | K31: =+H31+E31 -> 31541610651 | L31: =+I31+F31 -> 31541610651 | M31: =+IFERROR(K31*100/C31,0) -> 6.1782569 | N31: =+IFERROR(L31*100/C31,0) -> 6.1782569
A32: A-3-9-2-0-02 | B32: Per capita Programas de Promoción y Prevención R.C CSF | C32: =+VLOOKUP(A32,gasto!$A$4:$F$68,3,FALSE) -> 136252557967 | D32: 0 | E32: 0 | F32: 0 | G32: =+VLOOKUP(A32,gasto!$A$4:$F$68,4,FALSE) -> 10311264680 | H32: =+VLOOKUP(A32,gasto!$A$4:$F$68,5,FALSE) -> 10311264680 | I32: =+VLOOKUP(A32,gasto!$A$4:$F$68,6,FALSE) -> 10311264680 | J32: =+G32+D32 -> 10311264680 | K32: =+H32+E32 -> 10311264680 | L32: =+I32+F32 -> 10311264680 | M32: =+IFERROR(K32*100/C32,0) -> 7.5677586 | N32: =+IFERROR(L32*100/C32,0) -> 7.5677586
A33: A-3-9-3-0 | B33: Incapacidades | C33: =+SUM(C34:C35) -> 814461941941 | D33: =+SUM(D34:D35) -> 0 | E33: =+SUM(E34:E35) -> 0 | F33: =+SUM(F34:F35) -> 0 | G33: =+SUM(G34:G35) -> 67741191373 | H33: =+SUM(H34:H35) -> 67741191373 | I33: =+SUM(I34:I35) -> 67741191373 | J33: =+SUM(J34:J35) -> 67741191373 | ... L33: =+SUM(L34:L35) -> 67741191373 | M33: =+IFERROR(K33*100/C33,0) -> 8.3172936 | N33: =+IFERROR(L33*100/C33,0) -> 8.3172936
A34: A-3-9-3-0-01 | B34: Incapacidades SSF | C34: =+VLOOKUP(A34,gasto!$A$4:$F$68,3,FALSE) -> 629253806467 | D34: 0 | E34: 0 | F34: 0 | G34: =+VLOOKUP(A34,gasto!$A$4:$F$68,4,FALSE) -> 47814869173 | H34: =+VLOOKUP(A34,gasto!$A$4:$F$68,5,FALSE) -> 47814869173 | I34: =+VLOOKUP(A34,gasto!$A$4:$F$68,6,FALSE) -> 47814869173 | J34: =+G34+D34 -> 47814869173 | K34: =+H34+E34 -> 47814869173 | L34: =+I34+F34 -> 47814869173 | M34: =+IFERROR(K34*100/C34,0) -> 7.5986619 | N34: =+IFERROR(L34*100/C34,0) -> 7.5986619
A35: A-3-9-3-0-02 | B35: Incapacidades CSF | C35: =+VLOOKUP(A35,gasto!$A$4:$F$68,3,FALSE) -> 185208135474 | D35: 0 | E35: 0 | F35: 0 | G35: =+VLOOKUP(A35,gasto!$A$4:$F$68,4,FALSE) -> 19926322200 | H35: =+VLOOKUP(A35,gasto!$A$4:$F$68,5,FALSE) -> 19926322200 | I35: =+VLOOKUP(A35,gasto!$A$4:$F$68,6,FALSE) -> 19926322200 | J35: =+G35+D35 -> 19926322200 | K35: =+H35+E35 -> 19926322200 | L35: =+I35+F35 -> 19926322200 | M35: =+IFERROR(K35*100/C35,0) -> 10.758881 | N35: =+IFERROR(L35*100/C35,0) -> 10.758881
A36: A-3-9-4-0 | B36: Licencias de Maternidad y Paternidad | C36: =+VLOOKUP(A36,gasto!$A$4:$F$68,3,FALSE) -> 838554045453 | D36: 0 | E36: 0 | F36: 0 | G36: =+VLOOKUP(A36,gasto!$A$4:$F$68,4,FALSE) -> 67879430670 | H36: =+VLOOKUP(A36,gasto!$A$4:$F$68,5,FALSE) -> 67879430670 | I36: =+VLOOKUP(A36,gasto!$A$4:$F$68,6,FALSE) -> 67879430670 | J36: =+G36+D36 -> 67879430670 | K36: =+H36+E36 -> 67879430670 | L36: =+I36+F36 -> 67879430670 | M36: =+IFERROR(K36*100/C36,0) -> 8.0948188 | N36: =+IFERROR(L36*100/C36,0) -> 8.0948188
A37: A-3-9-5-0 | B37: Prestaciones Económicas Regímenes Especial y de Excepción | C37: =+VLOOKUP(A37,gasto!$A$4:$F$68,3,FALSE) -> 4102227236 | D37: 0 | E37: 0 | F37: 0 | G37: =+VLOOKUP(A37,gasto!$A$4:$F$68,4,FALSE) -> 3048911179 | H37: =+VLOOKUP(A37,gasto!$A$4:$F$68,5,FALSE) -> 73201075 | I37: =+VLOOKUP(A37,gasto!$A$4:$F$68,6,FALSE) -> 73201075 | J37: =+G37+D37 -> 3048911179 | K37: =+H37+E37 -> 73201075 | L37: =+I37+F37 -> 73201075 | M37: =+IFERROR(K37*100/C37,0) -> 1.7844227 | N37: =+IFERROR(L37*100/C37,0) -> 1.7844227
A38: A-3-9-6-0 | B38: UPC Régimen Subsidiado | C38: =+SUM(C39:C41) -> 21586257607421 | D38: =+SUM(D39:D41) -> 0 | E38: =+SUM(E39:E41) -> 0 | F38: =+SUM(F39:F41) -> 0 | G38: =+SUM(G39:G41) -> 1.7760712e+12 | H38: =+SUM(H39:H41) -> 1.7760712e+12 | I38: =+SUM(I39:I41) -> 1.7760712e+12 | J38: =+SUM(J39:J41) -> 1.7760712e+12 | ... L38: =+SUM(L39:L41) -> 1.7760712e+12 | M38: =+IFERROR(K38*100/C38,0) -> 8.2277866 | N38: =+IFERROR(L38*100/C38,0) -> 8.2277866
A39: A-3-9-6-0-01 | B39: UPC´S R.S. Cajas de Compensación Familiar SSF | C39: =+VLOOKUP(A39,gasto!$A$4:$F$68,3,FALSE) -> 28877831435 | D39: 0 | E39: 0 | F39: 0 | G39: =+VLOOKUP(A39,gasto!$A$4:$F$68,4,FALSE) -> 3204560767 | H39: =+VLOOKUP(A39,gasto!$A$4:$F$68,5,FALSE) -> 3204560767 | I39: =+VLOOKUP(A39,gasto!$A$4:$F$68,6,FALSE) -> 3204560767 | J39: =+G39+D39 -> 3204560767 | K39: =+H39+E39 -> 3204560767 | L39: =+I39+F39 -> 3204560767 | M39: =+IFERROR(K39*100/C39,0) -> 11.096958 | N39: =+IFERROR(L39*100/C39,0) -> 11.096958
A40: A-3-9-6-0-02 | B40: UPC´S R.S. CSF | C40: =+VLOOKUP(A40,gasto!$A$4:$F$68,3,FALSE) -> 21520379775986 | D40: 0 | E40: 0 | F40: 0 | G40: =+VLOOKUP(A40,gasto!$A$4:$F$68,4,FALSE) -> 1.7728666e+12 | H40: =+VLOOKUP(A40,gasto!$A$4:$F$68,5,FALSE) -> 1.7728666e+12 | I40: =+VLOOKUP(A40,gasto!$A$4:$F$68,6,FALSE) -> 1.7728666e+12 | J40: =+G40+D40 -> 1.7728666e+12 | K40: =+H40+E40 -> 1.7728666e+12 | L40: =+I40+F40 -> 1.7728666e+12 | M40: =+IFERROR(K40*100/C40,0) -> 8.2380825 | N40: =+IFERROR(L40*100/C40,0) -> 8.2380825
A41: A-3-9-6-0-03 | B41: UPC´S R.S. USPEC | C41: =+VLOOKUP(A41,gasto!$A$4:$F$68,3,FALSE) -> 37000000000 | D41: 0 | E41: 0 | F41: 0 | G41: =+VLOOKUP(A41,gasto!$A$4:$F$68,4,FALSE) -> 0 | H41: =+VLOOKUP(A41,gasto!$A$4:$F$68,5,FALSE) -> 0 | I41: =+VLOOKUP(A41,gasto!$A$4:$F$68,6,FALSE) -> 0 | J41: =+G41+D41 -> 0 | K41: =+H41+E41 -> 0 | L41: =+I41+F41 -> 0
A42: A-3-9-7-0 | B42: Prestaciones Excepcionales - Recobros | C42: =+SUM(C43:C44) -> 4083854535766 | D42: =+SUM(D43:D44) -> 0 | E42: =+SUM(E43:E44) -> 0 | F42: =+SUM(F43:F44) -> 0 | G42: =+SUM(G43:G44) -> 2.0671425e+11 | H42: =+SUM(H43:H44) -> 2.0671425e+11 | I42: =+SUM(I43:I44) -> 2.0671425e+11 | J42: =+SUM(J43:J44) -> 2.0671425e+11 | ... L42: =+SUM(L43:L44) -> 2.0671425e+11 | M42: =+IFERROR(K42*100/C42,0) -> 5.0617438 | N42: =+IFERROR(L42*100/C42,0) -> 5.0617438
A43: A-3-9-7-0-01 | B43: Recobros - Reembolsos Régimen Contributivo | C43: =+VLOOKUP(A43,gasto!$A$4:$F$68,3,FALSE) -> 4072663890220 | D43: 0 | E43: 0 | F43: 0 | G43: =+VLOOKUP(A43,gasto!$A$4:$F$68,4,FALSE) -> 2.0644103e+11 | H43: =+VLOOKUP(A43,gasto!$A$4:$F$68,5,FALSE) -> 2.0644103e+11 | I43: =+VLOOKUP(A43,gasto!$A$4:$F$68,6,FALSE) -> 2.0644103e+11 | J43: =+G43+D43 -> 2.0644103e+11 | K43: =+H43+E43 -> 2.0644103e+11 | L43: =+I43+F43 -> 2.0644103e+11 | M43: =+IFERROR(K43*100/C43,0) -> 5.0689434 | N43: =+IFERROR(L43*100/C43,0) -> 5.0689434
...

Sheet ingresos
A1: RUBRO | B1: inicial | C1: MODIFICACIONES | D1: AFORO DEFINITIVO | E1: INGRESO MES | F1: % | G1: acum
A2: 0-0-0-0 | B2: 422831681000 | C2: 0 | D2: 422831681000 | E2: 422831681000 | F2: 100 | G2: 422831681000 | H2: =+VLOOKUP(A2,'CUADRO 1-EJECUCION DE INGRESOS'!$A$11:$H$97,8,FALSE) -> 422831681000 | I2: =+H2-G2 -> 0
A3: 1-2-1-1 | B3: 17803782346000 | C3: 0 | D3: 17803782346000 | E3: 1241981862167 | F3: 6.98 | G3: 1241981862167 | H3: =+VLOOKUP(A3,'CUADRO 1-EJECUCION DE INGRESOS'!$A$11:$H$97,8,FALSE) -> 1241981862167 | I3: =+H3-G3 -> 0
A4: 1-2-1-1-01 | B4: 13686804885516 | C4: 0 | D4: 13686804885516 | E4: 9.5478383e+11 | F4: 6.98 | G4: 9.5478383e+11 | H4: =+VLOOKUP(A4,'CUADRO 1-EJECUCION DE INGRESOS'!$A$11:$H$97,8,FALSE) -> 9.5478383e+11 | I4: =+H4-G4 -> 0
A5: 1-2-1-1-02 | B5: 4116977460484 | C5: 0 | D5: 4116977460484 | E5: 2.8719804e+11 | F5: 6.98 | G5: 2.8719804e+11 | H5: =+VLOOKUP(A5,'CUADRO 1-EJECUCION DE INGRESOS'!$A$11:$H$97,8,FALSE) -> 2.8719804e+11 | I5: =+H5-G5 -> 0
A6: 1-2-1-2 | B6: 226673765000 | C6: 0 | D6: 226673765000 | E6: 0 | F6: 0 | G6: 0 | H6: =+VLOOKUP(A6,'CUADRO 1-EJECUCION DE INGRESOS'!$A$11:$H$97,8,FALSE) -> 0 | I6: =+H6-G6 -> 0
A7: 1-2-1-3 | B7: 0 | C7: 0 | D7: 0 | E7: 0 | F7: 0 | G7: 0 | H7: =+VLOOKUP(A7,'CUADRO 1-EJECUCION DE INGRESOS'!$A$11:$H$97,8,FALSE) -> 0 | I7: =+H7-G7 -> 0
A8: 1-2-1-4 | B8: 95551523562 | C8: 0 | D8: 95551523562 | E8: 0 | F8: 0 | G8: 0 | H8: =+VLOOKUP(A8,'CUADRO 1-EJECUCION DE INGRESOS'!$A$11:$H$97,8,FALSE) -> 0 | I8: =+H8-G8 -> 0
A9: 1-2-1-5 | B9: 1640527441000 | C9: 0 | D9: 1640527441000 | E9: 2.455599e+11 | F9: 14.97 | G9: 2.455599e+11 | H9: =+VLOOKUP(A9,'CUADRO 1-EJECUCION DE INGRESOS'!$A$11:$H$97,8,FALSE) -> 2.455599e+11 | I9: =+H9-G9 -> 0
A10: 1-2-1-5-01 | B10: 363281118360 | C10: 0 | D10: 363281118360 | E10: 7.770565e+10 | F10: 21.39 | G10: 7.770565e+10 | H10: =+VLOOKUP(A10,'CUADRO 1-EJECUCION DE INGRESOS'!$A$11:$H$97,8,FALSE) -> 7.770565e+10 | I10: =+H10-G10 -> 0
A11: 1-2-1-5-02 | B11: 1277246322640 | C11: 0 | D11: 1277246322640 | E11: 167854247950 | F11: 13.14 | G11: 167854247950 | H11: =+VLOOKUP(A11,'CUADRO 1-EJECUCION DE INGRESOS'!$A$11:$H$97,8,FALSE) -> 167854247950 | I11: =+H11-G11 -> 0
A12: 1-2-1-7 | B12: 6410791000 | C12: 0 | D12: 6410791000 | E12: 15439498040 | F12: 240.84 | G12: 15439498040 | H12: =+VLOOKUP(A12,'CUADRO 1-EJECUCION DE INGRESOS'!$A$11:$H$97,8,FALSE) -> 15439498040 | I12: =+H12-G12 -> 0
A13: 1-2-1-8 | B13: 8851770619 | C13: 0 | D13: 8851770619 | E13: 782571447 | F13: 8.84 | G13: 782571447 | H13: =+VLOOKUP(A13,'CUADRO 1-EJECUCION DE INGRESOS'!$A$11:$H$97,8,FALSE) -> 782571447 | I13: =+H13-G13 -> 0
... A81: 2-9-0-0-02 | B81: 0 | C81: 0 | D81: 0 | E81: 3123909 | F81: 0 | G81: 3123909 | H81: =+VLOOKUP(A81,'CUADRO 1-EJECUCION DE INGRESOS'!$A$11:$H$97,8,FALSE) -> 3123909 | I81: =+H81-G81 -> 0

Sheet gasto
D1: República de Colombia | E1: EJECUCIÓN DE EGRESOS ACUMULADOS | F1: ADRES ADMINISTRADORA DE LOS RECURSOS DEL SGSSS
A2: CÓDIGO RUBRO | B2: CONCEPTO DEL RUBRO | C2: APROPIACIÓN DEFINITIVA | D2: CDP | E2: RP | F2: PAGOS-OGAG | G2: T. CDP | H2: T. RP | I2: T. PAGOS-OGAG | J2: RP | K2: PAGOS
A3: URA
A4: A-3-2-1-0 | B4: Transferencias Entidades de Administración Pública Central | C4: 86345030430 | D4: 0 | E4: 0 | F4: 0 | G4: 0 | H4: 0 | I4: 0 | J4: 0 | K4: 0
A5: A-3-2-1-01 | B5: Contribución IVC Superintendencia Nacional de Salud | C5: 86345030430 | D5: 0 | E5: 0 | F5: 0 | G5: 0 | H5: 0 | I5: 0 | J5: 0 | K5: 0
A6: A-3-2-2-0 | B6: Empresas Públicas Nacionales no financieras -ADRES | C6: 145380000000 | D6: 145380000000 | E6: 4.166544e+09 | F6: 4.166544e+09 | G6: 145380000000 | H6: 4.166544e+09 | I6: 4.166544e+09 | J6: 2.87 | K6: 2.87
A7: A-3-2-2-0-01 | B7: Aportes hasta del 0,5% recursos CSF para el desarrollo objeto ADRES | C7: 145380000000 | D7: 145380000000 | E7: 4.166544e+09 | F7: 4.166544e+09 | G7: 145380000000 | H7: 4.166544e+09 | I7: 4.166544e+09 | J7: 2.87 | K7: 2.87
A8: A-3-6-1-0 | B8: Sentencias y Conciliaciones URA | C8: 20000000000 | D8: 1656232 | E8: 0 | F8: 0 | G8: 1656232 | H8: 0 | I8: 0 | J8: 0 | K8: 0
A9: A-3-6-1-1 | B9: Sentencias URA | C9: 20000000000 | D9: 1656232 | E9: 0 | F9: 0 | G9: 1656232 | H9: 0 | I9: 0 | J9: 0 | K9: 0
A10: A-3-6-1-2 | B10: Conciliaciones URA | C10: 0 | D10: 0 | E10: 0 | F10: 0 | G10: 0 | H10: 0 | I10: 0 | J10: 0 | K10: 0
A11: A-3-6-3-0 | B11: Destinatarios de otras transferencias Corrientes - Compensación Chance | C11: 160000000000 | D11: 0 | E11: 0 | F11: 0 | G11: 0 | H11: 0 | I11: 0 | J11: 0 | K11: 0
A12: A-3-6-3-0-01 | B12: Otras transferencias - Compensación del Chance Decreto 2550/12 | C12: 160000000000 | D12: 0 | E12: 0 | F12: 0 | G12: 0 | H12: 0 | I12: 0 | J12: 0 | K12: 0
A13: A-3-9-1-0 | B13: UPC Régimen Contributivo | C13: 23057892632980 | D13: 1825601270168 | E13: 1825601270168 | F13: 1825601270168 | G13: 1825601270168 | H13: 1825601270168 | I13: 1825601270168 | J13: 7.92 | K13: 7.92
A14: A-3-9-1-0-01 | B14: UPC Régimen Contributivo SSF | C14: 12399109660289 | D14: 910942673794 | E14: 910942673794 | F14: 910942673794 | G14: 910942673794 | H14: 910942673794 | I14: 910942673794 | J14: 7.35 | K14: 7.35
A15: A-3-9-1-0-02 | B15: UPC Régimen Contributivo CSF | C15: 10647939289644 | D15: 914297953268 | E15: 914297953268 | F15: 914297953268 | G15: 914297953268 | H15: 914297953268 | I15: 914297953268 | J15: 8.59 | K15: 8.59
... A73: A-9-9-9-9 | B73: Disponibilidad Final | C73: 254007875000 | D73: 0 | E73: 0 | F73: 0 | G73: 0 | H73: 0 | I73: 0 | J73: 0 | K73: 0

Sheet Hoja1
A3: ADMINISTRADORA DE LOS RECURSOS DEL SISTEMA GENERAL DE SEGURIDAD SOCIAL EN SALUD
A4: PRESUPUESTO DE INGRESOS 2017
A5: UNIDAD DE RECURSOS ADMINISTRADOS - URA
A6: CUADRO No. 1
A8: 1 | B8: 2 | C8: 3 | D8: 4 | E8: 5 | F8: 6 | G8: 7 | H8: 8 | I8: 9 | J8: 10
A9: CÓDIGO RUBRO | B9: CONCEPTO DEL RUBRO | C9: AFORO INICIAL | D9: MODIFICACIÓN PRESUPUESTAL | E9: AFORO DEFINITIVO | F9: Ingresos Acumulados Desde 01/08/2017 hasta 30/11/2017 | G9: Ingresos Desde 01/12/2017 hasta 31/12/2017 | H9: Ingresos Acumulados Desde 01/08/2017 hasta 31/12/2017 | I9: EJECUCIÓN ACUMULADA (%) | J9: PARTICIPACIÓN %
A10: URA
A11: 0-0-0-0 | B11: DISPONIBILIDAD INICIAL | C11: 1049732777065 | D11: 1028793184133 | E11: 2078525961198 | F11: 3.7980893e+11 | G11: 1.698717e+12 | H11: 2.078526e+12 | I11: 100 | J11: 11.173515
A12: 1-2-1-1 | B12: Aportes de la Nación para el Aseguramiento en Salud | C12: 800000000000 | D12: 0 | E12: 800000000000 | F12: 800000000000 | G12: 0 | H12: 800000000000 | I12: 100 | J12: 4.3005534
A13: 1-2-1-1-01 | B13: Aportes de la Nación para el Aseguramiento en Salud Cierre | C13: 800000000000 | D13: 0 | E13: 800000000000 | F13: 800000000000 | G13: 0 | H13: 800000000000 | I13: 100 | J13: 4.3005534
A14: 1-2-1-2 | B14: Compensación Regalías para el Régimen Subsidiado | C14: 0 | D14: 0 | E14: 0 | F14: 0 | G14: 0 | H14: 0 | I14: 0 | J14: 0
A15: 1-2-1-3 | B15: Impuesto sobre la renta para la equidad CREE | C15: 3379423220743 | D15: 0 | E15: 3379423220743 | F15: 2645477901368 | G15: 661369475338 | H15: 3306847376706 | I15: 97.852419 | J15: 17.776592
A16: 1-2-1-4 | B16: SGP FONSAET | C16: 76906712050 | D16: 0 | E16: 76906712050 | F16: 76906712050 | G16: 0 | H16: 76906712050 | I16: 100 | J16: 0.41342677
A17: 1-2-1-5 | B17: PRIMA FONSAT Y CONTRIBUCION SOAT | C17: 630863569234 | D17: 0 | E17: 630863569234 | F17: 4.9668302e+11 | G17: 93551929250 | H17: 5.9023495e+11 | I17: 93.55984 | J17: 3.1729211
A18: 1-2-1-5-01 | B18: % Prima (FONSAT) Decreto Ley 1335 de 2009 | C18: 153176997329 | D18: 0 | E18: 153176997329 | F18: 1.0986192e+11 | G18: 0 | H18: 1.0986192e+11 | I18: 71.722205 | J18: 0.59058382
A19: 1-2-1-5-02 | B19: Contribución Seguro Obligatorio de Accidentes de Tránsito - SOAT- Decreto Ley 1335 de 2009 | C19: 477686571905 | D19: 0 | E19: 477686571905 | F19: 386821096950 | G19: 93551929250 | H19: 480373026200 | I19: 100.56239 | J19: 2.5823373
A20: 1-2-1-7 | B20: Impuesto social a las municiones y explosivos | C20: 31868595127 | D20: 0 | E20: 31868595127 | F20: 31727550335 | G20: 7899641418 | H20: 39627191753 | I20: 124.34559 | J20: 0.21302357
A21: 1-2-1-8 | B21: Impuesto social a las armas | C21: 3612249620 | D21: 0 | E21: 3612249620 | F21: 3452971135 | G21: 969138385 | H21: 4422109520 | I21: 122.41982 | J21: 0.023771897
A22: 1-2-9-0 | B22: Otros aportes e impuestos de la nación | C22: 0 | D22: 0 | E22: 0 | F22: 0 | G22: 0 | H22: 0 | I22: 0 | J22: 0
... A86: 2-9-1-0-06 | B86: Regalías – artículo 5 Ley 1797 de 2016 | C86: 5000000000 | D86: 0 | E86: 5000000000 | F86: 0 | G86: 0 | H86: 0 | I86: 0 | J86: 0
B88: TOTAL | C88: 16692931290975 | D88: 1405041818640 | E88: 18097973109615 | F88: 1.3761589e+13 | G88: 4.8406684e+12 | H88: 1.8602257e+13 | I88: 102.78641 | J88: 100
C90: 16692931290975 | D90: 1405041818640 | E90: 18097973109615 | F90: 1.3761589e+13 | G90: 4.8406684e+12 | H90: 1.8602257e+13 | I90: 102.78641
C91: =+C90-C88 -> 0 | D91: =+D90-D88 -> 0 | E91: =+E90-E88 -> 0 | F91: =+F90-F88 -> 0 | G91: =+G90-G88 -> 0 | H91: =+H90-H88 -> 0 | I91: =+I90-I88 -> 0

Sheet Hoja2
A3: ADMINISTRADORA DE LOS RECURSOS DEL SISTEMA GENERAL DE SEGURIDAD SOCIAL EN SALUD
A4: PRESUPUESTO DE GASTOS 2017
A5: UNIDAD DE RECURSOS ADMINISTRADOS - URA
A6: CUADRO No. 2
A8: 1 | B8: 2 | C8: 3 | D8: 4 | E8: 5 | F8: 6 | G8: 7 | H8: 8 | I8: 9 | J8: 10 | K8: 11 | L8: 12 | M8: 13 | N8: 14
A9: CÓDIGO RUBRO | B9: CONCEPTO DEL RUBRO | C9: APROPIACIÓN DEFINITIVA | D9: EJECUCIÓN PRESUPUESTAL ACUMULADA DESDE 01/08/2017 HASTA 30/11/2017 | G9: EJECUCIÓN PRESUPUESTAL 01/12/2017 HASTA 31/12/2017 | J9: EJECUCIÓN PRESUPUESTAL ACUMULADA DESDE 01/08/2017 HASTA 31/12/2017 | M9: % | O9: SALDO APROPIACIÓN | P9: COMPROMISOS POR PAGAR | Q9: %
D10: T. CDP | E10: T. RP | F10: T. PAGOS-OP | G10: CDP | H10: RP | I10: OP | J10: T. CDP | K10: T. RP | L10: T. PAGOS-OP | M10: RP | N10: OP | Q10: PARTICIPACIÓN
B11: URA
A12: A-9-9-9-9 | B12: Disponibilidad Final | C12: 169607386609 | D12: 0 | E12: 0 | F12: 0 | G12: 0 | H12: 0 | I12: 0 | J12: 0 | K12: 0 | L12: 0 | M12: 0 | N12: 0 | O12: 169607386609 | P12: 0 | Q12: 0
A13: A-3-2-1-0 | B13: Transferencias Entidades de Administración Pública Central | C13: 40479356618 | D13: 22483398888 | E13: 22483398888 | F13: 22483398888 | G13: 5620849724 | H13: 5620849724 | I13: 5620849724 | J13: 28104248612 | K13: 28104248612 | L13: 28104248612 | M13: 69.428595 | N13: 69.428595 | O13: 12375108006 | P13: 0 | Q13: 0.15813624
A14: A-3-2-1-0-01 | B14: Contribución IVC Superintendencia Nacional de Salud | C14: 40479356618 | D14: 22483398888 | E14: 22483398888 | F14: 22483398888 | G14: 5620849724 | H14: 5620849724 | I14: 5620849724 | J14: 28104248612 | K14: 28104248612 | L14: 28104248612 | M14: 69.428595 | N14: 69.428595 | O14: 12375108006 | P14: 0 | Q14: 0.15813624
A15: A-3-2-2-0 | B15: Empresas Públicas Nacionales no financieras | C15: 54432463826 | D15: 54432463826 | E15: 6219861165 | F15: 6219861165 | G15: -1.737463e+10 | H15: 3.0837973e+10 | I15: 9100000000 | J15: 3.7057834e+10 | K15: 3.7057834e+10 | L15: 15319861165 | M15: 68.08039 | N15: 28.144714 | O15: 1.737463e+10 | P15: 2.1737973e+10 | Q15: 0.086201391
A16: A-3-2-2-0-01 | B16: Aportes hasta del 0,5% recursos CSF para el desarrollo objeto ADRES | C16: 54432463826 | D16: 54432463826 | E16: 6219861165 | F16: 6219861165 | G16: -1.737463e+10 | H16: 3.0837973e+10 | I16: 9100000000 | J16: 3.7057834e+10 | K16: 3.7057834e+10 | L16: 15319861165 | M16: 68.08039 | N16: 28.144714 | O16: 1.737463e+10 | P16: 2.1737973e+10 | Q16: 0.086201391
A17: A-3-6-1-0 | B17: Sentencias y Conciliaciones URA | C17: 5059377749 | D17: 1.2391943e+08 | E17: 0 | F17: 0 | G17: 2.2315349e+09 | H17: 2.3554543e+09 | I17: 2.331944e+09 | J17: 2.3554543e+09 | K17: 2.3554543e+09 | L17: 2.331944e+09 | M17: 46.556205 | N17: 46.091518 | O17: 2.7039235e+09 | P17: 23510302 | Q17: 0.013121321
A18: A-3-6-1-1 | B18: Sentencias URA | C18: 5059377749 | D18: 1.2391943e+08 | E18: 0 | F18: 0 | G18: 2.2315349e+09 | H18: 2.3554543e+09 | I18: 2.331944e+09 | J18: 2.3554543e+09 | K18: 2.3554543e+09 | L18: 2.331944e+09 | M18: 46.556205 | N18: 46.091518 | O18: 2.7039235e+09 | P18: 23510302 | Q18: 0.013121321
A19: A-3-6-1-2 | B19: Conciliaciones URA | C19: 0 | D19: 0 | E19: 0 | F19: 0 | G19: 0 | H19: 0 | I19: 0 | J19: 0 | K19: 0 | L19: 0 | M19: 0 | N19: 0 | O19: 0 | P19: 0 | Q19: 0
A20: A-3-6-3-0 | B20: Destinatarios de otras transferencias Corrientes | C20: 30652000000 | D20: 0 | E20: 0 | F20: 0 | G20: 30652000000 | H20: 30652000000 | I20: 30652000000 | J20: 30652000000 | K20: 30652000000 | L20: 30652000000 | M20: 100 | N20: 100 | O20: 0 | P20: 0 | Q20: 0.17247187
A21: A-3-6-3-0-01 | B21: Otras trasnferencias - Compensación del Chance Decreto 2550/12 | C21: 30652000000 | D21: 0 | E21: 0 | F21: 0 | G21: 30652000000 | H21: 30652000000 | I21: 30652000000 | J21: 30652000000 | K21: 30652000000 | L21: 30652000000 | M21: 100 | N21: 100 | O21: 0 | P21: 0 | Q21: 0.17247187
A22: A-3-9-1-0 | B22: UPC Régimen Contributivo | C22: 8076746600070 | D22: 6430211471821 | E22: 6430211471821 | F22: 6424483625438 | G22: 1646200098083 | H22: 1646200098083 | I22: 1651927944466 | J22: 8076411569904 | K22: 8076411569904 | L22: 8076411569904 | M22: 99.995852 | N22: 99.995852 | O22: 335030166 | P22: 0 | Q22: 45.44414
A23: A-3-9-1-0-01 | B23: UPC Régimen Contributivo SSF | C23: 4576838798468 | D23: 3638853998008 | E23: 3638853998008 | F23: 3636391786062 | G23: 937983462711 | H23: 937983462711 | I23: 940445674657 | J23: 4576837460719 | K23: 4576837460719 | L23: 4576837460719 | M23: 99.999971 | N23: 99.999971 | O23: 1337749 | P23: 0 | Q23: 25.752828
... A74: TOTAL | B74: TOTAL | C74: 18097973109615 | D74: 1.3816938e+13 | E74: 1.3767785e+13 | F74: 1.3761589e+13 | G74: 3.9977088e+12 | H74: 4.0468615e+12 | I74: 4.0105851e+12 | J74: 1.7814647e+13 | K74: 1.7814647e+13 | L74: 1.7772174e+13 | M74: 98.434486 | N74: 98.199803 | O74: 2.8332622e+11 | P74: 4.2472859e+10 | Q74: 100
C76: 16692931290975 | D76: 1.3816938e+13 | E76: 1.3816938e+13 | F76: 1.3816938e+13 | G76: 3.9977088e+12 | H76: 4.0468615e+12 | I76: 4.0105851e+12 | J76: 1.3816938e+13 | K76: 1.3816938e+13 | L76: 1.3816938e+13 | M76: 82.771191 | N76: 82.771191
C77: =+C76-C74 -> -1405041818640 | D77: =+D76-D74 -> 0 | E77: =+E76-E74 -> 4.9152731e+10 | F77: =+F76-F74 -> 5.5349216e+10 | G77: =+G76-G74 -> 0 | H77: =+H76-H74 -> 0 | I77: =+I76-I74 -> 0 | J77: =+J76-J74 -> -3.9977088e+12 | ... N77: =+N76-N74 -> -15.428612
