Workbook
Name OLE_LINK1: 'CUADRO 2-EJECUCION DE GASTOS'!#REF!

Sheet CUADRO 1-EJECUCION DE INGRESOS
H1: =+NOW() -> 43339.498 | I1: 0.39027778
A3: ADMINISTRADORA DE LOS RECURSOS DEL SISTEMA GENERAL DE SEGURIDAD SOCIAL EN SALUD
A4: PRESUPUESTO DE INGRESOS 2018
A5: UNIDAD DE RECURSOS ADMINISTRADOS - URA
A6: CUADRO No. 1
A9: CÓDIGO RUBRO | B9: CONCEPTO DEL RUBRO | C9: AFORO INICIAL Resol. 083/18 | D9: MODIFICACIÓN PRESUPUESTAL | E9: AFORO DEFINITIVO | F9: Ingresos Acumulados Desde 01/01/2018 hasta 30/06/2018 | G9: Ingresos Desde 01/07/2018 hasta 31/07/2018 | H9: Ingresos Acumulados Desde 01/01/2018 hasta 31/07/2018 | I9: EJECUCIÓN ACUMULADA (%)
A10: URA
A11: 0-0-0-0 | B11: DISPONIBILIDAD INICIAL | C11: 169607387000 | D11: =+VLOOKUP(A11,ingresos!$A$1:$D$78,2,FALSE) -> 0 | E11: =+VLOOKUP(A11,ingresos!$A$1:$D$78,3,FALSE) -> 6.5229052e+11 | F11: 6.5229052e+11 | G11: =+VLOOKUP(A11,ingresos!$A$1:$D$78,4,FALSE) -> 0 | H11: =+G11+F11 -> 6.5229052e+11 | I11: =+IFERROR(H11*100/E11,0) -> 100
A12: 1-0-0-0 | B12: INGRESOS CORRIENTES | C12: 42417328164000 | D12: =+D13+D27 -> 0 | E12: =+E13+E27 -> 4.2336299e+13 | F12: 2.2411321e+13 | G12: =+G13+G27 -> 3.6611992e+12 | H12: =+G12+F12 -> 2.607252e+13 | I12: =+IFERROR(H12*100/E12,0) -> 61.584316
A13: 1-2-0-0 | B13: Aportes e Impuestos | C13: 14223313699299 | D13: =+D14+D26 -> 0 | E13: =+E14+E26 -> 14223313699299 | F13: 7.2681572e+12 | G13: =+G14+G26 -> 1.1790511e+12 | H13: =+G13+F13 -> 8.4472082e+12 | I13: =+IFERROR(H13*100/E13,0) -> 59.389875
A14: 1-2-1-0 | B14: Aportes de la Nación | C14: 14223313699299 | D14: =+D15+D18+D19+D20+D21+D25+D24+D26 -> 0 | E14: =+E15+E18+E19+E20+E21+E25+E24+E26 -> 14223313699299 | F14: 7.2681572e+12 | G14: =+G15+G18+G19+G20+G21+G25+G24+G26 -> 1.1790511e+12 | H14: =+G14+F14 -> 8.4472082e+12 | I14: =+IFERROR(H14*100/E14,0) -> 59.389875
A15: 1-2-1-1 | B15: Aportes de la Nación para el Aseguramiento en Salud | C15: 12188014480000 | D15: =+SUM(D16:D17) -> 0 | E15: =+SUM(E16:E17) -> 12188014480000 | F15: 6077507240000 | G15: =+SUM(G16:G17) -> 1.0129179e+12 | H15: =+G15+F15 -> 7.0904251e+12 | I15: =+IFERROR(H15*100/E15,0) -> 58.175391
A16: 1-2-1-1-01 | B16: Aportes de la Nación para el Aseguramiento en Salud Cierre | C16: 8190948984384 | D16: =+VLOOKUP(A16,ingresos!$A$1:$D$78,2,FALSE) -> 0 | E16: =+VLOOKUP(A16,ingresos!$A$1:$D$78,3,FALSE) -> 8190948984384 | F16: 4.0728863e+12 | G16: =+VLOOKUP(A16,ingresos!$A$1:$D$78,4,FALSE) -> 6.9223034e+11 | H16: =+G16+F16 -> 4.7651166e+12 | I16: =+IFERROR(H16*100/E16,0) -> 58.175391
A17: 1-2-1-1-02 | B17: Imporenta | C17: 3997065495616 | D17: =+VLOOKUP(A17,ingresos!$A$1:$D$78,2,FALSE) -> 0 | E17: =+VLOOKUP(A17,ingresos!$A$1:$D$78,3,FALSE) -> 3997065495616 | F17: 2.004621e+12 | G17: =+VLOOKUP(A17,ingresos!$A$1:$D$78,4,FALSE) -> 3.2068753e+11 | H17: =+G17+F17 -> 2.3253085e+12 | I17: =+IFERROR(H17*100/E17,0) -> 58.175391
A18: 1-2-1-2 | B18: Compensación Regalías para el Régimen Subsidiado | C18: 220071616000 | D18: =+VLOOKUP(A18,ingresos!$A$1:$D$78,2,FALSE) -> 0 | E18: =+VLOOKUP(A18,ingresos!$A$1:$D$78,3,FALSE) -> 220071616000 | F18: 220071616000 | G18: =+VLOOKUP(A18,ingresos!$A$1:$D$78,4,FALSE) -> 0 | H18: =+G18+F18 -> 220071616000 | I18: =+IFERROR(H18*100/E18,0) -> 100
A19: 1-2-1-3 | B19: Impuesto sobre la renta para la equidad CREE | C19: 112615883615 | D19: =+VLOOKUP(A19,ingresos!$A$1:$D$78,2,FALSE) -> 0 | E19: =+VLOOKUP(A19,ingresos!$A$1:$D$78,3,FALSE) -> 112615883615 | F19: 112615883615 | G19: =+VLOOKUP(A19,ingresos!$A$1:$D$78,4,FALSE) -> 0 | H19: =+G19+F19 -> 112615883615 | I19: =+IFERROR(H19*100/E19,0) -> 100
A20: 1-2-1-4 | B20: SGP FONSAET | C20: 51737470684 | D20: =+VLOOKUP(A20,ingresos!$A$1:$D$78,2,FALSE) -> 0 | E20: =+VLOOKUP(A20,ingresos!$A$1:$D$78,3,FALSE) -> 51737470684 | F20: 0 | G20: =+VLOOKUP(A20,ingresos!$A$1:$D$78,4,FALSE) -> 0 | H20: =+G20+F20 -> 0 | I20: =+IFERROR(H20*100/E20,0) -> 0
A21: 1-2-1-5 | B21: PRIMA FONSAT Y CONTRIBUCION SOAT | C21: 1548964470000 | D21: =+SUM(D22:D23) -> 0 | E21: =+SUM(E22:E23) -> 1548964470000 | F21: 8.1092641e+11 | G21: =+SUM(G22:G23) -> 158106154114 | H21: =+G21+F21 -> 9.6903257e+11 | I21: =+IFERROR(H21*100/E21,0) -> 62.560025
A22: 1-2-1-5-01 | B22: % Prima (FONSAT) Decreto Ley 1335 de 2009 | C22: 344521245760 | D22: =+VLOOKUP(A22,ingresos!$A$1:$D$78,2,FALSE) -> 0 | E22: =+VLOOKUP(A22,ingresos!$A$1:$D$78,3,FALSE) -> 344521245760 | F22: 1.7801278e+11 | G22: =+VLOOKUP(A22,ingresos!$A$1:$D$78,4,FALSE) -> 57020606514 | H22: =+G22+F22 -> 2.3503338e+11 | I22: =+IFERROR(H22*100/E22,0) -> 68.220287
A23: 1-2-1-5-02 | B23: Contribución Seguro Obligatorio de Accidentes de Tránsito - SOAT- Decreto Ley 1335 de 2009 | C23: 1204443224240 | D23: =+VLOOKUP(A23,ingresos!$A$1:$D$78,2,FALSE) -> 0 | E23: =+VLOOKUP(A23,ingresos!$A$1:$D$78,3,FALSE) -> 1204443224240 | F23: 6.3291364e+11 | G23: =+VLOOKUP(A23,ingresos!$A$1:$D$78,4,FALSE) -> 101085547600 | H23: =+G23+F23 -> 7.3399919e+11 | I23: =+IFERROR(H23*100/E23,0) -> 60.940953
A24: 1-2-1-7 | B24: Impuesto social a las municiones y explosivos | C24: 93173435000 | D24: =+VLOOKUP(A24,ingresos!$A$1:$D$78,2,FALSE) -> 0 | E24: =+VLOOKUP(A24,ingresos!$A$1:$D$78,3,FALSE) -> 93173435000 | F24: 42577460554 | G24: =+VLOOKUP(A24,ingresos!$A$1:$D$78,4,FALSE) -> 7169482863 | H24: =+G24+F24 -> 49746943417 | I24: =+IFERROR(H24*100/E24,0) -> 53.391767
A25: 1-2-1-8 | B25: Impuesto social a las armas | C25: 8736344000 | D25: =+VLOOKUP(A25,ingresos!$A$1:$D$78,2,FALSE) -> 0 | E25: =+VLOOKUP(A25,ingresos!$A$1:$D$78,3,FALSE) -> 8736344000 | F25: 4458540953 | G25: =+VLOOKUP(A25,ingresos!$A$1:$D$78,4,FALSE) -> 857570807 | H25: =+G25+F25 -> 5316111760 | I25: =+IFERROR(H25*100/E25,0) -> 60.850532
A26: 1-2-9-0 | B26: Otros aportes e impuestos de la nación | C26: 0 | D26: =+VLOOKUP(A26,ingresos!$A$1:$D$78,2,FALSE) -> 0 | E26: =+VLOOKUP(A26,ingresos!$A$1:$D$78,3,FALSE) -> 0 | F26: 0 | G26: =+VLOOKUP(A26,ingresos!$A$1:$D$78,4,FALSE) -> 0 | H26: =+G26+F26 -> 0 | I26: =+IFERROR(H26*100/E26,0) -> 0
A27: 1-3-0-0 | B27: Otros Ingresos Corrientes | C27: 28194014464701 | D27: =+D28+D56 -> 0 | E27: =+E28+E56 -> 2.8112986e+13 | F27: 1.5143164e+13 | G27: =+G28+G56 -> 2.4821481e+12 | H27: =+G27+F27 -> 1.7625312e+13 | I27: =+IFERROR(H27*100/E27,0) -> 62.694559
A28: 1-3-5-0 | B28: Ingresos Sistema General de Seguridad Social en Salud | C28: 19251927507271 | D28: =+D29+D32+D35+D40+D50+D53 -> 0 | E28: =+E29+E32+E35+E40+E50+E53 -> 19251927507271 | F28: 1.0408395e+13 | G28: =+G29+G32+G35+G40+G50+G53 -> 1.7512275e+12 | H28: =+G28+F28 -> 1.2159623e+13 | I28: =+IFERROR(H28*100/E28,0) -> 63.160547
A29: 1-3-5-1 | B29: Cotizaciones al SGSSS | C29: 17803406036000 | D29: =+SUM(D30:D31) -> 0 | E29: =+SUM(E30:E31) -> 17803406036000 | F29: 9308156751181 | G29: =+SUM(G30:G31) -> 1580790040661 | H29: =+G29+F29 -> 10888946791842 | I29: =+IFERROR(H29*100/E29,0) -> 61.162155
A30: 1-3-5-1-01 | B30: Régimen Contributivo CSF | C30: 4777288159000 | D30: =+VLOOKUP(A30,ingresos!$A$1:$D$78,2,FALSE) -> 0 | E30: =+VLOOKUP(A30,ingresos!$A$1:$D$78,3,FALSE) -> 4777288159000 | F30: 3185733637647 | G30: =+VLOOKUP(A30,ingresos!$A$1:$D$78,4,FALSE) -> 542064425376 | H30: =+G30+F30 -> 3727798063023 | I30: =+IFERROR(H30*100/E30,0) -> 78.031677
A31: 1-3-5-1-02 | B31: Régimen Contributivo SSF | C31: 13026117877000 | D31: =+VLOOKUP(A31,ingresos!$A$1:$D$78,2,FALSE) -> 0 | E31: =+VLOOKUP(A31,ingresos!$A$1:$D$78,3,FALSE) -> 13026117877000 | F31: 6122423113534 | G31: =+VLOOKUP(A31,ingresos!$A$1:$D$78,4,FALSE) -> 1038725615285 | H31: =+G31+F31 -> 7161148728819 | I31: =+IFERROR(H31*100/E31,0) -> 54.97531
A32: 1-3-5-2 | B32: Aporte Solidaridad de Regímenes de Excepcion y Especiales | C32: 880078202271 | D32: =+SUM(D33:D34) -> 0 | E32: =+SUM(E33:E34) -> 880078202271 | F32: 4.1394722e+11 | G32: =+SUM(G33:G34) -> 7.2620773e+10 | H32: =+G32+F32 -> 4.8656799e+11 | I32: =+IFERROR(H32*100/E32,0) -> 55.286904
A33: 1-3-5-2-01 | B33: Cotizaciones afiliados REX con ingresos adicionales | C33: 440039101136 | D33: =+VLOOKUP(A33,ingresos!$A$1:$D$78,2,FALSE) -> 0 | E33: =+VLOOKUP(A33,ingresos!$A$1:$D$78,3,FALSE) -> 440039101136 | F33: 246214318772 | G33: =+VLOOKUP(A33,ingresos!$A$1:$D$78,4,FALSE) -> 41726084780 | H33: =+G33+F33 -> 287940403552 | I33: =+IFERROR(H33*100/E33,0) -> 65.435186
A34: 1-3-5-2-02 | B34: Aporte Solidario entidades REX | C34: 440039101135 | D34: =+VLOOKUP(A34,ingresos!$A$1:$D$78,2,FALSE) -> 0 | E34: =+VLOOKUP(A34,ingresos!$A$1:$D$78,3,FALSE) -> 440039101135 | F34: 1.677329e+11 | G34: =+VLOOKUP(A34,ingresos!$A$1:$D$78,4,FALSE) -> 3.0894688e+10 | H34: =+G34+F34 -> 1.9862759e+11 | I34: =+IFERROR(H34*100/E34,0) -> 45.138623
A35: 1-3-5-3 | B35: Aportes Cajas de Compensación Familiar | C35: 566983320000 | D35: =+SUM(D36:D39) -> 0 | E35: =+SUM(E36:E39) -> 566983320000 | F35: 2.3953779e+11 | G35: =+SUM(G36:G39) -> 4.1984121e+10 | H35: =+G35+F35 -> 2.8152191e+11 | I35: =+IFERROR(H35*100/E35,0) -> 49.652592
A36: 1-3-5-3-01 | B36: Aportes CCF Artículo 217 Ley 100 de 1993 CSF | C36: 540507991000 | D36: =+VLOOKUP(A36,ingresos!$A$1:$D$78,2,FALSE) -> 0 | E36: =+VLOOKUP(A36,ingresos!$A$1:$D$78,3,FALSE) -> 540507991000 | F36: 2.2300017e+11 | G36: =+VLOOKUP(A36,ingresos!$A$1:$D$78,4,FALSE) -> 3.9833666e+10 | H36: =+G36+F36 -> 2.6283383e+11 | I36: =+IFERROR(H36*100/E36,0) -> 48.627187
A37: 1-3-5-3-02 | B37: Aportes CCF Artículo 217 Ley 100 de 1993 SSF | C37: 26475329000 | D37: =+VLOOKUP(A37,ingresos!$A$1:$D$78,2,FALSE) -> 0 | E37: =+VLOOKUP(A37,ingresos!$A$1:$D$78,3,FALSE) -> 26475329000 | F37: 12902733786 | G37: =+VLOOKUP(A37,ingresos!$A$1:$D$78,4,FALSE) -> 2150455631 | H37: =+G37+F37 -> 15053189417 | I37: =+IFERROR(H37*100/E37,0) -> 56.857422
A38: 1-3-5-3-03 | B38: Aportes CCF Balance | C38: 0 | D38: =+VLOOKUP(A38,ingresos!$A$1:$D$78,2,FALSE) -> 0 | E38: =+VLOOKUP(A38,ingresos!$A$1:$D$78,3,FALSE) -> 0 | F38: 3634891107 | G38: =+VLOOKUP(A38,ingresos!$A$1:$D$78,4,FALSE) -> 0 | H38: =+G38+F38 -> 3634891107 | I38: =+IFERROR(H38*100/E38,0) -> 0
A39: 1-3-5-3-04 | B39: Otros Aportes CCF | C39: 0 | D39: =+VLOOKUP(A39,ingresos!$A$1:$D$78,2,FALSE) -> 0 | E39: =+VLOOKUP(A39,ingresos!$A$1:$D$78,3,FALSE) -> 0 | F39: 0 | G39: =+VLOOKUP(A39,ingresos!$A$1:$D$78,4,FALSE) -> 0 | H39: =+G39+F39 -> 0 | I39: =+IFERROR(H39*100/E39,0) -> 0
A40: 1-3-5-5 | B40: Reintegros / Recuperaciones | C40: 0 | D40: =+SUM(D41:D49) -> 0 | E40: =+SUM(E41:E49) -> 0 | F40: 3.2902717e+11 | G40: =+SUM(G41:G49) -> 3.7568559e+10 | H40: =+G40+F40 -> 3.6659573e+11 | I40: =+IFERROR(H40*100/E40,0) -> 0
A41: 1-3-5-5-01 | B41: UPC Régimen Contributivo Vigencias anteriores | C41: 0 | D41: =+VLOOKUP(A41,ingresos!$A$1:$D$78,2,FALSE) -> 0 | E41: =+VLOOKUP(A41,ingresos!$A$1:$D$78,3,FALSE) -> 0 | F41: 5.2181171e+09 | G41: =+VLOOKUP(A41,ingresos!$A$1:$D$78,4,FALSE) -> 1.6483477e+09 | H41: =+G41+F41 -> 6.8664648e+09 | I41: =+IFERROR(H41*100/E41,0) -> 0
A42: 1-3-5-5-02 | B42: P&P Vigencias anteriores | C42: 0 | D42: =+VLOOKUP(A42,ingresos!$A$1:$D$78,2,FALSE) -> 0 | E42: =+VLOOKUP(A42,ingresos!$A$1:$D$78,3,FALSE) -> 0 | F42: 0 | G42: =+VLOOKUP(A42,ingresos!$A$1:$D$78,4,FALSE) -> 0 | H42: =+G42+F42 -> 0 | I42: =+IFERROR(H42*100/E42,0) -> 0
A43: 1-3-5-5-03 | B43: Licencias de Maternidad y Paternidad Vigencias anteriores | C43: 0 | D43: =+VLOOKUP(A43,ingresos!$A$1:$D$78,2,FALSE) -> 0 | E43: =+VLOOKUP(A43,ingresos!$A$1:$D$78,3,FALSE) -> 0 | F43: 0 | G43: =+VLOOKUP(A43,ingresos!$A$1:$D$78,4,FALSE) -> 0 | H43: =+G43+F43 -> 0 | I43: =+IFERROR(H43*100/E43,0) -> 0
...

Sheet ingresos
A1: RUBRO | B1: MODIFICACIONES | C1: AFORO DEFINITIVO | D1: INGRESO JUNIO
A2: 0-0-0-0 | B2: 0 | C2: 6.5229052e+11 | D2: 0
A3: 1-2-1-1 | B3: 0 | C3: 12188014480000 | D3: 1.0129179e+12
A4: 1-2-1-1-01 | B4: 0 | C4: 8190948984384 | D4: 6.9223034e+11
A5: 1-2-1-1-02 | B5: 0 | C5: 3997065495616 | D5: 3.2068753e+11
A6: 1-2-1-2 | B6: 0 | C6: 220071616000 | D6: 0
A7: 1-2-1-3 | B7: 0 | C7: 112615883615 | D7: 0
A8: 1-2-1-4 | B8: 0 | C8: 51737470684 | D8: 0
A9: 1-2-1-5 | B9: 0 | C9: 1548964470000 | D9: 158106154114
A10: 1-2-1-5-01 | B10: 0 | C10: 344521245760 | D10: 57020606514
A11: 1-2-1-5-02 | B11: 0 | C11: 1204443224240 | D11: 101085547600
A12: 1-2-1-7 | B12: 0 | C12: 93173435000 | D12: 7169482863
A13: 1-2-1-8 | B13: 0 | C13: 8736344000 | D13: 857570807
... A78: 2-9-0-0-02 | B78: 0 | C78: 0 | D78: 0

Sheet CUADRO 2-EJECUCION DE GASTOS
M1: =+NOW() -> 43339.498 | N1: 0.39027778
A3: ADMINISTRADORA DE LOS RECURSOS DEL SISTEMA GENERAL DE SEGURIDAD SOCIAL EN SALUD
A4: PRESUPUESTO DE GASTOS 2018
A5: UNIDAD DE RECURSOS ADMINISTRADOS - URA
A6: CUADRO No. 2
A9: CÓDIGO RUBRO | B9: CONCEPTO DEL RUBRO | C9: APROPIACIÓN DEFINITIVA | D9: EJECUCION PRESUPUESTAL ACUMULADA DESDE 01/01/2018 HASTA 30/06/2018 | G9: EJECUCION PRESUPUESTAL DESDE 01/07/2018 HASTA 31/07/2018 | J9: EJECUCION PRESUPUESTAL ACUMULADA DESDE 01/01/2018 HASTA 31/07/2018 | M9: %
D10: T. CDP | E10: T. RP | F10: T. PAGOS-OP | G10: CDP | H10: RP | I10: PAGOS-OP | J10: T. CDP | K10: T. RP | L10: T. PAGOS-OP | M10: RP | N10: OP
B11: URA
A12: A-3-0-0-0 | B12: TRANSFERENCIAS | C12: =+C13+C18+C24 -> 4.3128604e+13 | D12: 2.2553424e+13 | E12: 2.2444627e+13 | F12: 2.2444627e+13 | G12: =+G13+G18+G24 -> 4.1865643e+12 | H12: =+H13+H18+H24 -> 4.1950823e+12 | I12: =+I13+I18+I24 -> 4.1950823e+12 | J12: =+G12+D12 -> 2.6739989e+13 | K12: =+H12+E12 -> 2.6639709e+13 | L12: =+I12+F12 -> 2.6639709e+13 | M12: =+IFERROR(K12*100/C12,0) -> 61.768076 | N12: =+IFERROR(L12*100/C12,0) -> 61.768076
A13: A-3-2-0-0 | B13: TRANSFERENCIAS AL SECTOR PUBLICO | C13: 197288838698 | D13: 1.7451442e+11 | E13: 6.7957492e+10 | F13: 6.7957492e+10 | G13: =+G14+G16 -> 0 | H13: =+H14+H16 -> 12056311838 | I13: =+I14+I16 -> 12056311838 | J13: =+G13+D13 -> 1.7451442e+11 | K13: =+H13+E13 -> 8.0013804e+10 | L13: =+I13+F13 -> 8.0013804e+10 | M13: =+IFERROR(K13*100/C13,0) -> 40.556681 | N13: =+IFERROR(L13*100/C13,0) -> 40.556681
A14: A-3-2-1-0 | B14: Transferencias Entidades de Administración Pública Central | C14: 74955308000 | D14: 73566309756 | E14: 36783154878 | F14: 36783154878 | G14: =+G15 -> 0 | H14: =+H15 -> 6130525813 | I14: =+I15 -> 6130525813 | J14: =+G14+D14 -> 73566309756 | K14: =+H14+E14 -> 42913680691 | L14: =+I14+F14 -> 42913680691 | M14: =+IFERROR(K14*100/C14,0) -> 57.252357 | N14: =+IFERROR(L14*100/C14,0) -> 57.252357
A15: A-3-2-1-01 | B15: Contribución IVC Superintendencia Nacional de Salud | C15: =+VLOOKUP(A15,gasto!$A$4:$F$66,3,FALSE) -> 74955308000 | D15: 73566309756 | E15: 36783154878 | F15: 36783154878 | G15: =+VLOOKUP(A15,gasto!$A$4:$F$66,4,FALSE) -> 0 | H15: =+VLOOKUP(A15,gasto!$A$4:$F$66,5,FALSE) -> 6130525813 | I15: =+VLOOKUP(A15,gasto!$A$4:$F$66,6,FALSE) -> 6130525813 | J15: =+G15+D15 -> 73566309756 | K15: =+H15+E15 -> 42913680691 | L15: =+I15+F15 -> 42913680691 | M15: =+IFERROR(K15*100/C15,0) -> 57.252357 | N15: =+IFERROR(L15*100/C15,0) -> 57.252357
A16: A-3-2-2-0 | B16: Empresas Públicas Nacionales no financieras -ADRES | C16: =+VLOOKUP(A16,gasto!$A$4:$F$66,3,FALSE) -> 122333530698 | D16: 1.0094811e+11 | E16: 3.1174337e+10 | F16: 3.1174337e+10 | G16: =+G17 -> 0 | H16: =+H17 -> 5925786025 | I16: =+I17 -> 5925786025 | J16: =+G16+D16 -> 1.0094811e+11 | K16: =+H16+E16 -> 3.7100123e+10 | L16: =+I16+F16 -> 3.7100123e+10 | M16: =+IFERROR(K16*100/C16,0) -> 30.327027 | N16: =+IFERROR(L16*100/C16,0) -> 30.327027
A17: A-3-2-2-0-01 | B17: Aportes hasta del 0,5% recursos CSF para el desarrollo objeto ADRES | C17: =+VLOOKUP(A17,gasto!$A$4:$F$66,3,FALSE) -> 122333530698 | D17: 1.0094811e+11 | E17: 3.1174337e+10 | F17: 3.1174337e+10 | G17: =+VLOOKUP(A17,gasto!$A$4:$F$66,4,FALSE) -> 0 | H17: =+VLOOKUP(A17,gasto!$A$4:$F$66,5,FALSE) -> 5925786025 | I17: =+VLOOKUP(A17,gasto!$A$4:$F$66,6,FALSE) -> 5925786025 | J17: =+G17+D17 -> 1.0094811e+11 | K17: =+H17+E17 -> 3.7100123e+10 | L17: =+I17+F17 -> 3.7100123e+10 | M17: =+IFERROR(K17*100/C17,0) -> 30.327027 | N17: =+IFERROR(L17*100/C17,0) -> 30.327027
A18: A-3-6-0-0 | B18: OTRAS TRANSFERENCIAS | C18: =+C19+C22 -> 6000000000 | D18: 2.4534687e+09 | E18: 2.4534687e+09 | F18: 2.4534687e+09 | G18: =+G19+G22 -> 1.2620085e+09 | H18: =+H19+H22 -> 0 | I18: =+I19+I22 -> 0 | J18: =+G18+D18 -> 3.7154772e+09 | K18: =+H18+E18 -> 2.4534687e+09 | L18: =+I18+F18 -> 2.4534687e+09 | M18: =+IFERROR(K18*100/C18,0) -> 40.891145 | N18: =+IFERROR(L18*100/C18,0) -> 40.891145
A19: A-3-6-1-0 | B19: Sentencias y Conciliaciones URA | C19: =+SUM(C20:C21) -> 6000000000 | D19: 2.4534687e+09 | E19: 2.4534687e+09 | F19: 2.4534687e+09 | G19: =+SUM(G20:G21) -> 1.2620085e+09 | H19: =+SUM(H20:H21) -> 0 | I19: =+SUM(I20:I21) -> 0 | J19: =+G19+D19 -> 3.7154772e+09 | K19: =+H19+E19 -> 2.4534687e+09 | L19: =+I19+F19 -> 2.4534687e+09 | M19: =+IFERROR(K19*100/C19,0) -> 40.891145 | N19: =+IFERROR(L19*100/C19,0) -> 40.891145
A20: A-3-6-1-1 | B20: Sentencias URA | C20: =+VLOOKUP(A20,gasto!$A$4:$F$66,3,FALSE) -> 6000000000 | D20: 2.4534687e+09 | E20: 2.4534687e+09 | F20: 2.4534687e+09 | G20: =+VLOOKUP(A20,gasto!$A$4:$F$66,4,FALSE) -> 1.2620085e+09 | H20: =+VLOOKUP(A20,gasto!$A$4:$F$66,5,FALSE) -> 0 | I20: =+VLOOKUP(A20,gasto!$A$4:$F$66,6,FALSE) -> 0 | J20: =+G20+D20 -> 3.7154772e+09 | K20: =+H20+E20 -> 2.4534687e+09 | L20: =+I20+F20 -> 2.4534687e+09 | M20: =+IFERROR(K20*100/C20,0) -> 40.891145 | N20: =+IFERROR(L20*100/C20,0) -> 40.891145
A21: A-3-6-1-2 | B21: Conciliaciones URA | C21: =+VLOOKUP(A21,gasto!$A$4:$F$66,3,FALSE) -> 0 | D21: 0 | E21: 0 | F21: 0 | G21: =+VLOOKUP(A21,gasto!$A$4:$F$66,4,FALSE) -> 0 | H21: =+VLOOKUP(A21,gasto!$A$4:$F$66,5,FALSE) -> 0 | I21: =+VLOOKUP(A21,gasto!$A$4:$F$66,6,FALSE) -> 0 | J21: =+G21+D21 -> 0 | K21: =+H21+E21 -> 0 | L21: =+I21+F21 -> 0 | M21: =+IFERROR(K21*100/C21,0) -> 0 | N21: =+IFERROR(L21*100/C21,0) -> 0
A22: A-3-6-3-0 | B22: Destinatarios de otras transferencias Corrientes - Compensación Chance | C22: =+C23 -> 0 | D22: 0 | E22: 0 | F22: 0 | G22: =+G23 -> 0 | H22: =+H23 -> 0 | I22: =+I23 -> 0 | J22: =+G22+D22 -> 0 | K22: =+H22+E22 -> 0 | L22: =+I22+F22 -> 0 | M22: =+IFERROR(K22*100/C22,0) -> 0 | N22: =+IFERROR(L22*100/C22,0) -> 0
A23: A-3-6-3-0-01 | B23: Otras transferencias - Compensación del Chance Decreto 2550/12 | C23: =+VLOOKUP(A23,gasto!$A$4:$F$66,3,FALSE) -> 0 | D23: 0 | E23: 0 | F23: 0 | G23: =+VLOOKUP(A23,gasto!$A$4:$F$66,4,FALSE) -> 0 | H23: =+VLOOKUP(A23,gasto!$A$4:$F$66,5,FALSE) -> 0 | I23: =+VLOOKUP(A23,gasto!$A$4:$F$66,6,FALSE) -> 0 | J23: =+G23+D23 -> 0 | K23: =+H23+E23 -> 0 | L23: =+I23+F23 -> 0 | M23: =+IFERROR(K23*100/C23,0) -> 0 | N23: =+IFERROR(L23*100/C23,0) -> 0
A24: A-3-9-0-0 | B24: ADMINISTRACIÓN DE RECURSOS DEL SGSSS | C24: =+C25+C30+C33+C36+C37+C38+C41+C44+C51+C55+C62+C70+C72+C74 -> 4.2925315e+13 | D24: 2.2376456e+13 | E24: 2.2374216e+13 | F24: 2.2374216e+13 | G24: =+G25+G30+G33+G36+G37+G38+G41+G44+G51+G55+G62+G70+G72+G74 -> 4.1853023e+12 | H24: =+H25+H30+H33+H36+H37+H38+H41+H44+H51+H55+H62+H70+H72+H74 -> 4.1830259e+12 | I24: =+I25+I30+I33+I36+I37+I38+I41+I44+I51+I55+I62+I70+I72+I74 -> 4.1830259e+12 | J24: =+G24+D24 -> 2.6561759e+13 | K24: =+H24+E24 -> 2.6557242e+13 | L24: =+I24+F24 -> 2.6557242e+13 | M24: =+IFERROR(K24*100/C24,0) -> 61.868484 | N24: =+IFERROR(L24*100/C24,0) -> 61.868484
A25: A-3-9-1-0 | B25: UPC Régimen Contributivo | C25: =+SUM(C26:C29) -> 19815600876556 | D25: 10310388273841 | E25: 10310388273841 | F25: 10310388273841 | G25: =+SUM(G26:G29) -> 1706562364495 | H25: =+SUM(H26:H29) -> 1706562364495 | I25: =+SUM(I26:I29) -> 1706562364495 | J25: =+G25+D25 -> 12016950638336 | K25: =+H25+E25 -> 12016950638336 | L25: =+I25+F25 -> 12016950638336 | M25: =+IFERROR(K25*100/C25,0) -> 60.643887 | N25: =+IFERROR(L25*100/C25,0) -> 60.643887
A26: A-3-9-1-0-01 | B26: UPC Régimen Contributivo SSF | C26: =+VLOOKUP(A26,gasto!$A$4:$F$66,3,FALSE) -> 11897430272837 | D26: 5607192426180 | E26: 5607192426180 | F26: 5607192426180 | G26: =+VLOOKUP(A26,gasto!$A$4:$F$66,4,FALSE) -> 952008781043 | H26: =+VLOOKUP(A26,gasto!$A$4:$F$66,5,FALSE) -> 952008781043 | I26: =+VLOOKUP(A26,gasto!$A$4:$F$66,6,FALSE) -> 952008781043 | J26: =+G26+D26 -> 6559201207223 | K26: =+H26+E26 -> 6559201207223 | L26: =+I26+F26 -> 6559201207223 | M26: =+IFERROR(K26*100/C26,0) -> 55.131243 | N26: =+IFERROR(L26*100/C26,0) -> 55.131243
A27: A-3-9-1-0-02 | B27: UPC Régimen Contributivo CSF | C27: =+VLOOKUP(A27,gasto!$A$4:$F$66,3,FALSE) -> 7834554371500 | D27: 4701334484123 | E27: 4701334484123 | F27: 4701334484123 | G27: =+VLOOKUP(A27,gasto!$A$4:$F$66,4,FALSE) -> 754410079007 | H27: =+VLOOKUP(A27,gasto!$A$4:$F$66,5,FALSE) -> 754410079007 | I27: =+VLOOKUP(A27,gasto!$A$4:$F$66,6,FALSE) -> 754410079007 | J27: =+G27+D27 -> 5455744563130 | K27: =+H27+E27 -> 5455744563130 | L27: =+I27+F27 -> 5455744563130 | M27: =+IFERROR(K27*100/C27,0) -> 69.636948 | N27: =+IFERROR(L27*100/C27,0) -> 69.636948
A28: A-3-9-1-0-03 | B28: Devolución aportes y cotizaciones no conciliadas vigencia anterior | C28: =+VLOOKUP(A28,gasto!$A$4:$F$66,3,FALSE) -> 76616232219 | D28: 1861363538 | E28: 1861363538 | F28: 1861363538 | G28: =+VLOOKUP(A28,gasto!$A$4:$F$66,4,FALSE) -> 143504445 | H28: =+VLOOKUP(A28,gasto!$A$4:$F$66,5,FALSE) -> 143504445 | I28: =+VLOOKUP(A28,gasto!$A$4:$F$66,6,FALSE) -> 143504445 | J28: =+G28+D28 -> 2004867983 | K28: =+H28+E28 -> 2004867983 | L28: =+I28+F28 -> 2004867983 | M28: =+IFERROR(K28*100/C28,0) -> 2.6167666 | N28: =+IFERROR(L28*100/C28,0) -> 2.6167666
A29: A-3-9-1-0-04 | B29: Rendimientos Financieros de los Saldos no Compensados de los Aportes Patronales según Art. 12 Decreto 1636 de 2016 | C29: =+VLOOKUP(A29,gasto!$A$4:$F$66,3,FALSE) -> 7000000000 | D29: 0 | E29: 0 | F29: 0 | G29: =+VLOOKUP(A29,gasto!$A$4:$F$66,4,FALSE) -> 0 | H29: =+VLOOKUP(A29,gasto!$A$4:$F$66,5,FALSE) -> 0 | I29: =+VLOOKUP(A29,gasto!$A$4:$F$66,6,FALSE) -> 0 | J29: =+G29+D29 -> 0 | K29: =+H29+E29 -> 0 | L29: =+I29+F29 -> 0 | M29: =+IFERROR(K29*100/C29,0) -> 0 | N29: =+IFERROR(L29*100/C29,0) -> 0
A30: A-3-9-2-0 | B30: Per capita Programas de Promoción y Prevención R.C | C30: =+SUM(C31:C32) -> 483767006000 | D30: 247769745787 | E30: 247769745787 | F30: 247769745787 | G30: =+SUM(G31:G32) -> 40700925206 | H30: =+SUM(H31:H32) -> 40700925206 | I30: =+SUM(I31:I32) -> 40700925206 | J30: =+G30+D30 -> 288470670993 | K30: =+H30+E30 -> 288470670993 | L30: =+I30+F30 -> 288470670993 | M30: =+IFERROR(K30*100/C30,0) -> 59.630084 | N30: =+IFERROR(L30*100/C30,0) -> 59.630084
A31: A-3-9-2-0-01 | B31: Per capita Programas de Promoción y Prevención R.C SSF | C31: =+VLOOKUP(A31,gasto!$A$4:$F$66,3,FALSE) -> 314169668000 | D31: 194314926849 | E31: 194314926849 | F31: 194314926849 | G31: =+VLOOKUP(A31,gasto!$A$4:$F$66,4,FALSE) -> 32073266296 | H31: =+VLOOKUP(A31,gasto!$A$4:$F$66,5,FALSE) -> 32073266296 | I31: =+VLOOKUP(A31,gasto!$A$4:$F$66,6,FALSE) -> 32073266296 | J31: =+G31+D31 -> 226388193145 | K31: =+H31+E31 -> 226388193145 | L31: =+I31+F31 -> 226388193145 | M31: =+IFERROR(K31*100/C31,0) -> 72.059214 | N31: =+IFERROR(L31*100/C31,0) -> 72.059214
A32: A-3-9-2-0-02 | B32: Per capita Programas de Promoción y Prevención R.C CSF | C32: =+VLOOKUP(A32,gasto!$A$4:$F$66,3,FALSE) -> 169597338000 | D32: 53454818938 | E32: 53454818938 | F32: 53454818938 | G32: =+VLOOKUP(A32,gasto!$A$4:$F$66,4,FALSE) -> 8627658910 | H32: =+VLOOKUP(A32,gasto!$A$4:$F$66,5,FALSE) -> 8627658910 | I32: =+VLOOKUP(A32,gasto!$A$4:$F$66,6,FALSE) -> 8627658910 | J32: =+G32+D32 -> 62082477848 | K32: =+H32+E32 -> 62082477848 | L32: =+I32+F32 -> 62082477848 | M32: =+IFERROR(K32*100/C32,0) -> 36.605809 | N32: =+IFERROR(L32*100/C32,0) -> 36.605809
A33: A-3-9-3-0 | B33: Incapacidades | C33: =+SUM(C34:C35) -> 918476359163 | D33: 424074397356 | E33: 424074397356 | F33: 424074397356 | G33: =+SUM(G34:G35) -> 69300422041 | H33: =+SUM(H34:H35) -> 69300422041 | I33: =+SUM(I34:I35) -> 69300422041 | J33: =+G33+D33 -> 493374819397 | K33: =+H33+E33 -> 493374819397 | L33: =+I33+F33 -> 493374819397 | M33: =+IFERROR(K33*100/C33,0) -> 53.71666 | N33: =+IFERROR(L33*100/C33,0) -> 53.71666
A34: A-3-9-3-0-01 | B34: Incapacidades SSF | C34: =+VLOOKUP(A34,gasto!$A$4:$F$66,3,FALSE) -> 695721754000 | D34: 320915760505 | E34: 320915760505 | F34: 320915760505 | G34: =+VLOOKUP(A34,gasto!$A$4:$F$66,4,FALSE) -> 54643567946 | H34: =+VLOOKUP(A34,gasto!$A$4:$F$66,5,FALSE) -> 54643567946 | I34: =+VLOOKUP(A34,gasto!$A$4:$F$66,6,FALSE) -> 54643567946 | J34: =+G34+D34 -> 375559328451 | K34: =+H34+E34 -> 375559328451 | L34: =+I34+F34 -> 375559328451 | M34: =+IFERROR(K34*100/C34,0) -> 53.981254 | N34: =+IFERROR(L34*100/C34,0) -> 53.981254
A35: A-3-9-3-0-02 | B35: Incapacidades CSF | C35: =+VLOOKUP(A35,gasto!$A$4:$F$66,3,FALSE) -> 222754605163 | D35: 103158636851 | E35: 103158636851 | F35: 103158636851 | G35: =+VLOOKUP(A35,gasto!$A$4:$F$66,4,FALSE) -> 14656854095 | H35: =+VLOOKUP(A35,gasto!$A$4:$F$66,5,FALSE) -> 14656854095 | I35: =+VLOOKUP(A35,gasto!$A$4:$F$66,6,FALSE) -> 14656854095 | J35: =+G35+D35 -> 117815490946 | K35: =+H35+E35 -> 117815490946 | L35: =+I35+F35 -> 117815490946 | M35: =+IFERROR(K35*100/C35,0) -> 52.89026 | N35: =+IFERROR(L35*100/C35,0) -> 52.89026
A36: A-3-9-4-0 | B36: Licencias de Maternidad y Paternidad | C36: =+VLOOKUP(A36,gasto!$A$4:$F$66,3,FALSE) -> 720776535000 | D36: 390321222008 | E36: 390321222008 | F36: 390321222008 | G36: =+VLOOKUP(A36,gasto!$A$4:$F$66,4,FALSE) -> 63849372089 | H36: =+VLOOKUP(A36,gasto!$A$4:$F$66,5,FALSE) -> 63849372089 | I36: =+VLOOKUP(A36,gasto!$A$4:$F$66,6,FALSE) -> 63849372089 | J36: =+G36+D36 -> 454170594097 | K36: =+H36+E36 -> 454170594097 | L36: =+I36+F36 -> 454170594097 | M36: =+IFERROR(K36*100/C36,0) -> 63.01129 | N36: =+IFERROR(L36*100/C36,0) -> 63.01129
A37: A-3-9-5-0 | B37: Prestaciones Económicas Regímenes Especial y de Excepción | C37: =+VLOOKUP(A37,gasto!$A$4:$F$66,3,FALSE) -> 3500000000 | D37: 3482123570 | E37: 1241773927 | F37: 1241773927 | G37: =+VLOOKUP(A37,gasto!$A$4:$F$66,4,FALSE) -> 0 | H37: =+VLOOKUP(A37,gasto!$A$4:$F$66,5,FALSE) -> 213932519 | I37: =+VLOOKUP(A37,gasto!$A$4:$F$66,6,FALSE) -> 213932519 | J37: =+G37+D37 -> 3482123570 | K37: =+H37+E37 -> 1455706446 | L37: =+I37+F37 -> 1455706446 | M37: =+IFERROR(K37*100/C37,0) -> 41.591613 | N37: =+IFERROR(L37*100/C37,0) -> 41.591613
A38: A-3-9-6-0 | B38: UPC Régimen Subsidiado | C38: =+SUM(C39:C40) -> 18322124359802 | D38: 9.4945026e+12 | E38: 9.4945026e+12 | F38: 9.4945026e+12 | G38: =+SUM(G39:G40) -> 1.6150247e+12 | H38: =+SUM(H39:H40) -> 1.6150247e+12 | I38: =+SUM(I39:I40) -> 1.6150247e+12 | J38: =+G38+D38 -> 1.1109527e+13 | K38: =+H38+E38 -> 1.1109527e+13 | L38: =+I38+F38 -> 1.1109527e+13 | M38: =+IFERROR(K38*100/C38,0) -> 60.634494 | N38: =+IFERROR(L38*100/C38,0) -> 60.634494
A39: A-3-9-6-0-01 | B39: UPC´S R.S. Cajas de Compensación Familiar SSF | C39: =+VLOOKUP(A39,gasto!$A$4:$F$66,3,FALSE) -> 26475329000 | D39: 12902733786 | E39: 12902733786 | F39: 12902733786 | G39: =+VLOOKUP(A39,gasto!$A$4:$F$66,4,FALSE) -> 2150455631 | H39: =+VLOOKUP(A39,gasto!$A$4:$F$66,5,FALSE) -> 2150455631 | I39: =+VLOOKUP(A39,gasto!$A$4:$F$66,6,FALSE) -> 2150455631 | J39: =+G39+D39 -> 15053189417 | K39: =+H39+E39 -> 15053189417 | L39: =+I39+F39 -> 15053189417 | M39: =+IFERROR(K39*100/C39,0) -> 56.857422 | N39: =+IFERROR(L39*100/C39,0) -> 56.857422
A40: A-3-9-6-0-02 | B40: UPC´S R.S. CSF | C40: =+VLOOKUP(A40,gasto!$A$4:$F$66,3,FALSE) -> 18295649030802 | D40: 9.4815999e+12 | E40: 9.4815999e+12 | F40: 9.4815999e+12 | G40: =+VLOOKUP(A40,gasto!$A$4:$F$66,4,FALSE) -> 1.6128742e+12 | H40: =+VLOOKUP(A40,gasto!$A$4:$F$66,5,FALSE) -> 1.6128742e+12 | I40: =+VLOOKUP(A40,gasto!$A$4:$F$66,6,FALSE) -> 1.6128742e+12 | J40: =+G40+D40 -> 1.1094474e+13 | K40: =+H40+E40 -> 1.1094474e+13 | L40: =+I40+F40 -> 1.1094474e+13 | M40: =+IFERROR(K40*100/C40,0) -> 60.639959 | N40: =+IFERROR(L40*100/C40,0) -> 60.639959
A41: A-3-9-7-0 | B41: Prestaciones Excepcionales - Recobros | C41: =+SUM(C42:C43) -> 2.1986543e+12 | D41: 1.3792019e+12 | E41: 1.3792019e+12 | F41: 1.3792019e+12 | G41: =+SUM(G42:G43) -> 6.6437945e+11 | H41: =+SUM(H42:H43) -> 6.6437945e+11 | I41: =+SUM(I42:I43) -> 6.6437945e+11 | J41: =+G41+D41 -> 2.0435813e+12 | K41: =+H41+E41 -> 2.0435813e+12 | L41: =+I41+F41 -> 2.0435813e+12 | M41: =+IFERROR(K41*100/C41,0) -> 92.946914 | N41: =+IFERROR(L41*100/C41,0) -> 92.946914
A42: A-3-9-7-0-01 | B42: Recobros - Reembolsos Régimen Contributivo | C42: =+VLOOKUP(A42,gasto!$A$4:$F$66,3,FALSE) -> 2.1861591e+12 | D42: 1.3710982e+12 | E42: 1.3710982e+12 | F42: 1.3710982e+12 | G42: =+VLOOKUP(A42,gasto!$A$4:$F$66,4,FALSE) -> 6.635177e+11 | H42: =+VLOOKUP(A42,gasto!$A$4:$F$66,5,FALSE) -> 6.635177e+11 | I42: =+VLOOKUP(A42,gasto!$A$4:$F$66,6,FALSE) -> 6.635177e+11 | J42: =+G42+D42 -> 2.0346159e+12 | K42: =+H42+E42 -> 2.0346159e+12 | L42: =+I42+F42 -> 2.0346159e+12 | M42: =+IFERROR(K42*100/C42,0) -> 93.06806 | N42: =+IFERROR(L42*100/C42,0) -> 93.06806
A43: A-3-9-7-0-02 | B43: Recobros - Reembolsos Régimen Subsidiado - Tutelas | C43: =+VLOOKUP(A43,gasto!$A$4:$F$66,3,FALSE) -> 12495208000 | D43: 8.1037283e+09 | E43: 8.1037283e+09 | F43: 8.1037283e+09 | G43: =+VLOOKUP(A43,gasto!$A$4:$F$66,4,FALSE) -> 8.6174876e+08 | H43: =+VLOOKUP(A43,gasto!$A$4:$F$66,5,FALSE) -> 8.6174876e+08 | I43: =+VLOOKUP(A43,gasto!$A$4:$F$66,6,FALSE) -> 8.6174876e+08 | J43: =+G43+D43 -> 8.965477e+09 | K43: =+H43+E43 -> 8.965477e+09 | L43: =+I43+F43 -> 8.965477e+09 | M43: =+IFERROR(K43*100/C43,0) -> 71.751323 | N43: =+IFERROR(L43*100/C43,0) -> 71.751323
...

Sheet gasto
A2: CÓDIGO RUBRO | B2: CONCEPTO DEL RUBRO | C2: APROPIACIÓN DEFINITIVA | D2: CDP | E2: RP | F2: PAGOS-OGAG | G2: T. CDP | H2: T. RP | I2: T. PAGOS-OGAG | J2: % | K2: RP
A3: URA
A4: A-3-2-1-0 | B4: Transferencias Entidades de Administración Pública Central | C4: 74955308000 | D4: 0 | E4: 6130525813 | F4: 6130525813 | G4: 73566309756 | H4: 42913680691 | I4: 42913680691 | J4: 57.25 | K4: 57.25
A5: A-3-2-1-01 | B5: Contribución IVC Superintendencia Nacional de Salud | C5: 74955308000 | D5: 0 | E5: 6130525813 | F5: 6130525813 | G5: 73566309756 | H5: 42913680691 | I5: 42913680691 | J5: 57.25 | K5: 57.25
A6: A-3-2-2-0 | B6: Empresas Públicas Nacionales no financieras -ADRES | C6: 122333530698 | D6: 0 | E6: 5925786025 | F6: 5925786025 | G6: 1.0094811e+11 | H6: 3.7100123e+10 | I6: 3.7100123e+10 | J6: 30.33 | K6: 30.33
A7: A-3-2-2-0-01 | B7: Aportes hasta del 0,5% recursos CSF para el desarrollo objeto ADRES | C7: 122333530698 | D7: 0 | E7: 5925786025 | F7: 5925786025 | G7: 1.0094811e+11 | H7: 3.7100123e+10 | I7: 3.7100123e+10 | J7: 30.33 | K7: 30.33
A8: A-3-6-1-0 | B8: Sentencias y Conciliaciones URA | C8: 6000000000 | D8: 1.2620085e+09 | E8: 0 | F8: 0 | G8: 3.7154772e+09 | H8: 2.4534687e+09 | I8: 2.4534687e+09 | J8: 40.89 | K8: 40.89
A9: A-3-6-1-1 | B9: Sentencias URA | C9: 6000000000 | D9: 1.2620085e+09 | E9: 0 | F9: 0 | G9: 3.7154772e+09 | H9: 2.4534687e+09 | I9: 2.4534687e+09 | J9: 40.89 | K9: 40.89
A10: A-3-6-1-2 | B10: Conciliaciones URA | C10: 0 | D10: 0 | E10: 0 | F10: 0 | G10: 0 | H10: 0 | I10: 0 | J10: 0 | K10: 0
A11: A-3-6-3-0 | B11: Destinatarios de otras transferencias Corrientes - Compensación Chance | C11: 0 | D11: 0 | E11: 0 | F11: 0 | G11: 0 | H11: 0 | I11: 0 | J11: 0 | K11: 0
A12: A-3-6-3-0-01 | B12: Otras transferencias - Compensación del Chance Decreto 2550/12 | C12: 0 | D12: 0 | E12: 0 | F12: 0 | G12: 0 | H12: 0 | I12: 0 | J12: 0 | K12: 0
A13: A-3-9-1-0 | B13: UPC Régimen Contributivo | C13: 19815600876556 | D13: 1706562364495 | E13: 1706562364495 | F13: 1706562364495 | G13: 12016950638336 | H13: 12016950638336 | I13: 12016950638336 | J13: 60.64 | K13: 60.64
A14: A-3-9-1-0-01 | B14: UPC Régimen Contributivo SSF | C14: 11897430272837 | D14: 952008781043 | E14: 952008781043 | F14: 952008781043 | G14: 6559201207223 | H14: 6559201207223 | I14: 6559201207223 | J14: 55.13 | K14: 55.13
A15: A-3-9-1-0-02 | B15: UPC Régimen Contributivo CSF | C15: 7834554371500 | D15: 754410079007 | E15: 754410079007 | F15: 754410079007 | G15: 5455744563130 | H15: 5455744563130 | I15: 5455744563130 | J15: 69.64 | K15: 69.64
... A55: A-3-9-11-0-05 | B55: Excedentes de Aportes Patronales / Resolución 2360 de 2016 | C55: 51800427204 | D55: 0 | E55: 0 | F55: 0 | G55: 1801877460 | H55: 1801877460 | I55: 1801877460 | J55: 3.48 | K55: 3.48
A56: A-3-9-11-0-06 | C56: 6973769571 | D56: 0 | E56: 0 | F56: 0 | G56: 0 | H56: 0 | I56: 0 | J56: 0 | K56: 0
A57: A-3-9-11-0-07 | B57: Otros Recursos con Destinación Especifica | C57: 59589973000 | D57: 377836513 | E57: 0 | F57: 0 | G57: 377836513 | H57: 0 | I57: 0 | J57: 0 | K57: 0
A58: A-3-9-12-0 | B58: Pago Obligaciones ESE´S con Recursos FONSAET | C58: 51737471000 | D58: 0 | E58: 0 | F58: 0 | G58: 0 | H58: 0 | I58: 0 | J58: 0 | K58: 0
A59: A-3-9-12-0-01 | B59: Pago Obligaciones EPS FONSAET | C59: 51737471000 | D59: 0 | E59: 0 | F59: 0 | G59: 0 | H59: 0 | I59: 0 | J59: 0 | K59: 0
A60: A-3-9-13-0 | B60: Reconocimiento Rendimientos Financieros cuentas de recaudo EPS SSF | C60: 4936416000 | D60: 557336218 | E60: 557336218 | F60: 557336218 | G60: 3753022278 | H60: 3753022278 | I60: 3753022278 | J60: 76.03 | K60: 76.03
A61: A-3-9-13-0-01 | B61: Rendimientos Financieros EPS SSF | C61: 4936416000 | D61: 557336218 | E61: 557336218 | F61: 557336218 | G61: 3753022278 | H61: 3753022278 | I61: 3753022278 | J61: 76.03 | K61: 76.03
A62: A-3-9-14-0 | B62: Apoyo Financiero y Fortalecimiento Patrimonial a las Entidades del Sector Salud | C62: 50000000000 | D62: 0 | E62: 0 | F62: 0 | G62: 0 | H62: 0 | I62: 0 | J62: 0 | K62: 0
A63: A-3-9-14-0-01 | B63: Operaciones de Compra de Cartera | C63: 50000000000 | D63: 0 | E63: 0 | F63: 0 | G63: 0 | H63: 0 | I63: 0 | J63: 0 | K63: 0
A64: A-3-9-14-0-02 | B64: Operaciones de Fortalecimiento Patrimonial Tasa Compensada | C64: 0 | D64: 0 | E64: 0 | F64: 0 | G64: 0 | H64: 0 | I64: 0 | J64: 0 | K64: 0
A65: A-3-9-14-0-03 | B65: Operaciones de Fortalecimiento Patrimonial - Bocas | C65: 0 | D65: 0 | E65: 0 | F65: 0 | G65: 0 | H65: 0 | I65: 0 | J65: 0 | K65: 0
A66: A-9-9-9-9 | B66: Disponibilidad Final | C66: 0 | D66: 0 | E66: 0 | F66: 0 | G66: 0 | H66: 0 | I66: 0 | J66: 0 | K66: 0

Sheet Hoja1
A3: ADMINISTRADORA DE LOS RECURSOS DEL SISTEMA GENERAL DE SEGURIDAD SOCIAL EN SALUD
A4: PRESUPUESTO DE INGRESOS 2017
A5: UNIDAD DE RECURSOS ADMINISTRADOS - URA
A6: CUADRO No. 1
A8: 1 | B8: 2 | C8: 3 | D8: 4 | E8: 5 | F8: 6 | G8: 7 | H8: 8 | I8: 9 | J8: 10
A9: CÓDIGO RUBRO | B9: CONCEPTO DEL RUBRO | C9: AFORO INICIAL | D9: MODIFICACIÓN PRESUPUESTAL | E9: AFORO DEFINITIVO | F9: Ingresos Acumulados Desde 01/08/2017 hasta 30/11/2017 | G9: Ingresos Desde 01/12/2017 hasta 31/12/2017 | H9: Ingresos Acumulados Desde 01/08/2017 hasta 31/12/2017 | I9: EJECUCIÓN ACUMULADA (%) | J9: PARTICIPACIÓN %
A10: URA
A11: 0-0-0-0 | B11: DISPONIBILIDAD INICIAL | C11: 1049732777065 | D11: 1028793184133 | E11: 2078525961198 | F11: 3.7980893e+11 | G11: 1.698717e+12 | H11: 2.078526e+12 | I11: 100 | J11: 11.173515
A12: 1-2-1-1 | B12: Aportes de la Nación para el Aseguramiento en Salud | C12: 800000000000 | D12: 0 | E12: 800000000000 | F12: 800000000000 | G12: 0 | H12: 800000000000 | I12: 100 | J12: 4.3005534
A13: 1-2-1-1-01 | B13: Aportes de la Nación para el Aseguramiento en Salud Cierre | C13: 800000000000 | D13: 0 | E13: 800000000000 | F13: 800000000000 | G13: 0 | H13: 800000000000 | I13: 100 | J13: 4.3005534
A14: 1-2-1-2 | B14: Compensación Regalías para el Régimen Subsidiado | C14: 0 | D14: 0 | E14: 0 | F14: 0 | G14: 0 | H14: 0 | I14: 0 | J14: 0
A15: 1-2-1-3 | B15: Impuesto sobre la renta para la equidad CREE | C15: 3379423220743 | D15: 0 | E15: 3379423220743 | F15: 2645477901368 | G15: 661369475338 | H15: 3306847376706 | I15: 97.852419 | J15: 17.776592
A16: 1-2-1-4 | B16: SGP FONSAET | C16: 76906712050 | D16: 0 | E16: 76906712050 | F16: 76906712050 | G16: 0 | H16: 76906712050 | I16: 100 | J16: 0.41342677
A17: 1-2-1-5 | B17: PRIMA FONSAT Y CONTRIBUCION SOAT | C17: 630863569234 | D17: 0 | E17: 630863569234 | F17: 4.9668302e+11 | G17: 93551929250 | H17: 5.9023495e+11 | I17: 93.55984 | J17: 3.1729211
A18: 1-2-1-5-01 | B18: % Prima (FONSAT) Decreto Ley 1335 de 2009 | C18: 153176997329 | D18: 0 | E18: 153176997329 | F18: 1.0986192e+11 | G18: 0 | H18: 1.0986192e+11 | I18: 71.722205 | J18: 0.59058382
A19: 1-2-1-5-02 | B19: Contribución Seguro Obligatorio de Accidentes de Tránsito - SOAT- Decreto Ley 1335 de 2009 | C19: 477686571905 | D19: 0 | E19: 477686571905 | F19: 386821096950 | G19: 93551929250 | H19: 480373026200 | I19: 100.56239 | J19: 2.5823373
A20: 1-2-1-7 | B20: Impuesto social a las municiones y explosivos | C20: 31868595127 | D20: 0 | E20: 31868595127 | F20: 31727550335 | G20: 7899641418 | H20: 39627191753 | I20: 124.34559 | J20: 0.21302357
A21: 1-2-1-8 | B21: Impuesto social a las armas | C21: 3612249620 | D21: 0 | E21: 3612249620 | F21: 3452971135 | G21: 969138385 | H21: 4422109520 | I21: 122.41982 | J21: 0.023771897
A22: 1-2-9-0 | B22: Otros aportes e impuestos de la nación | C22: 0 | D22: 0 | E22: 0 | F22: 0 | G22: 0 | H22: 0 | I22: 0 | J22: 0
... A86: 2-9-1-0-06 | B86: Regalías – artículo 5 Ley 1797 de 2016 | C86: 5000000000 | D86: 0 | E86: 5000000000 | F86: 0 | G86: 0 | H86: 0 | I86: 0 | J86: 0
B88: TOTAL | C88: 16692931290975 | D88: 1405041818640 | E88: 18097973109615 | F88: 1.3761589e+13 | G88: 4.8406684e+12 | H88: 1.8602257e+13 | I88: 102.78641 | J88: 100
C90: 16692931290975 | D90: 1405041818640 | E90: 18097973109615 | F90: 1.3761589e+13 | G90: 4.8406684e+12 | H90: 1.8602257e+13 | I90: 102.78641
C91: =+C90-C88 -> 0 | D91: =+D90-D88 -> 0 | E91: =+E90-E88 -> 0 | F91: =+F90-F88 -> 0 | G91: =+G90-G88 -> 0 | H91: =+H90-H88 -> 0 | I91: =+I90-I88 -> 0

Sheet Hoja2
A3: ADMINISTRADORA DE LOS RECURSOS DEL SISTEMA GENERAL DE SEGURIDAD SOCIAL EN SALUD
A4: PRESUPUESTO DE GASTOS 2017
A5: UNIDAD DE RECURSOS ADMINISTRADOS - URA
A6: CUADRO No. 2
A8: 1 | B8: 2 | C8: 3 | D8: 4 | E8: 5 | F8: 6 | G8: 7 | H8: 8 | I8: 9 | J8: 10 | K8: 11 | L8: 12 | M8: 13 | N8: 14
A9: CÓDIGO RUBRO | B9: CONCEPTO DEL RUBRO | C9: APROPIACIÓN DEFINITIVA | D9: EJECUCIÓN PRESUPUESTAL ACUMULADA DESDE 01/08/2017 HASTA 30/11/2017 | G9: EJECUCIÓN PRESUPUESTAL 01/12/2017 HASTA 31/12/2017 | J9: EJECUCIÓN PRESUPUESTAL ACUMULADA DESDE 01/08/2017 HASTA 31/12/2017 | M9: % | O9: SALDO APROPIACIÓN | P9: COMPROMISOS POR PAGAR | Q9: %
D10: T. CDP | E10: T. RP | F10: T. PAGOS-OP | G10: CDP | H10: RP | I10: OP | J10: T. CDP | K10: T. RP | L10: T. PAGOS-OP | M10: RP | N10: OP | Q10: PARTICIPACIÓN
B11: URA
A12: A-9-9-9-9 | B12: Disponibilidad Final | C12: 169607386609 | D12: 0 | E12: 0 | F12: 0 | G12: 0 | H12: 0 | I12: 0 | J12: 0 | K12: 0 | L12: 0 | M12: 0 | N12: 0 | O12: 169607386609 | P12: 0 | Q12: 0
A13: A-3-2-1-0 | B13: Transferencias Entidades de Administración Pública Central | C13: 40479356618 | D13: 22483398888 | E13: 22483398888 | F13: 22483398888 | G13: 5620849724 | H13: 5620849724 | I13: 5620849724 | J13: 28104248612 | K13: 28104248612 | L13: 28104248612 | M13: 69.428595 | N13: 69.428595 | O13: 12375108006 | P13: 0 | Q13: 0.15813624
A14: A-3-2-1-0-01 | B14: Contribución IVC Superintendencia Nacional de Salud | C14: 40479356618 | D14: 22483398888 | E14: 22483398888 | F14: 22483398888 | G14: 5620849724 | H14: 5620849724 | I14: 5620849724 | J14: 28104248612 | K14: 28104248612 | L14: 28104248612 | M14: 69.428595 | N14: 69.428595 | O14: 12375108006 | P14: 0 | Q14: 0.15813624
A15: A-3-2-2-0 | B15: Empresas Públicas Nacionales no financieras | C15: 54432463826 | D15: 54432463826 | E15: 6219861165 | F15: 6219861165 | G15: -1.737463e+10 | H15: 3.0837973e+10 | I15: 9100000000 | J15: 3.7057834e+10 | K15: 3.7057834e+10 | L15: 15319861165 | M15: 68.08039 | N15: 28.144714 | O15: 1.737463e+10 | P15: 2.1737973e+10 | Q15: 0.086201391
A16: A-3-2-2-0-01 | B16: Aportes hasta del 0,5% recursos CSF para el desarrollo objeto ADRES | C16: 54432463826 | D16: 54432463826 | E16: 6219861165 | F16: 6219861165 | G16: -1.737463e+10 | H16: 3.0837973e+10 | I16: 9100000000 | J16: 3.7057834e+10 | K16: 3.7057834e+10 | L16: 15319861165 | M16: 68.08039 | N16: 28.144714 | O16: 1.737463e+10 | P16: 2.1737973e+10 | Q16: 0.086201391
A17: A-3-6-1-0 | B17: Sentencias y Conciliaciones URA | C17: 5059377749 | D17: 1.2391943e+08 | E17: 0 | F17: 0 | G17: 2.2315349e+09 | H17: 2.3554543e+09 | I17: 2.331944e+09 | J17: 2.3554543e+09 | K17: 2.3554543e+09 | L17: 2.331944e+09 | M17: 46.556205 | N17: 46.091518 | O17: 2.7039235e+09 | P17: 23510302 | Q17: 0.013121321
A18: A-3-6-1-1 | B18: Sentencias URA | C18: 5059377749 | D18: 1.2391943e+08 | E18: 0 | F18: 0 | G18: 2.2315349e+09 | H18: 2.3554543e+09 | I18: 2.331944e+09 | J18: 2.3554543e+09 | K18: 2.3554543e+09 | L18: 2.331944e+09 | M18: 46.556205 | N18: 46.091518 | O18: 2.7039235e+09 | P18: 23510302 | Q18: 0.013121321
A19: A-3-6-1-2 | B19: Conciliaciones URA | C19: 0 | D19: 0 | E19: 0 | F19: 0 | G19: 0 | H19: 0 | I19: 0 | J19: 0 | K19: 0 | L19: 0 | M19: 0 | N19: 0 | O19: 0 | P19: 0 | Q19: 0
A20: A-3-6-3-0 | B20: Destinatarios de otras transferencias Corrientes | C20: 30652000000 | D20: 0 | E20: 0 | F20: 0 | G20: 30652000000 | H20: 30652000000 | I20: 30652000000 | J20: 30652000000 | K20: 30652000000 | L20: 30652000000 | M20: 100 | N20: 100 | O20: 0 | P20: 0 | Q20: 0.17247187
A21: A-3-6-3-0-01 | B21: Otras trasnferencias - Compensación del Chance Decreto 2550/12 | C21: 30652000000 | D21: 0 | E21: 0 | F21: 0 | G21: 30652000000 | H21: 30652000000 | I21: 30652000000 | J21: 30652000000 | K21: 30652000000 | L21: 30652000000 | M21: 100 | N21: 100 | O21: 0 | P21: 0 | Q21: 0.17247187
A22: A-3-9-1-0 | B22: UPC Régimen Contributivo | C22: 8076746600070 | D22: 6430211471821 | E22: 6430211471821 | F22: 6424483625438 | G22: 1646200098083 | H22: 1646200098083 | I22: 1651927944466 | J22: 8076411569904 | K22: 8076411569904 | L22: 8076411569904 | M22: 99.995852 | N22: 99.995852 | O22: 335030166 | P22: 0 | Q22: 45.44414
A23: A-3-9-1-0-01 | B23: UPC Régimen Contributivo SSF | C23: 4576838798468 | D23: 3638853998008 | E23: 3638853998008 | F23: 3636391786062 | G23: 937983462711 | H23: 937983462711 | I23: 940445674657 | J23: 4576837460719 | K23: 4576837460719 | L23: 4576837460719 | M23: 99.999971 | N23: 99.999971 | O23: 1337749 | P23: 0 | Q23: 25.752828
... A74: TOTAL | B74: TOTAL | C74: 18097973109615 | D74: 1.3816938e+13 | E74: 1.3767785e+13 | F74: 1.3761589e+13 | G74: 3.9977088e+12 | H74: 4.0468615e+12 | I74: 4.0105851e+12 | J74: 1.7814647e+13 | K74: 1.7814647e+13 | L74: 1.7772174e+13 | M74: 98.434486 | N74: 98.199803 | O74: 2.8332622e+11 | P74: 4.2472859e+10 | Q74: 100
C76: 16692931290975 | D76: 1.3816938e+13 | E76: 1.3816938e+13 | F76: 1.3816938e+13 | G76: 3.9977088e+12 | H76: 4.0468615e+12 | I76: 4.0105851e+12 | J76: 1.3816938e+13 | K76: 1.3816938e+13 | L76: 1.3816938e+13 | M76: 82.771191 | N76: 82.771191
C77: =+C76-C74 -> -1405041818640 | D77: =+D76-D74 -> 0 | E77: =+E76-E74 -> 4.9152731e+10 | F77: =+F76-F74 -> 5.5349216e+10 | G77: =+G76-G74 -> 0 | H77: =+H76-H74 -> 0 | I77: =+I76-I74 -> 0 | J77: =+J76-J74 -> -3.9977088e+12 | ... N77: =+N76-N74 -> -15.428612
