Workbook
Name OLE_LINK1: 'CUADRO 2-EJECUCION DE GASTOS'!#REF!

Sheet CUADRO 1-EJECUCION DE INGRESOS
H1: =+NOW() -> 43818.489 | I1: =+NOW() -> 43818.489
A3: ADMINISTRADORA DE LOS RECURSOS DEL SISTEMA GENERAL DE SEGURIDAD SOCIAL EN SALUD
A4: UNIDAD DE RECURSOS ADMINISTRADOS - URA
A5: CODIGO DE LA EMPRESA 12902 - ADMINISTRACION DE RECURSOS DEL SGSSS
A6: PRESUPUESTO DE INGRESOS DE NOVIEMBRE DE 2019
A7: CUADRO No. 1
A10: CÓDIGO RUBRO | B10: CONCEPTO DEL RUBRO | C10: AFORO INICIAL | D10: MODIFICACIÓN PRESUPUESTAL | E10: AFORO DEFINITIVO | F10: Ingresos Acumulados Desde 01/01/2019 hasta 31/10/2019 | G10: Ingresos Desde 01/11/2019 hasta 30/11/2019 | H10: Ingresos Acumulados Desde 01/01/2019 hasta 30/11/2019 | I10: EJECUCIÓN ACUMULADA (%)
A11: URA
A12: 0-0-0-0 | B12: =+VLOOKUP(A12,Ingresos!$A$2:$B$200,2,FALSE) -> Disponibilidad inicial | C12: 422831681000 | D12: =+VLOOKUP(A12,Ingresos!$A$1:$F$90,3,FALSE) -> 0 | E12: =+VLOOKUP(A12,Ingresos!$A$1:$F$200,4,FALSE) -> 910932869290 | F12: 910932869290 | G12: =+VLOOKUP(A12,Ingresos!$A$1:$E$200,5,FALSE) -> 0 | H12: =+G12+F12 -> 910932869290 | I12: =IFERROR(H12/E12*100,0) -> 100 | J12: =+H12/1000000 -> 910932.87
A13: 1-0-0-0 | B13: INGRESOS CORRIENTES | C13: 52054407755223 | D13: =+D14+D28 -> 0 | E13: =+E14+E28 -> 49290407755223 | F13: 4.2146255e+13 | G13: =+G14+G28 -> 4.7689103e+12 | H13: =+G13+F13 -> 4.6915166e+13 | I13: =IFERROR(H13/E13*100,0) -> 95.181127 | J13: =+H13/1000000 -> 46915166
A14: 1-2-0-0 | B14: Aportes e Impuestos | C14: 19781797637181 | D14: =+D15 -> 0 | E14: =+E15+E27 -> 17017797637181 | F14: 14510629164728 | G14: =+G15+G27 -> 1.3592823e+12 | H14: =+G14+F14 -> 1.5869911e+13 | I14: =IFERROR(H14/E14*100,0) -> 93.25479 | J14: =+H14/1000000 -> 15869911
A15: 1-2-1-0 | B15: Aportes de la Nación | C15: 19781797637181 | D15: =+D16+D19+D20+D21+D22+D25+D26 -> 0 | E15: =+E16+E19+E20+E21+E22+E26+E25+E27 -> 17017797637181 | F15: 14510629164728 | G15: =+G16+G19+G20+G21+G22+G26+G25+G27 -> 1.3592823e+12 | H15: =+G15+F15 -> 1.5869911e+13 | I15: =IFERROR(H15/E15*100,0) -> 93.25479 | J15: =+H15/1000000 -> 15869911
A16: 1-2-1-1 | B16: =+VLOOKUP(A16,Ingresos!$A$2:$B$200,2,FALSE) -> Aportes de la Nación para el Aseguramiento en Salud | C16: 17803782346000 | D16: =+D17+D18 -> 0 | E16: =+E17+E18 -> 15039782346000 | F16: 1.2676174e+13 | G16: =+SUM(G17:G18) -> 1160204084389 | H16: =+G16+F16 -> 1.3836378e+13 | I16: =IFERROR(H16/E16*100,0) -> 91.998527 | J16: =+H16/1000000 -> 13836378
A17: 1-2-1-1-01 | B17: =+VLOOKUP(A17,Ingresos!$A$2:$B$200,2,FALSE) -> Aportes de la Nación para el Aseguramiento en Salud Cierre | C17: 13686804885516 | D17: =+VLOOKUP(A17,Ingresos!$A$1:$F$90,3,FALSE) -> 0 | E17: =+VLOOKUP(A17,Ingresos!$A$1:$F$200,4,FALSE) -> 9743321670830 | F17: 8.456764e+12 | G17: =+VLOOKUP(A17,Ingresos!$A$1:$E$200,5,FALSE) -> 6.2167882e+11 | H17: =+G17+F17 -> 9.0784429e+12 | I17: =IFERROR(H17/E17*100,0) -> 93.176056 | J17: =+H17/1000000 -> 9078442.9
A18: 1-2-1-1-02 | B18: =+VLOOKUP(A18,Ingresos!$A$2:$B$200,2,FALSE) -> Imporenta | C18: 4116977460484 | D18: =+VLOOKUP(A18,Ingresos!$A$1:$F$90,3,FALSE) -> 0 | E18: =+VLOOKUP(A18,Ingresos!$A$1:$F$200,4,FALSE) -> 5296460675170 | F18: 4.2194101e+12 | G18: =+VLOOKUP(A18,Ingresos!$A$1:$E$200,5,FALSE) -> 5.3852527e+11 | H18: =+G18+F18 -> 4.7579354e+12 | I18: =IFERROR(H18/E18*100,0) -> 89.832356 | J18: =+H18/1000000 -> 4757935.4
A19: 1-2-1-2 | B19: =+VLOOKUP(A19,Ingresos!$A$2:$B$200,2,FALSE) -> Compensación Regalías para el Régimen Subsidiado | C19: 226673765000 | D19: =+VLOOKUP(A19,Ingresos!$A$1:$F$90,3,FALSE) -> 0 | E19: =+VLOOKUP(A19,Ingresos!$A$1:$F$200,4,FALSE) -> 226673765000 | F19: 226673765000 | G19: =+VLOOKUP(A19,Ingresos!$A$1:$E$200,5,FALSE) -> 0 | H19: =+G19+F19 -> 226673765000 | I19: =IFERROR(H19/E19*100,0) -> 100 | J19: =+H19/1000000 -> 226673.77
A20: 1-2-1-3 | B20: =+VLOOKUP(A20,Ingresos!$A$2:$B$200,2,FALSE) -> Impuesto sobre la renta para la equidad CREE | C20: 0 | D20: =+VLOOKUP(A20,Ingresos!$A$1:$F$90,3,FALSE) -> 0 | E20: =+VLOOKUP(A20,Ingresos!$A$1:$F$200,4,FALSE) -> 0 | F20: 0 | G20: =+VLOOKUP(A20,Ingresos!$A$1:$E$200,5,FALSE) -> 0 | H20: =+G20+F20 -> 0 | I20: =IFERROR(H20/E20*100,0) -> 0 | J20: =+H20/1000000 -> 0
A21: 1-2-1-4 | B21: =+VLOOKUP(A21,Ingresos!$A$2:$B$200,2,FALSE) -> SGP FONSAET | C21: 95551523562 | D21: =+VLOOKUP(A21,Ingresos!$A$1:$F$90,3,FALSE) -> 0 | E21: =+VLOOKUP(A21,Ingresos!$A$1:$F$200,4,FALSE) -> 95551523562 | F21: 0 | G21: =+VLOOKUP(A21,Ingresos!$A$1:$E$200,5,FALSE) -> 0 | H21: =+G21+F21 -> 0 | I21: =IFERROR(H21/E21*100,0) -> 0 | J21: =+H21/1000000 -> 0
A22: 1-2-1-5 | B22: =+VLOOKUP(A22,Ingresos!$A$2:$B$200,2,FALSE) -> PRIMA FONSAT Y CONTRIBUCION SOAT | C22: 1640527441000 | D22: =+D23+D24 -> 0 | E22: =+E23+E24 -> 1640527441000 | F22: 1.5016448e+12 | G22: =+SUM(G23:G24) -> 1.8790881e+11 | H22: =+G22+F22 -> 1.6895536e+12 | I22: =IFERROR(H22/E22*100,0) -> 102.98844 | J22: =+H22/1000000 -> 1689553.6
A23: 1-2-1-5-01 | B23: =+VLOOKUP(A23,Ingresos!$A$2:$B$200,2,FALSE) -> % Prima (FONSAT) Decreto Ley 1335 de 2009 | C23: 363281118360 | D23: =+VLOOKUP(A23,Ingresos!$A$1:$F$90,3,FALSE) -> 0 | E23: =+VLOOKUP(A23,Ingresos!$A$1:$F$200,4,FALSE) -> 363281118360 | F23: 3.2982961e+11 | G23: =+VLOOKUP(A23,Ingresos!$A$1:$E$200,5,FALSE) -> 6.7235893e+10 | H23: =+G23+F23 -> 3.9706551e+11 | I23: =IFERROR(H23/E23*100,0) -> 109.29979 | J23: =+H23/1000000 -> 397065.51
A24: 1-2-1-5-02 | B24: =+VLOOKUP(A24,Ingresos!$A$2:$B$200,2,FALSE) -> Contribución Seguro Obligatorio de Accidentes de Tránsito - SOAT- Decreto Ley 1335 de 2009 | C24: 1277246322640 | D24: =+VLOOKUP(A24,Ingresos!$A$1:$F$90,3,FALSE) -> 0 | E24: =+VLOOKUP(A24,Ingresos!$A$1:$F$200,4,FALSE) -> 1277246322640 | F24: 1.1718152e+12 | G24: =+VLOOKUP(A24,Ingresos!$A$1:$E$200,5,FALSE) -> 120672915300 | H24: =+G24+F24 -> 1.2924881e+12 | I24: =IFERROR(H24/E24*100,0) -> 101.19333 | J24: =+H24/1000000 -> 1292488.1
A25: 1-2-1-7 | B25: =+VLOOKUP(A25,Ingresos!$A$2:$B$200,2,FALSE) -> Impuesto social a las municiones y explosivos | C25: 6410791000 | D25: =+VLOOKUP(A25,Ingresos!$A$1:$F$90,3,FALSE) -> 0 | E25: =+VLOOKUP(A25,Ingresos!$A$1:$F$200,4,FALSE) -> 6410791000 | F25: 98318924241 | G25: =+VLOOKUP(A25,Ingresos!$A$1:$E$200,5,FALSE) -> 9997809749 | H25: =+G25+F25 -> 108316733990 | I25: =IFERROR(H25/E25*100,0) -> 1689.6001 | J25: =+H25/1000000 -> 108316.73
A26: 1-2-1-8 | B26: =+VLOOKUP(A26,Ingresos!$A$2:$B$200,2,FALSE) -> Impuesto social a las armas | C26: 8851770619 | D26: =+VLOOKUP(A26,Ingresos!$A$1:$F$90,3,FALSE) -> 0 | E26: =+VLOOKUP(A26,Ingresos!$A$1:$F$200,4,FALSE) -> 8851770619 | F26: 7817505342 | G26: =+VLOOKUP(A26,Ingresos!$A$1:$E$200,5,FALSE) -> 1171605398 | H26: =+G26+F26 -> 8989110740 | I26: =IFERROR(H26/E26*100,0) -> 101.55156 | J26: =+H26/1000000 -> 8989.1107
A27: 1-2-9-0 | B27: =+VLOOKUP(A27,Ingresos!$A$2:$B$200,2,FALSE) -> Otros aportes e impuestos de la nación | C27: 0 | D27: =+VLOOKUP(A27,Ingresos!$A$1:$F$90,3,FALSE) -> 0 | E27: =+VLOOKUP(A27,Ingresos!$A$1:$F$200,4,FALSE) -> 0 | F27: 0 | G27: =+VLOOKUP(A27,Ingresos!$A$1:$E$200,5,FALSE) -> 0 | H27: =+G27+F27 -> 0 | I27: =IFERROR(H27/E27*100,0) -> 0 | J27: =+H27/1000000 -> 0
A28: 1-3-0-0 | B28: Otros Ingresos Corrientes | C28: 32272610118042 | D28: =+D29 -> 0 | E28: =+E29+E58 -> 32272610118042 | F28: 2.7635626e+13 | G28: =+G29+G58 -> 3.409628e+12 | H28: =+G28+F28 -> 3.1045254e+13 | I28: =IFERROR(H28/E28*100,0) -> 96.196912 | J28: =+H28/1000000 -> 31045254
A29: 1-3-5-0 | B29: Ingresos Sistema General de Seguridad Social en Salud | C29: 22105255788877 | D29: =+D30+D33+D36+D41+D51+D54+D57 -> 0 | E29: =+E30+E33+E36+E41+E51+E54+E57 -> 22105255788877 | F29: 1.9267898e+13 | G29: =+G30+G33+G36+G41+G51+G54+G57 -> 1.886461e+12 | H29: =+G29+F29 -> 2.1154359e+13 | I29: =IFERROR(H29/E29*100,0) -> 95.698324 | J29: =+H29/1000000 -> 21154359
A30: 1-3-5-1 | B30: =+VLOOKUP(A30,Ingresos!$A$2:$B$200,2,FALSE) -> Cotizaciones al SGSSS | C30: 20346328129563 | D30: =+SUM(D31:D32) -> 0 | E30: =+SUM(E31:E32) -> 20346328129563 | F30: 16888413748856 | G30: =+SUM(G31:G32) -> 1670768305965 | H30: =+G30+F30 -> 18559182054821 | I30: =IFERROR(H30/E30*100,0) -> 91.216371 | J30: =+H30/1000000 -> 18559182
A31: 1-3-5-1-01 | B31: =+VLOOKUP(A31,Ingresos!$A$2:$B$200,2,FALSE) -> Régimen Contributivo CSF | C31: 6807438619821 | D31: =+VLOOKUP(A31,Ingresos!$A$1:$F$90,3,FALSE) -> -107990000000 | E31: =+VLOOKUP(A31,Ingresos!$A$1:$F$200,4,FALSE) -> 6699448619821 | F31: 5700380701536 | G31: =+VLOOKUP(A31,Ingresos!$A$1:$E$200,5,FALSE) -> 527551267486 | H31: =+G31+F31 -> 6227931969022 | I31: =IFERROR(H31/E31*100,0) -> 92.961859 | J31: =+H31/1000000 -> 6227932
A32: 1-3-5-1-02 | B32: =+VLOOKUP(A32,Ingresos!$A$2:$B$200,2,FALSE) -> Régimen Contributivo SSF | C32: 13538889509742 | D32: =+VLOOKUP(A32,Ingresos!$A$1:$F$90,3,FALSE) -> 107990000000 | E32: =+VLOOKUP(A32,Ingresos!$A$1:$F$200,4,FALSE) -> 13646879509742 | F32: 11188033047320 | G32: =+VLOOKUP(A32,Ingresos!$A$1:$E$200,5,FALSE) -> 1143217038479 | H32: =+G32+F32 -> 12331250085799 | I32: =IFERROR(H32/E32*100,0) -> 90.359485 | J32: =+H32/1000000 -> 12331250
A33: 1-3-5-2 | B33: =+VLOOKUP(A33,Ingresos!$A$2:$B$200,2,FALSE) -> Aporte Solidaridad de Regímenes de Excepcion y Especiales | C33: 1000356775894 | D33: =+SUM(D34:D35) -> 0 | E33: =+SUM(E34:E35) -> 1000356775894 | F33: 7.4229323e+11 | G33: =+SUM(G34:G35) -> 7.7705941e+10 | H33: =+G33+F33 -> 8.1999917e+11 | I33: =IFERROR(H33/E33*100,0) -> 81.970672 | J33: =+H33/1000000 -> 819999.17
A34: 1-3-5-2-01 | B34: =+VLOOKUP(A34,Ingresos!$A$2:$B$200,2,FALSE) -> Cotizaciones afiliados REX con ingresos adicionales | C34: 594961177882 | D34: =+VLOOKUP(A34,Ingresos!$A$1:$F$90,3,FALSE) -> 0 | E34: =+VLOOKUP(A34,Ingresos!$A$1:$F$200,4,FALSE) -> 594961177882 | F34: 434906212652 | G34: =+VLOOKUP(A34,Ingresos!$A$1:$E$200,5,FALSE) -> 44120317048 | H34: =+G34+F34 -> 479026529700 | I34: =IFERROR(H34/E34*100,0) -> 80.513914 | J34: =+H34/1000000 -> 479026.53
A35: 1-3-5-2-02 | B35: =+VLOOKUP(A35,Ingresos!$A$2:$B$200,2,FALSE) -> Aporte Solidario entidades REX | C35: 405395598012 | D35: =+VLOOKUP(A35,Ingresos!$A$1:$F$90,3,FALSE) -> 0 | E35: =+VLOOKUP(A35,Ingresos!$A$1:$F$200,4,FALSE) -> 405395598012 | F35: 3.0738702e+11 | G35: =+VLOOKUP(A35,Ingresos!$A$1:$E$200,5,FALSE) -> 3.3585624e+10 | H35: =+G35+F35 -> 3.4097264e+11 | I35: =IFERROR(H35/E35*100,0) -> 84.10862 | J35: =+H35/1000000 -> 340972.64
A36: 1-3-5-3 | B36: =+VLOOKUP(A36,Ingresos!$A$2:$B$200,2,FALSE) -> Aportes Cajas de Compensación Familiar | C36: 499207099674 | D36: =+SUM(D37:D40) -> 0 | E36: =+SUM(E37:E40) -> 499207099674 | F36: 4.469249e+11 | G36: =+SUM(G37:G40) -> 4.1428447e+10 | H36: =+G36+F36 -> 4.8835335e+11 | I36: =IFERROR(H36/E36*100,0) -> 97.825802 | J36: =+H36/1000000 -> 488353.35
A37: 1-3-5-3-01 | B37: =+VLOOKUP(A37,Ingresos!$A$2:$B$200,2,FALSE) -> Aportes CCF Artículo 217 Ley 100 de 1993 CSF | C37: 466578060617 | D37: =+VLOOKUP(A37,Ingresos!$A$1:$F$90,3,FALSE) -> 0 | E37: =+VLOOKUP(A37,Ingresos!$A$1:$F$200,4,FALSE) -> 466578060617 | F37: 4.2049742e+11 | G37: =+VLOOKUP(A37,Ingresos!$A$1:$E$200,5,FALSE) -> 4.0404763e+10 | H37: =+G37+F37 -> 4.6090218e+11 | I37: =IFERROR(H37/E37*100,0) -> 98.783509 | J37: =+H37/1000000 -> 460902.18
A38: 1-3-5-3-02 | B38: =+VLOOKUP(A38,Ingresos!$A$2:$B$200,2,FALSE) -> Aportes CCF Artículo 217 Ley 100 de 1993 SSF | C38: 28877831435 | D38: =+VLOOKUP(A38,Ingresos!$A$1:$F$90,3,FALSE) -> 0 | E38: =+VLOOKUP(A38,Ingresos!$A$1:$F$200,4,FALSE) -> 28877831435 | F38: 2.3598027e+10 | G38: =+VLOOKUP(A38,Ingresos!$A$1:$E$200,5,FALSE) -> 1.0236848e+09 | H38: =+G38+F38 -> 2.4621711e+10 | I38: =IFERROR(H38/E38*100,0) -> 85.261636 | J38: =+H38/1000000 -> 24621.711
A39: 1-3-5-3-03 | B39: =+VLOOKUP(A39,Ingresos!$A$2:$B$200,2,FALSE) -> Aportes CCF Balance | C39: 3751207622 | D39: =+VLOOKUP(A39,Ingresos!$A$1:$F$90,3,FALSE) -> 0 | E39: =+VLOOKUP(A39,Ingresos!$A$1:$F$200,4,FALSE) -> 3751207622 | F39: 2000102769 | G39: =+VLOOKUP(A39,Ingresos!$A$1:$E$200,5,FALSE) -> 0 | H39: =+G39+F39 -> 2000102769 | I39: =IFERROR(H39/E39*100,0) -> 53.318903 | J39: =+H39/1000000 -> 2000.1028
A40: 1-3-5-3-04 | B40: =+VLOOKUP(A40,Ingresos!$A$2:$B$200,2,FALSE) -> Otros Aportes CCF | C40: 0 | D40: =+VLOOKUP(A40,Ingresos!$A$1:$F$90,3,FALSE) -> 0 | E40: =+VLOOKUP(A40,Ingresos!$A$1:$F$200,4,FALSE) -> 0 | F40: 8.2935047e+08 | G40: =+VLOOKUP(A40,Ingresos!$A$1:$E$200,5,FALSE) -> 0 | H40: =+G40+F40 -> 8.2935047e+08 | I40: =IFERROR(H40/E40*100,0) -> 0 | J40: =+H40/1000000 -> 829.35047
A41: 1-3-5-5 | B41: =+VLOOKUP(A41,Ingresos!$A$2:$B$200,2,FALSE) -> Reintegros / Recuperaciones | C41: 0 | D41: =+SUM(D42:D50) -> 0 | E41: =+SUM(E42:E50) -> 0 | F41: 9.9901217e+11 | G41: =+SUM(G42:G50) -> 7.6217125e+10 | H41: =+G41+F41 -> 1.0752293e+12 | I41: =IFERROR(H41/E41*100,0) -> 0 | J41: =+H41/1000000 -> 1075229.3
A42: 1-3-5-5-01 | B42: =+VLOOKUP(A42,Ingresos!$A$2:$B$200,2,FALSE) -> UPC Régimen Contributivo Vigencias anteriores | C42: 0 | D42: =+VLOOKUP(A42,Ingresos!$A$1:$F$90,3,FALSE) -> 0 | E42: =+VLOOKUP(A42,Ingresos!$A$1:$F$200,4,FALSE) -> 0 | F42: 5.470649e+10 | G42: =+VLOOKUP(A42,Ingresos!$A$1:$E$200,5,FALSE) -> 1.4231722e+09 | H42: =+G42+F42 -> 5.6129663e+10 | I42: =IFERROR(H42/E42*100,0) -> 0 | J42: =+H42/1000000 -> 56129.663
A43: 1-3-5-5-02 | B43: =+VLOOKUP(A43,Ingresos!$A$2:$B$200,2,FALSE) -> P&P Vigencias anteriores | C43: 0 | D43: =+VLOOKUP(A43,Ingresos!$A$1:$F$90,3,FALSE) -> 0 | E43: =+VLOOKUP(A43,Ingresos!$A$1:$F$200,4,FALSE) -> 0 | F43: 0 | G43: =+VLOOKUP(A43,Ingresos!$A$1:$E$200,5,FALSE) -> 0 | H43: =+G43+F43 -> 0 | I43: =IFERROR(H43/E43*100,0) -> 0 | J43: =+H43/1000000 -> 0
...

Sheet Ingresos
A1: RUBRO | B1: inicial | C1: MODIFICACIONES | D1: AFORO DEFINITIVO | E1: INGRESO MES | F1: % | G1: según ejec. Sistema acum | H1: formulado
A2: 0-0-0-0 | B2: Disponibilidad inicial | C2: 0 | D2: 910932869290 | E2: 0 | F2: 100 | G2: 910932869290 | H2: =+VLOOKUP(A2,'CUADRO 1-EJECUCION DE INGRESOS'!$A$10:$H$101,8,FALSE) -> 910932869290 | I2: =+H2-G2 -> 0
A3: 1-2-1-1 | B3: Aportes de la Nación para el Aseguramiento en Salud | C3: 0 | D3: 15039782346000 | E3: 1160204084389 | F3: 92 | G3: 1.3836378e+13 | H3: =+VLOOKUP(A3,'CUADRO 1-EJECUCION DE INGRESOS'!$A$10:$H$101,8,FALSE) -> 1.3836378e+13 | I3: =+H3-G3 -> 0.08203125
A4: 1-2-1-1-01 | B4: Aportes de la Nación para el Aseguramiento en Salud Cierre | C4: 0 | D4: 9743321670830 | E4: 6.2167882e+11 | F4: 93.18 | G4: 9.0784429e+12 | H4: =+VLOOKUP(A4,'CUADRO 1-EJECUCION DE INGRESOS'!$A$10:$H$101,8,FALSE) -> 9.0784429e+12 | I4: =+H4-G4 -> 0
A5: 1-2-1-1-02 | B5: Imporenta | C5: 0 | D5: 5296460675170 | E5: 5.3852527e+11 | F5: 89.83 | G5: 4.7579354e+12 | H5: =+VLOOKUP(A5,'CUADRO 1-EJECUCION DE INGRESOS'!$A$10:$H$101,8,FALSE) -> 4.7579354e+12 | I5: =+H5-G5 -> 0
A6: 1-2-1-2 | B6: Compensación Regalías para el Régimen Subsidiado | C6: 0 | D6: 226673765000 | E6: 0 | F6: 100 | G6: 226673765000 | H6: =+VLOOKUP(A6,'CUADRO 1-EJECUCION DE INGRESOS'!$A$10:$H$101,8,FALSE) -> 226673765000 | I6: =+H6-G6 -> 0
A7: 1-2-1-3 | B7: Impuesto sobre la renta para la equidad CREE | C7: 0 | D7: 0 | E7: 0 | F7: 0 | G7: 0 | H7: =+VLOOKUP(A7,'CUADRO 1-EJECUCION DE INGRESOS'!$A$10:$H$101,8,FALSE) -> 0 | I7: =+H7-G7 -> 0
A8: 1-2-1-4 | B8: SGP FONSAET | C8: 0 | D8: 95551523562 | E8: 0 | F8: 0 | G8: 0 | H8: =+VLOOKUP(A8,'CUADRO 1-EJECUCION DE INGRESOS'!$A$10:$H$101,8,FALSE) -> 0 | I8: =+H8-G8 -> 0
A9: 1-2-1-5 | B9: PRIMA FONSAT Y CONTRIBUCION SOAT | C9: 0 | D9: 1640527441000 | E9: 1.8790881e+11 | F9: 102.99 | G9: 1.6895536e+12 | H9: =+VLOOKUP(A9,'CUADRO 1-EJECUCION DE INGRESOS'!$A$10:$H$101,8,FALSE) -> 1.6895536e+12 | I9: =+H9-G9 -> 0
A10: 1-2-1-5-01 | B10: % Prima (FONSAT) Decreto Ley 1335 de 2009 | C10: 0 | D10: 363281118360 | E10: 6.7235893e+10 | F10: 109.3 | G10: 3.9706551e+11 | H10: =+VLOOKUP(A10,'CUADRO 1-EJECUCION DE INGRESOS'!$A$10:$H$101,8,FALSE) -> 3.9706551e+11 | I10: =+H10-G10 -> 0
A11: 1-2-1-5-02 | B11: Contribución Seguro Obligatorio de Accidentes de Tránsito - SOAT- Decreto Ley 1335 de 2009 | C11: 0 | D11: 1277246322640 | E11: 120672915300 | F11: 101.19 | G11: 1.2924881e+12 | H11: =+VLOOKUP(A11,'CUADRO 1-EJECUCION DE INGRESOS'!$A$10:$H$101,8,FALSE) -> 1.2924881e+12 | I11: =+H11-G11 -> 0
A12: 1-2-1-7 | B12: Impuesto social a las municiones y explosivos | C12: 0 | D12: 6410791000 | E12: 9997809749 | F12: 1689.6 | G12: 108316733990 | H12: =+VLOOKUP(A12,'CUADRO 1-EJECUCION DE INGRESOS'!$A$10:$H$101,8,FALSE) -> 108316733990 | I12: =+H12-G12 -> 0
A13: 1-2-1-8 | B13: Impuesto social a las armas | C13: 0 | D13: 8851770619 | E13: 1171605398 | F13: 101.55 | G13: 8989110740 | H13: =+VLOOKUP(A13,'CUADRO 1-EJECUCION DE INGRESOS'!$A$10:$H$101,8,FALSE) -> 8989110740 | I13: =+H13-G13 -> 0
... A84: 2-9-0-0-02 | B84: Otros Recursos de Capital no contemplados en los anteriores | C84: 0 | D84: 0 | E84: 0 | F84: 0 | G84: 0 | H84: =+VLOOKUP(A84,'CUADRO 1-EJECUCION DE INGRESOS'!$A$10:$H$101,8,FALSE) -> 0 | I84: =+H84-G84 -> 0
D85: 5.0735617e+12 | E85: 0 | F85: 94.27

Sheet CUADRO 2-EJECUCION DE GASTOS
M1: =+TODAY() -> 43818 | N1: =+NOW() -> 43818.489
A3: ADMINISTRADORA DE LOS RECURSOS DEL SISTEMA GENERAL DE SEGURIDAD SOCIAL EN SALUD
A4: UNIDAD DE RECURSOS ADMINISTRADOS - URA
A5: CODIGO DE LA EMPRESA 12902 - ADMINISTRACION DE RECURSOS DEL SGSSS
A6: PRESUPUESTO DE GASTOS NOVIEMBRE DE 2019
A7: CUADRO No. 2
A10: CÓDIGO RUBRO | B10: CONCEPTO DEL RUBRO | C10: APROPIACIÓN DEFINITIVA | D10: EJECUCION PRESUPUESTAL ACUMULADA DESDE 01/01/2019 HASTA 31/10/2019 | G10: EJECUCION PRESUPUESTAL DESDE 01/11/2019 HASTA 30/11/2019 | J10: EJECUCION PRESUPUESTAL ACUMULADA DESDE 01/01/2019 HASTA 30/11/2019 | M10: %
D11: T. CDP | E11: T. RP | F11: T. PAGOS-OG | G11: CDP | H11: RP | I11: PAGOS-OG | J11: T. CDP | K11: T. RP | L11: T. PAGOS-OG | M11: RP | N11: OG
B12: URA
A13: A-3-0-0-0 | B13: TRANSFERENCIAS | C13: =+C14+C19+C25 -> 5.3093572e+13 | D13: 4.6380563e+13 | E13: 4.2615021e+13 | F13: 4.2615021e+13 | G13: =+G14+G19+G25 -> 4.8857093e+12 | H13: =+H14+H19+H25 -> 4.1824172e+12 | I13: =+I14+I19+I25 -> 4.1624172e+12 | J13: =+G13+D13 -> 5.1266272e+13 | K13: =+H13+E13 -> 4.6797438e+13 | L13: =+I13+F13 -> 4.6777438e+13 | M13: =+IFERROR(K13*100/C13,0) -> 88.141438 | N13: =+IFERROR(L13*100/C13,0) -> 88.103769 | O13: =+L13/1000000 -> 46777438
A14: A-3-2-0-0 | B14: TRANSFERENCIAS AL SECTOR PUBLICO | C14: =+C15+C17 -> 231725030430 | D14: 228185519661 | E14: 1.0309248e+11 | F14: 1.0309248e+11 | G14: =+G15+G17 -> 0 | H14: =+H15+H17 -> 1.0906417e+10 | I14: =+I15+I17 -> 1.0906417e+10 | J14: =+G14+D14 -> 228185519661 | K14: =+H14+E14 -> 1.139989e+11 | L14: =+I14+F14 -> 1.139989e+11 | M14: =+IFERROR(K14*100/C14,0) -> 49.195764 | N14: =+IFERROR(L14*100/C14,0) -> 49.195764 | O14: =+L14/1000000 -> 113998.9
A15: A-3-2-1-0 | B15: =+VLOOKUP(A15,gasto!$A$4:$B$100,2,FALSE) -> Transferencias Entidades de Administración Pública Central | C15: =+C16 -> 86345030430 | D15: 82805519661 | E15: 6.8840742e+10 | F15: 6.8840742e+10 | G15: =+G16 -> 0 | H15: =+H16 -> 6.8799777e+09 | I15: =+I16 -> 6.8799777e+09 | J15: =+J16 -> 82805519661 | K15: =+K16 -> 7.5720719e+10 | L15: =+L16 -> 7.5720719e+10 | M15: =+IFERROR(K15*100/C15,0) -> 87.695515 | N15: =+IFERROR(L15*100/C15,0) -> 87.695515 | O15: =+L15/1000000 -> 75720.719
A16: A-3-2-1-01 | B16: =+VLOOKUP(A16,gasto!$A$4:$B$100,2,FALSE) -> Contribución IVC Superintendencia Nacional de Salud | C16: =+VLOOKUP(A16,gasto!$A$4:$F$80,3,FALSE) -> 86345030430 | D16: 82805519661 | E16: 6.8840742e+10 | F16: 6.8840742e+10 | G16: =+VLOOKUP(A16,gasto!$A$4:$F$80,4,FALSE) -> 0 | H16: =+VLOOKUP(A16,gasto!$A$4:$F$80,5,FALSE) -> 6.8799777e+09 | I16: =+VLOOKUP(A16,gasto!$A$4:$F$80,6,FALSE) -> 6.8799777e+09 | J16: =+G16+D16 -> 82805519661 | K16: =+H16+E16 -> 7.5720719e+10 | L16: =+I16+F16 -> 7.5720719e+10 | M16: =+IFERROR(K16*100/C16,0) -> 87.695515 | N16: =+IFERROR(L16*100/C16,0) -> 87.695515 | O16: =+L16/1000000 -> 75720.719
A17: A-3-2-2-0 | B17: =+VLOOKUP(A17,gasto!$A$4:$B$100,2,FALSE) -> Empresas Públicas Nacionales no financieras -ADRES | C17: =+C18 -> 145380000000 | D17: 145380000000 | E17: 3.425174e+10 | F17: 3.425174e+10 | G17: =+G18 -> 0 | H17: =+H18 -> 4.0264397e+09 | I17: =+I18 -> 4.0264397e+09 | J17: =+J18 -> 145380000000 | K17: =+K18 -> 3.827818e+10 | L17: =+L18 -> 3.827818e+10 | M17: =+IFERROR(K17*100/C17,0) -> 26.329743 | N17: =+IFERROR(L17*100/C17,0) -> 26.329743 | O17: =+L17/1000000 -> 38278.18
A18: A-3-2-2-0-01 | B18: =+VLOOKUP(A18,gasto!$A$4:$B$100,2,FALSE) -> Aportes hasta del 0,5% recursos CSF para el desarrollo objeto ADRES | C18: =+VLOOKUP(A18,gasto!$A$4:$F$80,3,FALSE) -> 145380000000 | D18: 145380000000 | E18: 3.425174e+10 | F18: 3.425174e+10 | G18: =+VLOOKUP(A18,gasto!$A$4:$F$80,4,FALSE) -> 0 | H18: =+VLOOKUP(A18,gasto!$A$4:$F$80,5,FALSE) -> 4.0264397e+09 | I18: =+VLOOKUP(A18,gasto!$A$4:$F$80,6,FALSE) -> 4.0264397e+09 | J18: =+G18+D18 -> 145380000000 | K18: =+H18+E18 -> 3.827818e+10 | L18: =+I18+F18 -> 3.827818e+10 | M18: =+IFERROR(K18*100/C18,0) -> 26.329743 | N18: =+IFERROR(L18*100/C18,0) -> 26.329743 | O18: =+L18/1000000 -> 38278.18
A19: A-3-6-0-0 | B19: OTRAS TRANSFERENCIAS | C19: =+C20+C23 -> 154000000000 | D19: 2.1803278e+09 | E19: 2.1803278e+09 | F19: 2.1803278e+09 | G19: =+G20+G23 -> 32260652 | H19: =+H20+H23 -> 1298784.6 | I19: =+I20+I23 -> 1298784.6 | J19: =+G19+D19 -> 2.2125885e+09 | K19: =+H19+E19 -> 2.1816266e+09 | L19: =+I19+F19 -> 2.1816266e+09 | M19: =+IFERROR(K19*100/C19,0) -> 1.4166407 | N19: =+IFERROR(L19*100/C19,0) -> 1.4166407 | O19: =+L19/1000000 -> 2181.6266
A20: A-3-6-1-0 | B20: =+VLOOKUP(A20,gasto!$A$4:$B$100,2,FALSE) -> Sentencias y Conciliaciones URA | C20: =+SUM(C21:C22) -> 20000000000 | D20: 2.1803278e+09 | E20: 2.1803278e+09 | F20: 2.1803278e+09 | G20: =+SUM(G21:G22) -> 32260652 | H20: =+SUM(H21:H22) -> 1298784.6 | I20: =+SUM(I21:I22) -> 1298784.6 | J20: =+SUM(J21:J22) -> 2.2125885e+09 | K20: =+SUM(K21:K22) -> 2.1816266e+09 | L20: =+SUM(L21:L22) -> 2.1816266e+09 | M20: =+IFERROR(K20*100/C20,0) -> 10.908133 | N20: =+IFERROR(L20*100/C20,0) -> 10.908133 | O20: =+L20/1000000 -> 2181.6266
A21: A-3-6-1-1 | B21: =+VLOOKUP(A21,gasto!$A$4:$B$100,2,FALSE) -> Sentencias URA | C21: =+VLOOKUP(A21,gasto!$A$4:$F$80,3,FALSE) -> 20000000000 | D21: 2.1803278e+09 | E21: 2.1803278e+09 | F21: 2.1803278e+09 | G21: =+VLOOKUP(A21,gasto!$A$4:$F$80,4,FALSE) -> 32260652 | H21: =+VLOOKUP(A21,gasto!$A$4:$F$80,5,FALSE) -> 1298784.6 | I21: =+VLOOKUP(A21,gasto!$A$4:$F$80,6,FALSE) -> 1298784.6 | J21: =+G21+D21 -> 2.2125885e+09 | K21: =+H21+E21 -> 2.1816266e+09 | L21: =+I21+F21 -> 2.1816266e+09 | M21: =+IFERROR(K21*100/C21,0) -> 10.908133 | N21: =+IFERROR(L21*100/C21,0) -> 10.908133 | O21: =+L21/1000000 -> 2181.6266
A22: A-3-6-1-2 | B22: =+VLOOKUP(A22,gasto!$A$4:$B$100,2,FALSE) -> Conciliaciones URA | C22: =+VLOOKUP(A22,gasto!$A$4:$F$80,3,FALSE) -> 0 | D22: 0 | E22: 0 | F22: 0 | G22: =+VLOOKUP(A22,gasto!$A$4:$F$80,4,FALSE) -> 0 | H22: =+VLOOKUP(A22,gasto!$A$4:$F$80,5,FALSE) -> 0 | I22: =+VLOOKUP(A22,gasto!$A$4:$F$80,6,FALSE) -> 0 | J22: =+G22+D22 -> 0 | K22: =+H22+E22 -> 0 | L22: =+I22+F22 -> 0 | M22: =+IFERROR(K22*100/C22,0) -> 0 | N22: =+IFERROR(L22*100/C22,0) -> 0 | O22: =+L22/1000000 -> 0
A23: A-3-6-3-0 | B23: =+VLOOKUP(A23,gasto!$A$4:$B$100,2,FALSE) -> Destinatarios de otras transferencias Corrientes - Compensación Chance | C23: =+C24 -> 134000000000 | D23: 0 | E23: 0 | F23: 0 | G23: =+G24 -> 0 | H23: =+H24 -> 0 | I23: =+I24 -> 0 | J23: =+J24 -> 0 | K23: =+K24 -> 0 | L23: =+L24 -> 0 | M23: =+IFERROR(K23*100/C23,0) -> 0 | N23: =+IFERROR(L23*100/C23,0) -> 0 | O23: =+L23/1000000 -> 0
A24: A-3-6-3-0-01 | B24: =+VLOOKUP(A24,gasto!$A$4:$B$100,2,FALSE) -> Otras transferencias - Compensación del Chance Decreto 2550/12 | C24: =+VLOOKUP(A24,gasto!$A$4:$F$80,3,FALSE) -> 134000000000 | D24: 0 | E24: 0 | F24: 0 | G24: =+VLOOKUP(A24,gasto!$A$4:$F$80,4,FALSE) -> 0 | H24: =+VLOOKUP(A24,gasto!$A$4:$F$80,5,FALSE) -> 0 | I24: =+VLOOKUP(A24,gasto!$A$4:$F$80,6,FALSE) -> 0 | J24: =+G24+D24 -> 0 | K24: =+H24+E24 -> 0 | L24: =+I24+F24 -> 0 | M24: =+IFERROR(K24*100/C24,0) -> 0 | N24: =+IFERROR(L24*100/C24,0) -> 0 | O24: =+L24/1000000 -> 0
A25: A-3-9-0-0 | B25: ADMINISTRACIÓN DE RECURSOS DEL SGSSS | C25: =+C26+C31+C34+C37+C38+C39+C43+C48+C55+C59+C69+C80+C82+C84+C88+C93 -> 5.2707847e+13 | D25: 4.6050197e+13 | E25: 4.2509583e+13 | F25: 4.2509583e+13 | G25: =+G26+G31+G34+G37+G38+G39+G43+G48+G55+G59+G69+G80+G82+G84+G88+G93 -> 4.885677e+12 | H25: =+H26+H31+H34+H37+H38+H39+H43+H48+H55+H59+H69+H80+H82+H84+H88+H93 -> 4.1715095e+12 | I25: =+I26+I31+I34+I37+I38+I39+I43+I48+I55+I59+I69+I80+I82+I84+I88+I93 -> 4.1515095e+12 | J25: =+J26+J31+J34+J37+J38+J39+J43+J48+J55+J59+J69+J80+J82+J84+J88 -> 5.0935874e+13 | K25: =+K26+K31+K34+K37+K38+K39+K43+K48+K55+K59+K69+K80+K82+K84+K88 -> 4.6681092e+13 | L25: =+L26+L31+L34+L37+L38+L39+L43+L48+L55+L59+L69+L80+L82+L84+L88 -> 4.6661092e+13 | M25: =+IFERROR(K25*100/C25,0) -> 88.565736 | N25: =+IFERROR(L25*100/C25,0) -> 88.527791 | O25: =+L25/1000000 -> 46661092
A26: A-3-9-1-0 | B26: =+VLOOKUP(A26,gasto!$A$4:$B$100,2,FALSE) -> UPC Régimen Contributivo | C26: =+SUM(C27:C30) -> 22863934384378 | D26: 1.9588681e+13 | E26: 18634853148471 | F26: 18634853148471 | G26: =+SUM(G27:G30) -> 3.1690367e+12 | H26: =+SUM(H27:H30) -> 1829621715847 | I26: =+SUM(I27:I30) -> 1829621715847 | J26: =+SUM(J27:J30) -> 22757717488720 | K26: =+SUM(K27:K30) -> 20464474864318 | L26: =+SUM(L27:L30) -> 20464474864318 | M26: =+IFERROR(K26*100/C26,0) -> 89.505483 | N26: =+IFERROR(L26*100/C26,0) -> 89.505483 | O26: =+L26/1000000 -> 20464475
A27: A-3-9-1-0-01 | B27: =+VLOOKUP(A27,gasto!$A$4:$B$100,2,FALSE) -> UPC Régimen Contributivo SSF | C27: =+VLOOKUP(A27,gasto!$A$4:$F$80,3,FALSE) -> 12575109660289 | D27: 1.0578906e+13 | E27: 10308892111405 | F27: 10308892111405 | G27: =+VLOOKUP(A27,gasto!$A$4:$F$80,4,FALSE) -> 1.8899866e+12 | H27: =+VLOOKUP(A27,gasto!$A$4:$F$80,5,FALSE) -> 1054086594082 | I27: =+VLOOKUP(A27,gasto!$A$4:$F$80,6,FALSE) -> 1054086594082 | J27: =+G27+D27 -> 12468892764631 | K27: =+H27+E27 -> 11362978705487 | L27: =+I27+F27 -> 11362978705487 | M27: =+IFERROR(K27*100/C27,0) -> 90.360872 | N27: =+IFERROR(L27*100/C27,0) -> 90.360872 | O27: =+L27/1000000 -> 11362979
A28: A-3-9-1-0-02 | B28: =+VLOOKUP(A28,gasto!$A$4:$B$100,2,FALSE) -> UPC Régimen Contributivo CSF | C28: =+VLOOKUP(A28,gasto!$A$4:$F$80,3,FALSE) -> 10287649289644 | D28: 9008599217429 | E28: 8324785602621 | F28: 8324785602621 | G28: =+VLOOKUP(A28,gasto!$A$4:$F$80,4,FALSE) -> 1279050072215 | H28: =+VLOOKUP(A28,gasto!$A$4:$F$80,5,FALSE) -> 775535121765 | I28: =+VLOOKUP(A28,gasto!$A$4:$F$80,6,FALSE) -> 775535121765 | J28: =+G28+D28 -> 10287649289644 | K28: =+H28+E28 -> 9100320724386 | L28: =+I28+F28 -> 9100320724386 | M28: =+IFERROR(K28*100/C28,0) -> 88.458699 | N28: =+IFERROR(L28*100/C28,0) -> 88.458699 | O28: =+L28/1000000 -> 9100320.7
A29: A-3-9-1-0-03 | B29: =+VLOOKUP(A29,gasto!$A$4:$B$100,2,FALSE) -> Devolución aportes y cotizaciones no conciliadas vigencia anterior | C29: =+VLOOKUP(A29,gasto!$A$4:$F$80,3,FALSE) -> 1175434445 | D29: 1175434445 | E29: 1175434445 | F29: 1175434445 | G29: =+VLOOKUP(A29,gasto!$A$4:$F$80,4,FALSE) -> 0 | H29: =+VLOOKUP(A29,gasto!$A$4:$F$80,5,FALSE) -> 0 | I29: =+VLOOKUP(A29,gasto!$A$4:$F$80,6,FALSE) -> 0 | J29: =+G29+D29 -> 1175434445 | K29: =+H29+E29 -> 1175434445 | L29: =+I29+F29 -> 1175434445 | M29: =+IFERROR(K29*100/C29,0) -> 100 | N29: =+IFERROR(L29*100/C29,0) -> 100 | O29: =+L29/1000000 -> 1175.4344
A30: A-3-9-1-0-04 | B30: =+VLOOKUP(A30,gasto!$A$4:$B$100,2,FALSE) -> Rendimientos Financieros de los Saldos no Compensados de los Aportes Patronales según Art. 12 Decreto 1636 de 2016 | C30: =+VLOOKUP(A30,gasto!$A$4:$F$80,3,FALSE) -> 0 | D30: 0 | E30: 0 | F30: 0 | G30: =+VLOOKUP(A30,gasto!$A$4:$F$80,4,FALSE) -> 0 | H30: =+VLOOKUP(A30,gasto!$A$4:$F$80,5,FALSE) -> 0 | I30: =+VLOOKUP(A30,gasto!$A$4:$F$80,6,FALSE) -> 0 | J30: =+G30+D30 -> 0 | K30: =+H30+E30 -> 0 | L30: =+I30+F30 -> 0 | M30: =+IFERROR(K30*100/C30,0) -> 0 | N30: =+IFERROR(L30*100/C30,0) -> 0 | O30: =+L30/1000000 -> 0
A31: A-3-9-2-0 | B31: =+VLOOKUP(A31,gasto!$A$4:$B$100,2,FALSE) -> Per capita Programas de Promoción y Prevención R.C | C31: =+SUM(C32:C33) -> 547768600953 | D31: 5.2516483e+11 | E31: 423253138281 | F31: 423253138281 | G31: =+SUM(G32:G33) -> 2.2598926e+10 | H31: =+SUM(H32:H33) -> 41146647064 | I31: =+SUM(I32:I33) -> 41146647064 | J31: =+SUM(J32:J33) -> 547763758957 | K31: =+SUM(K32:K33) -> 464399785345 | L31: =+SUM(L32:L33) -> 464399785345 | M31: =+IFERROR(K31*100/C31,0) -> 84.780286 | N31: =+IFERROR(L31*100/C31,0) -> 84.780286 | O31: =+L31/1000000 -> 464399.79
A32: A-3-9-2-0-01 | B32: =+VLOOKUP(A32,gasto!$A$4:$B$100,2,FALSE) -> Per capita Programas de Promoción y Prevención R.C SSF | C32: =+VLOOKUP(A32,gasto!$A$4:$F$80,3,FALSE) -> 411516042986 | D32: 411426168868 | E32: 338609191257 | F32: 338609191257 | G32: =+VLOOKUP(A32,gasto!$A$4:$F$80,4,FALSE) -> 85032122 | H32: =+VLOOKUP(A32,gasto!$A$4:$F$80,5,FALSE) -> 34152449700 | I32: =+VLOOKUP(A32,gasto!$A$4:$F$80,6,FALSE) -> 34152449700 | J32: =+G32+D32 -> 411511200990 | K32: =+H32+E32 -> 372761640957 | L32: =+I32+F32 -> 372761640957 | M32: =+IFERROR(K32*100/C32,0) -> 90.582529 | N32: =+IFERROR(L32*100/C32,0) -> 90.582529 | O32: =+L32/1000000 -> 372761.64
A33: A-3-9-2-0-02 | B33: =+VLOOKUP(A33,gasto!$A$4:$B$100,2,FALSE) -> Per capita Programas de Promoción y Prevención R.C CSF | C33: =+VLOOKUP(A33,gasto!$A$4:$F$80,3,FALSE) -> 136252557967 | D33: 1.1373866e+11 | E33: 84643947024 | F33: 84643947024 | G33: =+VLOOKUP(A33,gasto!$A$4:$F$80,4,FALSE) -> 2.2513894e+10 | H33: =+VLOOKUP(A33,gasto!$A$4:$F$80,5,FALSE) -> 6994197364 | I33: =+VLOOKUP(A33,gasto!$A$4:$F$80,6,FALSE) -> 6994197364 | J33: =+G33+D33 -> 136252557967 | K33: =+H33+E33 -> 91638144388 | L33: =+I33+F33 -> 91638144388 | M33: =+IFERROR(K33*100/C33,0) -> 67.256091 | N33: =+IFERROR(L33*100/C33,0) -> 67.256091 | O33: =+L33/1000000 -> 91638.144
A34: A-3-9-3-0 | B34: =+VLOOKUP(A34,gasto!$A$4:$B$100,2,FALSE) -> Incapacidades | C34: =+SUM(C35:C36) -> 845461941941 | D34: 7.190495e+11 | E34: 681924346779 | F34: 681924346779 | G34: =+SUM(G35:G36) -> 1.2340259e+11 | H34: =+SUM(H35:H36) -> 67250636446 | I34: =+SUM(I35:I36) -> 67250636446 | J34: =+SUM(J35:J36) -> 842452089891 | K34: =+SUM(K35:K36) -> 749174983225 | L34: =+SUM(L35:L36) -> 749174983225 | M34: =+IFERROR(K34*100/C34,0) -> 88.61132 | N34: =+IFERROR(L34*100/C34,0) -> 88.61132 | O34: =+L34/1000000 -> 749174.98
A35: A-3-9-3-0-01 | B35: =+VLOOKUP(A35,gasto!$A$4:$B$100,2,FALSE) -> Incapacidades SSF | C35: =+VLOOKUP(A35,gasto!$A$4:$F$80,3,FALSE) -> 660253806467 | D35: 5.6233398e+11 | E35: 540531744658 | F35: 540531744658 | G35: =+VLOOKUP(A35,gasto!$A$4:$F$80,4,FALSE) -> 9.4909976e+10 | H35: =+VLOOKUP(A35,gasto!$A$4:$F$80,5,FALSE) -> 54977994697 | I35: =+VLOOKUP(A35,gasto!$A$4:$F$80,6,FALSE) -> 54977994697 | J35: =+G35+D35 -> 657243954417 | K35: =+H35+E35 -> 595509739355 | L35: =+I35+F35 -> 595509739355 | M35: =+IFERROR(K35*100/C35,0) -> 90.194064 | N35: =+IFERROR(L35*100/C35,0) -> 90.194064 | O35: =+L35/1000000 -> 595509.74
A36: A-3-9-3-0-02 | B36: =+VLOOKUP(A36,gasto!$A$4:$B$100,2,FALSE) -> Incapacidades CSF | C36: =+VLOOKUP(A36,gasto!$A$4:$F$80,3,FALSE) -> 185208135474 | D36: 156715520546 | E36: 141392602121 | F36: 141392602121 | G36: =+VLOOKUP(A36,gasto!$A$4:$F$80,4,FALSE) -> 28492614928 | H36: =+VLOOKUP(A36,gasto!$A$4:$F$80,5,FALSE) -> 12272641749 | I36: =+VLOOKUP(A36,gasto!$A$4:$F$80,6,FALSE) -> 12272641749 | J36: =+G36+D36 -> 185208135474 | K36: =+H36+E36 -> 153665243870 | L36: =+I36+F36 -> 153665243870 | M36: =+IFERROR(K36*100/C36,0) -> 82.968949 | N36: =+IFERROR(L36*100/C36,0) -> 82.968949 | O36: =+L36/1000000 -> 153665.24
A37: A-3-9-4-0 | B37: =+VLOOKUP(A37,gasto!$A$4:$B$100,2,FALSE) -> Licencias de Maternidad y Paternidad | C37: =+VLOOKUP(A37,gasto!$A$4:$F$80,3,FALSE) -> 838554045453 | D37: 838554045453 | E37: 662280886992 | F37: 662280886992 | G37: =+VLOOKUP(A37,gasto!$A$4:$F$80,4,FALSE) -> 0 | H37: =+VLOOKUP(A37,gasto!$A$4:$F$80,5,FALSE) -> 64400742809 | I37: =+VLOOKUP(A37,gasto!$A$4:$F$80,6,FALSE) -> 64400742809 | J37: =+G37+D37 -> 838554045453 | K37: =+H37+E37 -> 726681629801 | L37: =+I37+F37 -> 726681629801 | M37: =+IFERROR(K37*100/C37,0) -> 86.65889 | N37: =+IFERROR(L37*100/C37,0) -> 86.65889 | O37: =+L37/1000000 -> 726681.63
A38: A-3-9-5-0 | B38: =+VLOOKUP(A38,gasto!$A$4:$B$100,2,FALSE) -> Prestaciones Económicas Regímenes Especial y de Excepción | C38: =+VLOOKUP(A38,gasto!$A$4:$F$80,3,FALSE) -> 5142227236 | D38: 4842227236 | E38: 3518636432 | F38: 3518636432 | G38: =+VLOOKUP(A38,gasto!$A$4:$F$80,4,FALSE) -> 0 | H38: =+VLOOKUP(A38,gasto!$A$4:$F$80,5,FALSE) -> 565599472 | I38: =+VLOOKUP(A38,gasto!$A$4:$F$80,6,FALSE) -> 565599472 | J38: =+G38+D38 -> 4842227236 | K38: =+H38+E38 -> 4084235904 | L38: =+I38+F38 -> 4084235904 | M38: =+IFERROR(K38*100/C38,0) -> 79.425426 | N38: =+IFERROR(L38*100/C38,0) -> 79.425426 | O38: =+L38/1000000 -> 4084.2359
A39: A-3-9-6-0 | B39: =+VLOOKUP(A39,gasto!$A$4:$B$100,2,FALSE) -> UPC Régimen Subsidiado | C39: =+SUM(C40:C42) -> 2.2009869e+13 | D39: 2.0320446e+13 | E39: 1.8283986e+13 | F39: 1.8283986e+13 | G39: =+SUM(G40:G42) -> 1.2658121e+12 | H39: =+SUM(H40:H42) -> 1.830925e+12 | I39: =+SUM(I40:I42) -> 1.830925e+12 | J39: =+SUM(J40:J42) -> 21586257607421 | K39: =+SUM(K40:K42) -> 2.0114911e+13 | L39: =+SUM(L40:L42) -> 2.0114911e+13 | M39: =+IFERROR(K39*100/C39,0) -> 91.390417 | N39: =+IFERROR(L39*100/C39,0) -> 91.390417 | O39: =+L39/1000000 -> 20114911
A40: A-3-9-6-0-01 | B40: =+VLOOKUP(A40,gasto!$A$4:$B$100,2,FALSE) -> UPC´S R.S. Cajas de Compensación Familiar SSF | C40: =+VLOOKUP(A40,gasto!$A$4:$F$80,3,FALSE) -> 28877831435 | D40: 28877831435 | E40: 2.3598027e+10 | F40: 2.3598027e+10 | G40: =+VLOOKUP(A40,gasto!$A$4:$F$80,4,FALSE) -> 0 | H40: =+VLOOKUP(A40,gasto!$A$4:$F$80,5,FALSE) -> 1.0236848e+09 | I40: =+VLOOKUP(A40,gasto!$A$4:$F$80,6,FALSE) -> 1.0236848e+09 | J40: =+G40+D40 -> 28877831435 | K40: =+H40+E40 -> 2.4621711e+10 | L40: =+I40+F40 -> 2.4621711e+10 | M40: =+IFERROR(K40*100/C40,0) -> 85.261636 | N40: =+IFERROR(L40*100/C40,0) -> 85.261636 | O40: =+L40/1000000 -> 24621.711
A41: A-3-9-6-0-02 | B41: =+VLOOKUP(A41,gasto!$A$4:$B$100,2,FALSE) -> UPC´S R.S. CSF | C41: =+VLOOKUP(A41,gasto!$A$4:$F$80,3,FALSE) -> 2.1980992e+13 | D41: 2.0291568e+13 | E41: 1.8260388e+13 | F41: 1.8260388e+13 | G41: =+VLOOKUP(A41,gasto!$A$4:$F$80,4,FALSE) -> 1.2658121e+12 | H41: =+VLOOKUP(A41,gasto!$A$4:$F$80,5,FALSE) -> 1.8299014e+12 | I41: =+VLOOKUP(A41,gasto!$A$4:$F$80,6,FALSE) -> 1.8299014e+12 | J41: =+G41+D41 -> 21557379775986 | K41: =+H41+E41 -> 2.009029e+13 | L41: =+I41+F41 -> 2.009029e+13 | M41: =+IFERROR(K41*100/C41,0) -> 91.398469 | N41: =+IFERROR(L41*100/C41,0) -> 91.398469 | O41: =+L41/1000000 -> 20090290
A42: A-3-9-6-0-03 | B42: =+VLOOKUP(A42,gasto!$A$4:$B$100,2,FALSE) -> UPC´S R.S. USPEC | C42: =+VLOOKUP(A42,gasto!$A$4:$F$80,3,FALSE) -> 0 | D42: 0 | E42: 0 | F42: 0 | G42: =+VLOOKUP(A42,gasto!$A$4:$F$80,4,FALSE) -> 0 | H42: =+VLOOKUP(A42,gasto!$A$4:$F$80,5,FALSE) -> 0 | I42: =+VLOOKUP(A42,gasto!$A$4:$F$80,6,FALSE) -> 0 | J42: =+G42+D42 -> 0 | K42: =+H42+E42 -> 0 | L42: =+I42+F42 -> 0 | M42: =+IFERROR(K42*100/C42,0) -> 0 | N42: =+IFERROR(L42*100/C42,0) -> 0 | O42: =+L42/1000000 -> 0
A43: A-3-9-7-0 | B43: =+VLOOKUP(A43,gasto!$A$4:$B$100,2,FALSE) -> Prestaciones Excepcionales - Recobros | C43: =+SUM(C44:C47) -> 4.7355084e+12 | D43: 3.5350806e+12 | E43: 3.5350806e+12 | F43: 3.5350806e+12 | G43: =+SUM(G44:G47) -> 2.8103751e+11 | H43: =+SUM(H44:H47) -> 2.7613414e+11 | I43: =+SUM(I44:I47) -> 2.7613414e+11 | J43: =+SUM(J44:J47) -> 3.8161181e+12 | K43: =+SUM(K44:K47) -> 3.8112147e+12 | L43: =+SUM(L44:L47) -> 3.8112147e+12 | M43: =+IFERROR(K43*100/C43,0) -> 80.481638 | N43: =+IFERROR(L43*100/C43,0) -> 80.481638 | O43: =+L43/1000000 -> 3811214.7
...

Sheet gasto
D1: República de Colombia | E1: EJECUCIÓN DE EGRESOS ACUMULADOS | F1: ADRES ADMINISTRADORA DE LOS RECURSOS DEL SGSSS
A2: CÓDIGO RUBRO | B2: CONCEPTO DEL RUBRO | C2: APROPIACIÓN DEFINITIVA | D2: CDP | E2: RP | F2: PAGOS-OGAG | G2: T. CDP | H2: T. RP | I2: T. PAGOS-OGAG | J2: RP | K2: PAGOS
A3: URA
A4: A-3-2-1-0 | B4: Transferencias Entidades de Administración Pública Central | C4: 86345030430 | D4: 0 | E4: 6.8799777e+09 | F4: 6.8799777e+09 | G4: 82805519661 | H4: 7.5720719e+10 | I4: 7.5720719e+10 | J4: 87.7 | K4: 87.7 | M4: =+VLOOKUP(A4,'CUADRO 2-EJECUCION DE GASTOS'!$A$13:$N$95,10,FALSE) -> 82805519661 | N4: =+VLOOKUP(A4,'CUADRO 2-EJECUCION DE GASTOS'!$A$13:$N$95,11,FALSE) -> 7.5720719e+10 | O4: =+VLOOKUP(A4,'CUADRO 2-EJECUCION DE GASTOS'!$A$13:$N$95,12,FALSE) -> 7.5720719e+10 | P4: =+M4-G4 -> 0 | Q4: =+N4-H4 -> 0 | R4: =+O4-I4 -> 0
A5: A-3-2-1-01 | B5: Contribución IVC Superintendencia Nacional de Salud | C5: 86345030430 | D5: 0 | E5: 6.8799777e+09 | F5: 6.8799777e+09 | G5: 82805519661 | H5: 7.5720719e+10 | I5: 7.5720719e+10 | J5: 87.7 | K5: 87.7 | M5: =+VLOOKUP(A5,'CUADRO 2-EJECUCION DE GASTOS'!$A$13:$N$95,10,FALSE) -> 82805519661 | N5: =+VLOOKUP(A5,'CUADRO 2-EJECUCION DE GASTOS'!$A$13:$N$95,11,FALSE) -> 7.5720719e+10 | O5: =+VLOOKUP(A5,'CUADRO 2-EJECUCION DE GASTOS'!$A$13:$N$95,12,FALSE) -> 7.5720719e+10 | P5: =+M5-G5 -> 0 | Q5: =+N5-H5 -> 0 | R5: =+O5-I5 -> 0
A6: A-3-2-2-0 | B6: Empresas Públicas Nacionales no financieras -ADRES | C6: 145380000000 | D6: 0 | E6: 4.0264397e+09 | F6: 4.0264397e+09 | G6: 145380000000 | H6: 3.827818e+10 | I6: 3.827818e+10 | J6: 26.33 | K6: 26.33 | M6: =+VLOOKUP(A6,'CUADRO 2-EJECUCION DE GASTOS'!$A$13:$N$95,10,FALSE) -> 145380000000 | N6: =+VLOOKUP(A6,'CUADRO 2-EJECUCION DE GASTOS'!$A$13:$N$95,11,FALSE) -> 3.827818e+10 | O6: =+VLOOKUP(A6,'CUADRO 2-EJECUCION DE GASTOS'!$A$13:$N$95,12,FALSE) -> 3.827818e+10 | P6: =+M6-G6 -> 0 | Q6: =+N6-H6 -> 0 | R6: =+O6-I6 -> 0
A7: A-3-2-2-0-01 | B7: Aportes hasta del 0,5% recursos CSF para el desarrollo objeto ADRES | C7: 145380000000 | D7: 0 | E7: 4.0264397e+09 | F7: 4.0264397e+09 | G7: 145380000000 | H7: 3.827818e+10 | I7: 3.827818e+10 | J7: 26.33 | K7: 26.33 | M7: =+VLOOKUP(A7,'CUADRO 2-EJECUCION DE GASTOS'!$A$13:$N$95,10,FALSE) -> 145380000000 | N7: =+VLOOKUP(A7,'CUADRO 2-EJECUCION DE GASTOS'!$A$13:$N$95,11,FALSE) -> 3.827818e+10 | O7: =+VLOOKUP(A7,'CUADRO 2-EJECUCION DE GASTOS'!$A$13:$N$95,12,FALSE) -> 3.827818e+10 | P7: =+M7-G7 -> 0 | Q7: =+N7-H7 -> 0 | R7: =+O7-I7 -> 0
A8: A-3-6-1-0 | B8: Sentencias y Conciliaciones URA | C8: 20000000000 | D8: 32260652 | E8: 1298784.6 | F8: 1298784.6 | G8: 2.2125885e+09 | H8: 2.1816266e+09 | I8: 2.1816266e+09 | J8: 10.91 | K8: 10.91 | M8: =+VLOOKUP(A8,'CUADRO 2-EJECUCION DE GASTOS'!$A$13:$N$95,10,FALSE) -> 2.2125885e+09 | N8: =+VLOOKUP(A8,'CUADRO 2-EJECUCION DE GASTOS'!$A$13:$N$95,11,FALSE) -> 2.1816266e+09 | O8: =+VLOOKUP(A8,'CUADRO 2-EJECUCION DE GASTOS'!$A$13:$N$95,12,FALSE) -> 2.1816266e+09 | P8: =+M8-G8 -> 0 | Q8: =+N8-H8 -> 0 | R8: =+O8-I8 -> 0
A9: A-3-6-1-1 | B9: Sentencias URA | C9: 20000000000 | D9: 32260652 | E9: 1298784.6 | F9: 1298784.6 | G9: 2.2125885e+09 | H9: 2.1816266e+09 | I9: 2.1816266e+09 | J9: 10.91 | K9: 10.91 | M9: =+VLOOKUP(A9,'CUADRO 2-EJECUCION DE GASTOS'!$A$13:$N$95,10,FALSE) -> 2.2125885e+09 | N9: =+VLOOKUP(A9,'CUADRO 2-EJECUCION DE GASTOS'!$A$13:$N$95,11,FALSE) -> 2.1816266e+09 | O9: =+VLOOKUP(A9,'CUADRO 2-EJECUCION DE GASTOS'!$A$13:$N$95,12,FALSE) -> 2.1816266e+09 | P9: =+M9-G9 -> 0 | Q9: =+N9-H9 -> 0 | R9: =+O9-I9 -> 0
A10: A-3-6-1-2 | B10: Conciliaciones URA | C10: 0 | D10: 0 | E10: 0 | F10: 0 | G10: 0 | H10: 0 | I10: 0 | J10: 0 | K10: 0 | M10: =+VLOOKUP(A10,'CUADRO 2-EJECUCION DE GASTOS'!$A$13:$N$95,10,FALSE) -> 0 | N10: =+VLOOKUP(A10,'CUADRO 2-EJECUCION DE GASTOS'!$A$13:$N$95,11,FALSE) -> 0 | O10: =+VLOOKUP(A10,'CUADRO 2-EJECUCION DE GASTOS'!$A$13:$N$95,12,FALSE) -> 0 | P10: =+M10-G10 -> 0 | Q10: =+N10-H10 -> 0 | R10: =+O10-I10 -> 0
A11: A-3-6-3-0 | B11: Destinatarios de otras transferencias Corrientes - Compensación Chance | C11: 134000000000 | D11: 0 | E11: 0 | F11: 0 | G11: 0 | H11: 0 | I11: 0 | J11: 0 | K11: 0 | M11: =+VLOOKUP(A11,'CUADRO 2-EJECUCION DE GASTOS'!$A$13:$N$95,10,FALSE) -> 0 | N11: =+VLOOKUP(A11,'CUADRO 2-EJECUCION DE GASTOS'!$A$13:$N$95,11,FALSE) -> 0 | O11: =+VLOOKUP(A11,'CUADRO 2-EJECUCION DE GASTOS'!$A$13:$N$95,12,FALSE) -> 0 | P11: =+M11-G11 -> 0 | Q11: =+N11-H11 -> 0 | R11: =+O11-I11 -> 0
A12: A-3-6-3-0-01 | B12: Otras transferencias - Compensación del Chance Decreto 2550/12 | C12: 134000000000 | D12: 0 | E12: 0 | F12: 0 | G12: 0 | H12: 0 | I12: 0 | J12: 0 | K12: 0 | M12: =+VLOOKUP(A12,'CUADRO 2-EJECUCION DE GASTOS'!$A$13:$N$95,10,FALSE) -> 0 | N12: =+VLOOKUP(A12,'CUADRO 2-EJECUCION DE GASTOS'!$A$13:$N$95,11,FALSE) -> 0 | O12: =+VLOOKUP(A12,'CUADRO 2-EJECUCION DE GASTOS'!$A$13:$N$95,12,FALSE) -> 0 | P12: =+M12-G12 -> 0 | Q12: =+N12-H12 -> 0 | R12: =+O12-I12 -> 0
A13: A-3-9-1-0 | B13: UPC Régimen Contributivo | C13: 22863934384378 | D13: 3.1690367e+12 | E13: 1829621715847 | F13: 1829621715847 | G13: 22757717488720 | H13: 20464474864318 | I13: 20464474864318 | J13: 89.51 | K13: 89.51 | M13: =+VLOOKUP(A13,'CUADRO 2-EJECUCION DE GASTOS'!$A$13:$N$95,10,FALSE) -> 22757717488720 | N13: =+VLOOKUP(A13,'CUADRO 2-EJECUCION DE GASTOS'!$A$13:$N$95,11,FALSE) -> 20464474864318 | O13: =+VLOOKUP(A13,'CUADRO 2-EJECUCION DE GASTOS'!$A$13:$N$95,12,FALSE) -> 20464474864318 | P13: =+M13-G13 -> 0 | Q13: =+N13-H13 -> 0 | R13: =+O13-I13 -> 0
A14: A-3-9-1-0-01 | B14: UPC Régimen Contributivo SSF | C14: 12575109660289 | D14: 1.8899866e+12 | E14: 1054086594082 | F14: 1054086594082 | G14: 12468892764631 | H14: 11362978705487 | I14: 11362978705487 | J14: 90.36 | K14: 90.36 | M14: =+VLOOKUP(A14,'CUADRO 2-EJECUCION DE GASTOS'!$A$13:$N$95,10,FALSE) -> 12468892764631 | N14: =+VLOOKUP(A14,'CUADRO 2-EJECUCION DE GASTOS'!$A$13:$N$95,11,FALSE) -> 11362978705487 | O14: =+VLOOKUP(A14,'CUADRO 2-EJECUCION DE GASTOS'!$A$13:$N$95,12,FALSE) -> 11362978705487 | P14: =+M14-G14 -> 0 | Q14: =+N14-H14 -> 0 | R14: =+O14-I14 -> 0
A15: A-3-9-1-0-02 | B15: UPC Régimen Contributivo CSF | C15: 10287649289644 | D15: 1279050072215 | E15: 775535121765 | F15: 775535121765 | G15: 10287649289644 | H15: 9100320724386 | I15: 9100320724386 | J15: 88.46 | K15: 88.46 | M15: =+VLOOKUP(A15,'CUADRO 2-EJECUCION DE GASTOS'!$A$13:$N$95,10,FALSE) -> 10287649289644 | N15: =+VLOOKUP(A15,'CUADRO 2-EJECUCION DE GASTOS'!$A$13:$N$95,11,FALSE) -> 9100320724386 | O15: =+VLOOKUP(A15,'CUADRO 2-EJECUCION DE GASTOS'!$A$13:$N$95,12,FALSE) -> 9100320724386 | P15: =+M15-G15 -> 0 | Q15: =+N15-H15 -> 0 | R15: =+O15-I15 -> 0
... A82: A-9-9-9-9 | B82: Disponibilidad Final | C82: 254007875000 | D82: 0 | E82: 0 | F82: 0 | G82: 0 | H82: 0 | I82: 0 | J82: 0 | K82: 0 | M82: =+VLOOKUP(A82,'CUADRO 2-EJECUCION DE GASTOS'!$A$13:$N$95,10,FALSE) -> 0 | N82: =+VLOOKUP(A82,'CUADRO 2-EJECUCION DE GASTOS'!$A$13:$N$95,11,FALSE) -> 0 | O82: =+VLOOKUP(A82,'CUADRO 2-EJECUCION DE GASTOS'!$A$13:$N$95,12,FALSE) -> 0 | P82: =+M82-G82 -> 0 | Q82: =+N82-H82 -> 0 | R82: =+O82-I82 -> 0
