Workbook
Name OLE_LINK1: 'CUADRO 2-EJECUCION DE GASTOS'!#REF!

Sheet CUADRO 1-EJECUCION DE INGRESOS
H1: =+NOW() -> 43539.586 | I1: =+NOW() -> 43539.586
A3: ADMINISTRADORA DE LOS RECURSOS DEL SISTEMA GENERAL DE SEGURIDAD SOCIAL EN SALUD
A4: PRESUPUESTO DE INGRESOS 2019
A5: UNIDAD DE RECURSOS ADMINISTRADOS - URA
A6: CUADRO No. 1
A9: CÓDIGO RUBRO | B9: CONCEPTO DEL RUBRO | C9: AFORO INICIAL | D9: MODIFICACIÓN PRESUPUESTAL | E9: AFORO DEFINITIVO | F9: Ingresos Acumulados Desde 01/01/2019 hasta 31/01/2019 | G9: Ingresos Desde 01/02/2019 hasta 28/02/2019 | H9: Ingresos Acumulados Desde 01/01/2019 hasta 28/02/2019 | I9: EJECUCIÓN ACUMULADA (%)
A10: URA
A11: 0-0-0-0 | B11: DISPONIBILIDAD INICIAL | C11: 422831681000 | D11: =+VLOOKUP(A11,ingresos!$A$1:$F$81,3,FALSE) -> 0 | E11: =+VLOOKUP(A11,ingresos!$A$1:$F$81,4,FALSE) -> 422831681000 | F11: 422831681000 | G11: =+VLOOKUP(A11,ingresos!$A$1:$E$100,5,FALSE) -> 0 | H11: =+G11+F11 -> 422831681000 | I11: =IFERROR(H11/E11*100,0) -> 100
A12: 1-0-0-0 | B12: INGRESOS CORRIENTES | C12: 52054407755223 | D12: =+D13+D27 -> 0 | E12: =+E13+E27 -> 52054407755223 | F12: 4.2522704e+12 | G12: =+G13+G27 -> 4.0638893e+12 | H12: =+G12+F12 -> 8.3161597e+12 | I12: =IFERROR(H12/E12*100,0) -> 15.975899
A13: 1-2-0-0 | B13: Aportes e Impuestos | C13: 19781797637181 | D13: =+D14 -> 0 | E13: =+E14+E26 -> 19781797637181 | F13: 1.5037638e+12 | G13: =+G14+G26 -> 1454714187731 | H13: =+G13+F13 -> 2.958478e+12 | I13: =IFERROR(H13/E13*100,0) -> 14.955557
A14: 1-2-1-0 | B14: Aportes de la Nación | C14: 19781797637181 | D14: =+D15+D18+D19+D20+D21+D24+D25 -> 0 | E14: =+E15+E18+E19+E20+E21+E25+E24+E26 -> 19781797637181 | F14: 1.5037638e+12 | G14: =+G15+G18+G19+G20+G21+G25+G24+G26 -> 1454714187731 | H14: =+G14+F14 -> 2.958478e+12 | I14: =IFERROR(H14/E14*100,0) -> 14.955557
A15: 1-2-1-1 | B15: Aportes de la Nación para el Aseguramiento en Salud | C15: 17803782346000 | D15: =+D16+D17 -> 0 | E15: =+E16+E17 -> 17803782346000 | F15: 1241981862167 | G15: =+SUM(G16:G17) -> 1241981862167 | H15: =+G15+F15 -> 2483963724334 | I15: =IFERROR(H15/E15*100,0) -> 13.951888
A16: 1-2-1-1-01 | B16: Aportes de la Nación para el Aseguramiento en Salud Cierre | C16: 13686804885516 | D16: =+VLOOKUP(A16,ingresos!$A$1:$F$81,3,FALSE) -> 0 | E16: =+VLOOKUP(A16,ingresos!$A$1:$F$81,4,FALSE) -> 13686804885516 | F16: 9.5478383e+11 | G16: =+VLOOKUP(A16,ingresos!$A$1:$E$100,5,FALSE) -> 9.5478383e+11 | H16: =+G16+F16 -> 1.9095677e+12 | I16: =IFERROR(H16/E16*100,0) -> 13.951888
A17: 1-2-1-1-02 | B17: Imporenta | C17: 4116977460484 | D17: =+VLOOKUP(A17,ingresos!$A$1:$F$81,3,FALSE) -> 0 | E17: =+VLOOKUP(A17,ingresos!$A$1:$F$81,4,FALSE) -> 4116977460484 | F17: 2.8719804e+11 | G17: =+VLOOKUP(A17,ingresos!$A$1:$E$100,5,FALSE) -> 2.8719804e+11 | H17: =+G17+F17 -> 5.7439607e+11 | I17: =IFERROR(H17/E17*100,0) -> 13.951888
A18: 1-2-1-2 | B18: Compensación Regalías para el Régimen Subsidiado | C18: 226673765000 | D18: =+VLOOKUP(A18,ingresos!$A$1:$F$81,3,FALSE) -> 0 | E18: =+VLOOKUP(A18,ingresos!$A$1:$F$81,4,FALSE) -> 226673765000 | F18: 0 | G18: =+VLOOKUP(A18,ingresos!$A$1:$E$100,5,FALSE) -> 113336882500 | H18: =+G18+F18 -> 113336882500 | I18: =IFERROR(H18/E18*100,0) -> 50
A19: 1-2-1-3 | B19: Impuesto sobre la renta para la equidad CREE | C19: 0 | D19: =+VLOOKUP(A19,ingresos!$A$1:$F$81,3,FALSE) -> 0 | E19: =+VLOOKUP(A19,ingresos!$A$1:$F$81,4,FALSE) -> 0 | F19: 0 | G19: =+VLOOKUP(A19,ingresos!$A$1:$E$100,5,FALSE) -> 0 | H19: =+G19+F19 -> 0 | I19: =IFERROR(H19/E19*100,0) -> 0
A20: 1-2-1-4 | B20: SGP FONSAET | C20: 95551523562 | D20: =+VLOOKUP(A20,ingresos!$A$1:$F$81,3,FALSE) -> 0 | E20: =+VLOOKUP(A20,ingresos!$A$1:$F$81,4,FALSE) -> 95551523562 | F20: 0 | G20: =+VLOOKUP(A20,ingresos!$A$1:$E$100,5,FALSE) -> 0 | H20: =+G20+F20 -> 0 | I20: =IFERROR(H20/E20*100,0) -> 0
A21: 1-2-1-5 | B21: PRIMA FONSAT Y CONTRIBUCION SOAT | C21: 1640527441000 | D21: =+D22+D23 -> 0 | E21: =+E22+E23 -> 1640527441000 | F21: 2.455599e+11 | G21: =+SUM(G22:G23) -> 96949660450 | H21: =+G21+F21 -> 3.4250956e+11 | I21: =IFERROR(H21/E21*100,0) -> 20.878015
A22: 1-2-1-5-01 | B22: % Prima (FONSAT) Decreto Ley 1335 de 2009 | C22: 363281118360 | D22: =+VLOOKUP(A22,ingresos!$A$1:$F$81,3,FALSE) -> 0 | E22: =+VLOOKUP(A22,ingresos!$A$1:$F$81,4,FALSE) -> 363281118360 | F22: 7.770565e+10 | G22: =+VLOOKUP(A22,ingresos!$A$1:$E$100,5,FALSE) -> 0 | H22: =+G22+F22 -> 7.770565e+10 | I22: =IFERROR(H22/E22*100,0) -> 21.38995
A23: 1-2-1-5-02 | B23: Contribución Seguro Obligatorio de Accidentes de Tránsito - SOAT- Decreto Ley 1335 de 2009 | C23: 1277246322640 | D23: =+VLOOKUP(A23,ingresos!$A$1:$F$81,3,FALSE) -> 0 | E23: =+VLOOKUP(A23,ingresos!$A$1:$F$81,4,FALSE) -> 1277246322640 | F23: 167854247950 | G23: =+VLOOKUP(A23,ingresos!$A$1:$E$100,5,FALSE) -> 96949660450 | H23: =+G23+F23 -> 264803908400 | I23: =IFERROR(H23/E23*100,0) -> 20.732407
A24: 1-2-1-7 | B24: Impuesto social a las municiones y explosivos | C24: 6410791000 | D24: =+VLOOKUP(A24,ingresos!$A$1:$F$81,3,FALSE) -> 0 | E24: =+VLOOKUP(A24,ingresos!$A$1:$F$81,4,FALSE) -> 6410791000 | F24: 15439498040 | G24: =+VLOOKUP(A24,ingresos!$A$1:$E$100,5,FALSE) -> 2248525224 | H24: =+G24+F24 -> 17688023264 | I24: =IFERROR(H24/E24*100,0) -> 275.91015
A25: 1-2-1-8 | B25: Impuesto social a las armas | C25: 8851770619 | D25: =+VLOOKUP(A25,ingresos!$A$1:$F$81,3,FALSE) -> 0 | E25: =+VLOOKUP(A25,ingresos!$A$1:$F$81,4,FALSE) -> 8851770619 | F25: 782571447 | G25: =+VLOOKUP(A25,ingresos!$A$1:$E$100,5,FALSE) -> 197257390 | H25: =+G25+F25 -> 979828837 | I25: =IFERROR(H25/E25*100,0) -> 11.069298
A26: 1-2-9-0 | B26: Otros aportes e impuestos de la nación | C26: 0 | D26: =+VLOOKUP(A26,ingresos!$A$1:$F$81,3,FALSE) -> 0 | E26: =+VLOOKUP(A26,ingresos!$A$1:$F$81,4,FALSE) -> 0 | F26: 0 | G26: =+VLOOKUP(A26,ingresos!$A$1:$E$100,5,FALSE) -> 0 | H26: =+G26+F26 -> 0 | I26: =IFERROR(H26/E26*100,0) -> 0
A27: 1-3-0-0 | B27: Otros Ingresos Corrientes | C27: 32272610118042 | D27: =+D28 -> 0 | E27: =+E28+E56 -> 32272610118042 | F27: 2.7485066e+12 | G27: =+G28+G56 -> 2.6091751e+12 | H27: =+G27+F27 -> 5.3576817e+12 | I27: =IFERROR(H27/E27*100,0) -> 16.601327
A28: 1-3-5-0 | B28: Ingresos Sistema General de Seguridad Social en Salud | C28: 22105255788877 | D28: =+D29+D32+D35+D40+D50+D53 -> 0 | E28: =+E29+E32+E35+E40+E50+E53 -> 22105255788877 | F28: 1.918439e+12 | G28: =+G29+G32+G35+G40+G50+G53 -> 1.7521832e+12 | H28: =+G28+F28 -> 3.6706222e+12 | I28: =IFERROR(H28/E28*100,0) -> 16.605201
A29: 1-3-5-1 | B29: Cotizaciones al SGSSS | C29: 20346328129563 | D29: =+SUM(D30:D31) -> 0 | E29: =+SUM(E30:E31) -> 20346328129563 | F29: 1706496864866 | G29: =+SUM(G30:G31) -> 1579203265432 | H29: =+G29+F29 -> 3285700130298 | I29: =IFERROR(H29/E29*100,0) -> 16.14886
A30: 1-3-5-1-01 | B30: Régimen Contributivo CSF | C30: 6807438619821 | D30: =+VLOOKUP(A30,ingresos!$A$1:$F$81,3,FALSE) -> 0 | E30: =+VLOOKUP(A30,ingresos!$A$1:$F$81,4,FALSE) -> 6807438619821 | F30: 716197711248 | G30: =+VLOOKUP(A30,ingresos!$A$1:$E$100,5,FALSE) -> 486418197765 | H30: =+G30+F30 -> 1202615909013 | I30: =IFERROR(H30/E30*100,0) -> 17.666203
A31: 1-3-5-1-02 | B31: Régimen Contributivo SSF | C31: 13538889509742 | D31: =+VLOOKUP(A31,ingresos!$A$1:$F$81,3,FALSE) -> 0 | E31: =+VLOOKUP(A31,ingresos!$A$1:$F$81,4,FALSE) -> 13538889509742 | F31: 990299153618 | G31: =+VLOOKUP(A31,ingresos!$A$1:$E$100,5,FALSE) -> 1092785067667 | H31: =+G31+F31 -> 2083084221285 | I31: =IFERROR(H31/E31*100,0) -> 15.385931
A32: 1-3-5-2 | B32: Aporte Solidaridad de Regímenes de Excepcion y Especiales | C32: 1000356775894 | D32: =+SUM(D33:D34) -> 0 | E32: =+SUM(E33:E34) -> 1000356775894 | F32: 6.2818952e+10 | G32: =+SUM(G33:G34) -> 7.1190325e+10 | H32: =+G32+F32 -> 1.3400928e+11 | I32: =IFERROR(H32/E32*100,0) -> 13.396148
A33: 1-3-5-2-01 | B33: Cotizaciones afiliados REX con ingresos adicionales | C33: 594961177882 | D33: =+VLOOKUP(A33,ingresos!$A$1:$F$81,3,FALSE) -> 0 | E33: =+VLOOKUP(A33,ingresos!$A$1:$F$81,4,FALSE) -> 594961177882 | F33: 40622846969 | G33: =+VLOOKUP(A33,ingresos!$A$1:$E$100,5,FALSE) -> 42313417844 | H33: =+G33+F33 -> 82936264813 | I33: =IFERROR(H33/E33*100,0) -> 13.939778
A34: 1-3-5-2-02 | B34: Aporte Solidario entidades REX | C34: 405395598012 | D34: =+VLOOKUP(A34,ingresos!$A$1:$F$81,3,FALSE) -> 0 | E34: =+VLOOKUP(A34,ingresos!$A$1:$F$81,4,FALSE) -> 405395598012 | F34: 2.2196105e+10 | G34: =+VLOOKUP(A34,ingresos!$A$1:$E$100,5,FALSE) -> 2.8876907e+10 | H34: =+G34+F34 -> 5.1073012e+10 | I34: =IFERROR(H34/E34*100,0) -> 12.598314
A35: 1-3-5-3 | B35: Aportes Cajas de Compensación Familiar | C35: 499207099674 | D35: =+SUM(D36:D39) -> 0 | E35: =+SUM(E36:E39) -> 499207099674 | F35: 5.0320072e+10 | G35: =+SUM(G36:G39) -> 4.3108052e+10 | H35: =+G35+F35 -> 9.3428124e+10 | I35: =IFERROR(H35/E35*100,0) -> 18.715304
A36: 1-3-5-3-01 | B36: Aportes CCF Artículo 217 Ley 100 de 1993 CSF | C36: 466578060617 | D36: =+VLOOKUP(A36,ingresos!$A$1:$F$81,3,FALSE) -> 0 | E36: =+VLOOKUP(A36,ingresos!$A$1:$F$81,4,FALSE) -> 466578060617 | F36: 4.660073e+10 | G36: =+VLOOKUP(A36,ingresos!$A$1:$E$100,5,FALSE) -> 3.8664696e+10 | H36: =+G36+F36 -> 8.5265426e+10 | I36: =IFERROR(H36/E36*100,0) -> 18.274633
A37: 1-3-5-3-02 | B37: Aportes CCF Artículo 217 Ley 100 de 1993 SSF | C37: 28877831435 | D37: =+VLOOKUP(A37,ingresos!$A$1:$F$81,3,FALSE) -> 0 | E37: =+VLOOKUP(A37,ingresos!$A$1:$F$81,4,FALSE) -> 28877831435 | F37: 3204560767 | G37: =+VLOOKUP(A37,ingresos!$A$1:$E$100,5,FALSE) -> 2958034371 | H37: =+G37+F37 -> 6162595138 | I37: =IFERROR(H37/E37*100,0) -> 21.340228
A38: 1-3-5-3-03 | B38: Aportes CCF Balance | C38: 3751207622 | D38: =+VLOOKUP(A38,ingresos!$A$1:$F$81,3,FALSE) -> 0 | E38: =+VLOOKUP(A38,ingresos!$A$1:$F$81,4,FALSE) -> 3751207622 | F38: 514780895 | G38: =+VLOOKUP(A38,ingresos!$A$1:$E$100,5,FALSE) -> 1485321874 | H38: =+G38+F38 -> 2000102769 | I38: =IFERROR(H38/E38*100,0) -> 53.318903
A39: 1-3-5-3-04 | B39: Otros Aportes CCF | C39: 0 | D39: =+VLOOKUP(A39,ingresos!$A$1:$F$81,3,FALSE) -> 0 | E39: =+VLOOKUP(A39,ingresos!$A$1:$F$81,4,FALSE) -> 0 | F39: 0 | G39: =+VLOOKUP(A39,ingresos!$A$1:$E$100,5,FALSE) -> 0 | H39: =+G39+F39 -> 0 | I39: =IFERROR(H39/E39*100,0) -> 0
A40: 1-3-5-5 | B40: Reintegros / Recuperaciones | C40: 0 | D40: =+SUM(D41:D49) -> 0 | E40: =+SUM(E41:E49) -> 0 | F40: 8.1696375e+10 | G40: =+SUM(G41:G49) -> 4.1910385e+10 | H40: =+G40+F40 -> 1.2360676e+11 | I40: =IFERROR(H40/E40*100,0) -> 0
A41: 1-3-5-5-01 | B41: UPC Régimen Contributivo Vigencias anteriores | C41: 0 | D41: =+VLOOKUP(A41,ingresos!$A$1:$F$81,3,FALSE) -> 0 | E41: =+VLOOKUP(A41,ingresos!$A$1:$F$81,4,FALSE) -> 0 | F41: 7.3991137e+09 | G41: =+VLOOKUP(A41,ingresos!$A$1:$E$100,5,FALSE) -> 64427597 | H41: =+G41+F41 -> 7.4635413e+09 | I41: =IFERROR(H41/E41*100,0) -> 0
A42: 1-3-5-5-02 | B42: P&P Vigencias anteriores | C42: 0 | D42: =+VLOOKUP(A42,ingresos!$A$1:$F$81,3,FALSE) -> 0 | E42: =+VLOOKUP(A42,ingresos!$A$1:$F$81,4,FALSE) -> 0 | F42: 0 | G42: =+VLOOKUP(A42,ingresos!$A$1:$E$100,5,FALSE) -> 0 | H42: =+G42+F42 -> 0 | I42: =IFERROR(H42/E42*100,0) -> 0
A43: 1-3-5-5-03 | B43: Licencias de Maternidad y Paternidad Vigencias anteriores | C43: 0 | D43: =+VLOOKUP(A43,ingresos!$A$1:$F$81,3,FALSE) -> 0 | E43: =+VLOOKUP(A43,ingresos!$A$1:$F$81,4,FALSE) -> 0 | F43: 0 | G43: =+VLOOKUP(A43,ingresos!$A$1:$E$100,5,FALSE) -> 0 | H43: =+G43+F43 -> 0 | I43: =IFERROR(H43/E43*100,0) -> 0
...

Sheet CUADRO 2-EJECUCION DE GASTOS
M1: =+TODAY() -> 43539 | N1: =+NOW() -> 43539.586
A3: ADMINISTRADORA DE LOS RECURSOS DEL SISTEMA GENERAL DE SEGURIDAD SOCIAL EN SALUD
A4: PRESUPUESTO DE GASTOS 2019
A5: UNIDAD DE RECURSOS ADMINISTRADOS - URA
A6: CUADRO No. 2
A9: CÓDIGO RUBRO | B9: CONCEPTO DEL RUBRO | C9: APROPIACIÓN DEFINITIVA | D9: EJECUCION PRESUPUESTAL ACUMULADA DESDE 01/01/2019 HASTA 31/01/2019 | G9: EJECUCION PRESUPUESTAL DESDE 01/02/2019 HASTA 28/02/2019 | J9: EJECUCION PRESUPUESTAL ACUMULADA DESDE 01/01/2019 HASTA 28/02/2019 | M9: %
D10: T. CDP | E10: T. RP | F10: T. PAGOS-OP | G10: CDP | H10: RP | I10: PAGOS-OP | J10: T. CDP | K10: T. RP | L10: T. PAGOS-OP | M10: RP | N10: OP
B11: URA
A12: A-3-0-0-0 | B12: TRANSFERENCIAS | C12: =+C13+C18+C24 -> 52382816715223 | D12: 4.1486636e+12 | E12: 3.9911398e+12 | F12: 3.9911398e+12 | G12: =+G13+G18+G24 -> 4.0398987e+12 | H12: =+H13+H18+H24 -> 3.9726599e+12 | I12: =+I13+I18+I24 -> 3.9726599e+12 | J12: =+G12+D12 -> 8.1885623e+12 | K12: =+H12+E12 -> 7.9637997e+12 | L12: =+I12+F12 -> 7.9637997e+12 | M12: =+IFERROR(K12*100/C12,0) -> 15.203077 | N12: =+IFERROR(L12*100/C12,0) -> 15.203077
A13: A-3-2-0-0 | B13: TRANSFERENCIAS AL SECTOR PUBLICO | C13: =+C14+C16 -> 231725030430 | D13: 145380000000 | E13: 4.166544e+09 | F13: 4.166544e+09 | G13: =+G14+G16 -> 82805519661 | H13: =+H14+H16 -> 1.6118497e+10 | I13: =+I14+I16 -> 1.6118497e+10 | J13: =+G13+D13 -> 228185519661 | K13: =+H13+E13 -> 2.0285041e+10 | L13: =+I13+F13 -> 2.0285041e+10 | M13: =+IFERROR(K13*100/C13,0) -> 8.7539274 | N13: =+IFERROR(L13*100/C13,0) -> 8.7539274
A14: A-3-2-1-0 | B14: Transferencias Entidades de Administración Pública Central | C14: =+C15 -> 86345030430 | D14: 0 | E14: 0 | F14: 0 | G14: =+G15 -> 82805519661 | H14: =+H15 -> 1.380092e+10 | I14: =+I15 -> 1.380092e+10 | J14: =+J15 -> 82805519661 | K14: =+K15 -> 1.380092e+10 | L14: =+L15 -> 1.380092e+10 | M14: =+IFERROR(K14*100/C14,0) -> 15.983456 | N14: =+IFERROR(L14*100/C14,0) -> 15.983456
A15: A-3-2-1-01 | B15: Contribución IVC Superintendencia Nacional de Salud | C15: =+VLOOKUP(A15,gasto!$A$4:$F$68,3,FALSE) -> 86345030430 | D15: 0 | E15: 0 | F15: 0 | G15: =+VLOOKUP(A15,gasto!$A$4:$F$68,4,FALSE) -> 82805519661 | H15: =+VLOOKUP(A15,gasto!$A$4:$F$68,5,FALSE) -> 1.380092e+10 | I15: =+VLOOKUP(A15,gasto!$A$4:$F$68,6,FALSE) -> 1.380092e+10 | J15: =+G15+D15 -> 82805519661 | K15: =+H15+E15 -> 1.380092e+10 | L15: =+I15+F15 -> 1.380092e+10 | M15: =+IFERROR(K15*100/C15,0) -> 15.983456 | N15: =+IFERROR(L15*100/C15,0) -> 15.983456
A16: A-3-2-2-0 | B16: Empresas Públicas Nacionales no financieras -ADRES | C16: =+C17 -> 145380000000 | D16: 145380000000 | E16: 4.166544e+09 | F16: 4.166544e+09 | G16: =+G17 -> 0 | H16: =+H17 -> 2.317577e+09 | I16: =+I17 -> 2.317577e+09 | J16: =+J17 -> 145380000000 | K16: =+K17 -> 6.484121e+09 | L16: =+L17 -> 6.484121e+09 | M16: =+IFERROR(K16*100/C16,0) -> 4.460119 | N16: =+IFERROR(L16*100/C16,0) -> 4.460119
A17: A-3-2-2-0-01 | B17: Aportes hasta del 0,5% recursos CSF para el desarrollo objeto ADRES | C17: =+VLOOKUP(A17,gasto!$A$4:$F$68,3,FALSE) -> 145380000000 | D17: 145380000000 | E17: 4.166544e+09 | F17: 4.166544e+09 | G17: =+VLOOKUP(A17,gasto!$A$4:$F$68,4,FALSE) -> 0 | H17: =+VLOOKUP(A17,gasto!$A$4:$F$68,5,FALSE) -> 2.317577e+09 | I17: =+VLOOKUP(A17,gasto!$A$4:$F$68,6,FALSE) -> 2.317577e+09 | J17: =+G17+D17 -> 145380000000 | K17: =+H17+E17 -> 6.484121e+09 | L17: =+I17+F17 -> 6.484121e+09 | M17: =+IFERROR(K17*100/C17,0) -> 4.460119 | N17: =+IFERROR(L17*100/C17,0) -> 4.460119
A18: A-3-6-0-0 | B18: OTRAS TRANSFERENCIAS | C18: =+C19+C22 -> 180000000000 | D18: 1656232 | E18: 0 | F18: 0 | G18: =+G19+G22 -> 0 | H18: =+H19+H22 -> 1656232 | I18: =+I19+I22 -> 1656232 | J18: =+G18+D18 -> 1656232 | K18: =+H18+E18 -> 1656232 | L18: =+I18+F18 -> 1656232 | M18: =+IFERROR(K18*100/C18,0) -> 0.00092012889 | N18: =+IFERROR(L18*100/C18,0) -> 0.00092012889
A19: A-3-6-1-0 | B19: Sentencias y Conciliaciones URA | C19: =+SUM(C20:C21) -> 20000000000 | D19: 1656232 | E19: 0 | F19: 0 | G19: =+SUM(G20:G21) -> 0 | H19: =+SUM(H20:H21) -> 1656232 | I19: =+SUM(I20:I21) -> 1656232 | J19: =+SUM(J20:J21) -> 1656232 | K19: =+SUM(K20:K21) -> 1656232 | L19: =+SUM(L20:L21) -> 1656232 | M19: =+IFERROR(K19*100/C19,0) -> 0.00828116 | N19: =+IFERROR(L19*100/C19,0) -> 0.00828116
A20: A-3-6-1-1 | B20: Sentencias URA | C20: =+VLOOKUP(A20,gasto!$A$4:$F$68,3,FALSE) -> 20000000000 | D20: 1656232 | E20: 0 | F20: 0 | G20: =+VLOOKUP(A20,gasto!$A$4:$F$68,4,FALSE) -> 0 | H20: =+VLOOKUP(A20,gasto!$A$4:$F$68,5,FALSE) -> 1656232 | I20: =+VLOOKUP(A20,gasto!$A$4:$F$68,6,FALSE) -> 1656232 | J20: =+G20+D20 -> 1656232 | K20: =+H20+E20 -> 1656232 | L20: =+I20+F20 -> 1656232 | M20: =+IFERROR(K20*100/C20,0) -> 0.00828116 | N20: =+IFERROR(L20*100/C20,0) -> 0.00828116
A21: A-3-6-1-2 | B21: Conciliaciones URA | C21: =+VLOOKUP(A21,gasto!$A$4:$F$68,3,FALSE) -> 0 | D21: 0 | E21: 0 | F21: 0 | G21: =+VLOOKUP(A21,gasto!$A$4:$F$68,4,FALSE) -> 0 | H21: =+VLOOKUP(A21,gasto!$A$4:$F$68,5,FALSE) -> 0 | I21: =+VLOOKUP(A21,gasto!$A$4:$F$68,6,FALSE) -> 0 | J21: =+G21+D21 -> 0 | K21: =+H21+E21 -> 0 | L21: =+I21+F21 -> 0 | M21: =+IFERROR(K21*100/C21,0) -> 0 | N21: =+IFERROR(L21*100/C21,0) -> 0
A22: A-3-6-3-0 | B22: Destinatarios de otras transferencias Corrientes - Compensación Chance | C22: =+C23 -> 160000000000 | D22: 0 | E22: 0 | F22: 0 | G22: =+G23 -> 0 | H22: =+H23 -> 0 | I22: =+I23 -> 0 | J22: =+J23 -> 0 | K22: =+K23 -> 0 | L22: =+L23 -> 0 | M22: =+IFERROR(K22*100/C22,0) -> 0 | N22: =+IFERROR(L22*100/C22,0) -> 0
A23: A-3-6-3-0-01 | B23: Otras transferencias - Compensación del Chance Decreto 2550/12 | C23: =+VLOOKUP(A23,gasto!$A$4:$F$68,3,FALSE) -> 160000000000 | D23: 0 | E23: 0 | F23: 0 | G23: =+VLOOKUP(A23,gasto!$A$4:$F$68,4,FALSE) -> 0 | H23: =+VLOOKUP(A23,gasto!$A$4:$F$68,5,FALSE) -> 0 | I23: =+VLOOKUP(A23,gasto!$A$4:$F$68,6,FALSE) -> 0 | J23: =+G23+D23 -> 0 | K23: =+H23+E23 -> 0 | L23: =+I23+F23 -> 0 | M23: =+IFERROR(K23*100/C23,0) -> 0 | N23: =+IFERROR(L23*100/C23,0) -> 0
A24: A-3-9-0-0 | B24: ADMINISTRACIÓN DE RECURSOS DEL SGSSS | C24: =+C25+C30+C33+C36+C37+C38+C42+C45+C52+C56+C66+C77+C79+C81 -> 51971091684793 | D24: 4.003282e+12 | E24: 3.9869733e+12 | F24: 3.9869733e+12 | G24: =+G25+G30+G33+G36+G37+G38+G42+G45+G52+G56+G66+G77+G79+G81 -> 3.9570932e+12 | H24: =+H25+H30+H33+H36+H37+H38+H42+H45+H52+H56+H66+H77+H79+H81 -> 3.9565398e+12 | I24: =+I25+I30+I33+I36+I37+I38+I42+I45+I52+I56+I66+I77+I79+I81 -> 3.9565398e+12 | J24: =+G24+D24 -> 7.9603752e+12 | K24: =+H24+E24 -> 7.943513e+12 | L24: =+I24+F24 -> 7.943513e+12 | M24: =+IFERROR(K24*100/C24,0) -> 15.284484 | N24: =+IFERROR(L24*100/C24,0) -> 15.284484
A25: A-3-9-1-0 | B25: UPC Régimen Contributivo | C25: =+SUM(C26:C29) -> 23057892632980 | D25: 1825601270168 | E25: 1825601270168 | F25: 1825601270168 | G25: =+SUM(G26:G29) -> 1760987462633 | H25: =+SUM(H26:H29) -> 1760987462633 | I25: =+SUM(I26:I29) -> 1760987462633 | J25: =+SUM(J26:J29) -> 3586588732801 | K25: =+SUM(K26:K29) -> 3586588732801 | L25: =+SUM(L26:L29) -> 3586588732801 | M25: =+IFERROR(K25*100/C25,0) -> 15.554712 | N25: =+IFERROR(L25*100/C25,0) -> 15.554712
A26: A-3-9-1-0-01 | B26: UPC Régimen Contributivo SSF | C26: =+VLOOKUP(A26,gasto!$A$4:$F$68,3,FALSE) -> 12399109660289 | D26: 910942673794 | E26: 910942673794 | F26: 910942673794 | G26: =+VLOOKUP(A26,gasto!$A$4:$F$68,4,FALSE) -> 1006693409199 | H26: =+VLOOKUP(A26,gasto!$A$4:$F$68,5,FALSE) -> 1006693409199 | I26: =+VLOOKUP(A26,gasto!$A$4:$F$68,6,FALSE) -> 1006693409199 | J26: =+G26+D26 -> 1917636082993 | K26: =+H26+E26 -> 1917636082993 | L26: =+I26+F26 -> 1917636082993 | M26: =+IFERROR(K26*100/C26,0) -> 15.465918 | N26: =+IFERROR(L26*100/C26,0) -> 15.465918
A27: A-3-9-1-0-02 | B27: UPC Régimen Contributivo CSF | C27: =+VLOOKUP(A27,gasto!$A$4:$F$68,3,FALSE) -> 10647939289644 | D27: 914297953268 | E27: 914297953268 | F27: 914297953268 | G27: =+VLOOKUP(A27,gasto!$A$4:$F$68,4,FALSE) -> 753812543226 | H27: =+VLOOKUP(A27,gasto!$A$4:$F$68,5,FALSE) -> 753812543226 | I27: =+VLOOKUP(A27,gasto!$A$4:$F$68,6,FALSE) -> 753812543226 | J27: =+G27+D27 -> 1668110496494 | K27: =+H27+E27 -> 1668110496494 | L27: =+I27+F27 -> 1668110496494 | M27: =+IFERROR(K27*100/C27,0) -> 15.666041 | N27: =+IFERROR(L27*100/C27,0) -> 15.666041
A28: A-3-9-1-0-03 | B28: Devolución aportes y cotizaciones no conciliadas vigencia anterior | C28: =+VLOOKUP(A28,gasto!$A$4:$F$68,3,FALSE) -> 10223147816 | D28: 360643106 | E28: 360643106 | F28: 360643106 | G28: =+VLOOKUP(A28,gasto!$A$4:$F$68,4,FALSE) -> 481510208 | H28: =+VLOOKUP(A28,gasto!$A$4:$F$68,5,FALSE) -> 481510208 | I28: =+VLOOKUP(A28,gasto!$A$4:$F$68,6,FALSE) -> 481510208 | J28: =+G28+D28 -> 842153314 | K28: =+H28+E28 -> 842153314 | L28: =+I28+F28 -> 842153314 | M28: =+IFERROR(K28*100/C28,0) -> 8.2377104 | N28: =+IFERROR(L28*100/C28,0) -> 8.2377104
A29: A-3-9-1-0-04 | B29: Rendimientos Financieros de los Saldos no Compensados de los Aportes Patronales según Art. 12 Decreto 1636 de 2016 | C29: =+VLOOKUP(A29,gasto!$A$4:$F$68,3,FALSE) -> 620535231 | D29: 0 | E29: 0 | F29: 0 | G29: =+VLOOKUP(A29,gasto!$A$4:$F$68,4,FALSE) -> 0 | H29: =+VLOOKUP(A29,gasto!$A$4:$F$68,5,FALSE) -> 0 | I29: =+VLOOKUP(A29,gasto!$A$4:$F$68,6,FALSE) -> 0 | J29: =+G29+D29 -> 0 | K29: =+H29+E29 -> 0 | L29: =+I29+F29 -> 0 | M29: =+IFERROR(K29*100/C29,0) -> 0 | N29: =+IFERROR(L29*100/C29,0) -> 0
A30: A-3-9-2-0 | B30: Per capita Programas de Promoción y Prevención R.C | C30: =+SUM(C31:C32) -> 646778600953 | D30: 41852875331 | E30: 41852875331 | F30: 41852875331 | G30: =+SUM(G31:G32) -> 39698517109 | H30: =+SUM(H31:H32) -> 39698517109 | I30: =+SUM(I31:I32) -> 39698517109 | J30: =+SUM(J31:J32) -> 81551392440 | K30: =+SUM(K31:K32) -> 81551392440 | L30: =+SUM(L31:L32) -> 81551392440 | M30: =+IFERROR(K30*100/C30,0) -> 12.608858 | N30: =+IFERROR(L30*100/C30,0) -> 12.608858
A31: A-3-9-2-0-01 | B31: Per capita Programas de Promoción y Prevención R.C SSF | C31: =+VLOOKUP(A31,gasto!$A$4:$F$68,3,FALSE) -> 510526042986 | D31: 31541610651 | E31: 31541610651 | F31: 31541610651 | G31: =+VLOOKUP(A31,gasto!$A$4:$F$68,4,FALSE) -> 33176782964 | H31: =+VLOOKUP(A31,gasto!$A$4:$F$68,5,FALSE) -> 33176782964 | I31: =+VLOOKUP(A31,gasto!$A$4:$F$68,6,FALSE) -> 33176782964 | J31: =+G31+D31 -> 64718393615 | K31: =+H31+E31 -> 64718393615 | L31: =+I31+F31 -> 64718393615 | M31: =+IFERROR(K31*100/C31,0) -> 12.676806 | N31: =+IFERROR(L31*100/C31,0) -> 12.676806
A32: A-3-9-2-0-02 | B32: Per capita Programas de Promoción y Prevención R.C CSF | C32: =+VLOOKUP(A32,gasto!$A$4:$F$68,3,FALSE) -> 136252557967 | D32: 10311264680 | E32: 10311264680 | F32: 10311264680 | G32: =+VLOOKUP(A32,gasto!$A$4:$F$68,4,FALSE) -> 6521734145 | H32: =+VLOOKUP(A32,gasto!$A$4:$F$68,5,FALSE) -> 6521734145 | I32: =+VLOOKUP(A32,gasto!$A$4:$F$68,6,FALSE) -> 6521734145 | J32: =+G32+D32 -> 16832998825 | K32: =+H32+E32 -> 16832998825 | L32: =+I32+F32 -> 16832998825 | M32: =+IFERROR(K32*100/C32,0) -> 12.354263 | N32: =+IFERROR(L32*100/C32,0) -> 12.354263
A33: A-3-9-3-0 | B33: Incapacidades | C33: =+SUM(C34:C35) -> 814461941941 | D33: 67741191373 | E33: 67741191373 | F33: 67741191373 | G33: =+SUM(G34:G35) -> 64137338163 | H33: =+SUM(H34:H35) -> 64137338163 | I33: =+SUM(I34:I35) -> 64137338163 | J33: =+SUM(J34:J35) -> 131878529536 | K33: =+SUM(K34:K35) -> 131878529536 | L33: =+SUM(L34:L35) -> 131878529536 | M33: =+IFERROR(K33*100/C33,0) -> 16.192105 | N33: =+IFERROR(L33*100/C33,0) -> 16.192105
A34: A-3-9-3-0-01 | B34: Incapacidades SSF | C34: =+VLOOKUP(A34,gasto!$A$4:$F$68,3,FALSE) -> 629253806467 | D34: 47814869173 | E34: 47814869173 | F34: 47814869173 | G34: =+VLOOKUP(A34,gasto!$A$4:$F$68,4,FALSE) -> 52914875504 | H34: =+VLOOKUP(A34,gasto!$A$4:$F$68,5,FALSE) -> 52914875504 | I34: =+VLOOKUP(A34,gasto!$A$4:$F$68,6,FALSE) -> 52914875504 | J34: =+G34+D34 -> 100729744677 | K34: =+H34+E34 -> 100729744677 | L34: =+I34+F34 -> 100729744677 | M34: =+IFERROR(K34*100/C34,0) -> 16.007809 | N34: =+IFERROR(L34*100/C34,0) -> 16.007809
A35: A-3-9-3-0-02 | B35: Incapacidades CSF | C35: =+VLOOKUP(A35,gasto!$A$4:$F$68,3,FALSE) -> 185208135474 | D35: 19926322200 | E35: 19926322200 | F35: 19926322200 | G35: =+VLOOKUP(A35,gasto!$A$4:$F$68,4,FALSE) -> 11222462659 | H35: =+VLOOKUP(A35,gasto!$A$4:$F$68,5,FALSE) -> 11222462659 | I35: =+VLOOKUP(A35,gasto!$A$4:$F$68,6,FALSE) -> 11222462659 | J35: =+G35+D35 -> 31148784859 | K35: =+H35+E35 -> 31148784859 | L35: =+I35+F35 -> 31148784859 | M35: =+IFERROR(K35*100/C35,0) -> 16.81826 | N35: =+IFERROR(L35*100/C35,0) -> 16.81826
A36: A-3-9-4-0 | B36: Licencias de Maternidad y Paternidad | C36: =+VLOOKUP(A36,gasto!$A$4:$F$68,3,FALSE) -> 838554045453 | D36: 67879430670 | E36: 67879430670 | F36: 67879430670 | G36: =+VLOOKUP(A36,gasto!$A$4:$F$68,4,FALSE) -> 64995286647 | H36: =+VLOOKUP(A36,gasto!$A$4:$F$68,5,FALSE) -> 64995286647 | I36: =+VLOOKUP(A36,gasto!$A$4:$F$68,6,FALSE) -> 64995286647 | J36: =+G36+D36 -> 132874717317 | K36: =+H36+E36 -> 132874717317 | L36: =+I36+F36 -> 132874717317 | M36: =+IFERROR(K36*100/C36,0) -> 15.845695 | N36: =+IFERROR(L36*100/C36,0) -> 15.845695
A37: A-3-9-5-0 | B37: Prestaciones Económicas Regímenes Especial y de Excepción | C37: =+VLOOKUP(A37,gasto!$A$4:$F$68,3,FALSE) -> 4102227236 | D37: 3048911179 | E37: 73201075 | F37: 73201075 | G37: =+VLOOKUP(A37,gasto!$A$4:$F$68,4,FALSE) -> 1053316057 | H37: =+VLOOKUP(A37,gasto!$A$4:$F$68,5,FALSE) -> 499896927 | I37: =+VLOOKUP(A37,gasto!$A$4:$F$68,6,FALSE) -> 499896927 | J37: =+G37+D37 -> 4102227236 | K37: =+H37+E37 -> 573098002 | L37: =+I37+F37 -> 573098002 | M37: =+IFERROR(K37*100/C37,0) -> 13.970411 | N37: =+IFERROR(L37*100/C37,0) -> 13.970411
A38: A-3-9-6-0 | B38: UPC Régimen Subsidiado | C38: =+SUM(C39:C41) -> 21586257607421 | D38: 1.7760712e+12 | E38: 1.7760712e+12 | F38: 1.7760712e+12 | G38: =+SUM(G39:G41) -> 1.7568776e+12 | H38: =+SUM(H39:H41) -> 1.7568776e+12 | I38: =+SUM(I39:I41) -> 1.7568776e+12 | J38: =+SUM(J39:J41) -> 3.5329488e+12 | K38: =+SUM(K39:K41) -> 3.5329488e+12 | L38: =+SUM(L39:L41) -> 3.5329488e+12 | M38: =+IFERROR(K38*100/C38,0) -> 16.366657 | N38: =+IFERROR(L38*100/C38,0) -> 16.366657
A39: A-3-9-6-0-01 | B39: UPC´S R.S. Cajas de Compensación Familiar SSF | C39: =+VLOOKUP(A39,gasto!$A$4:$F$68,3,FALSE) -> 28877831435 | D39: 3204560767 | E39: 3204560767 | F39: 3204560767 | G39: =+VLOOKUP(A39,gasto!$A$4:$F$68,4,FALSE) -> 2958034371 | H39: =+VLOOKUP(A39,gasto!$A$4:$F$68,5,FALSE) -> 2958034371 | I39: =+VLOOKUP(A39,gasto!$A$4:$F$68,6,FALSE) -> 2958034371 | J39: =+G39+D39 -> 6162595138 | K39: =+H39+E39 -> 6162595138 | L39: =+I39+F39 -> 6162595138 | M39: =+IFERROR(K39*100/C39,0) -> 21.340228 | N39: =+IFERROR(L39*100/C39,0) -> 21.340228
A40: A-3-9-6-0-02 | B40: UPC´S R.S. CSF | C40: =+VLOOKUP(A40,gasto!$A$4:$F$68,3,FALSE) -> 21520379775986 | D40: 1.7728666e+12 | E40: 1.7728666e+12 | F40: 1.7728666e+12 | G40: =+VLOOKUP(A40,gasto!$A$4:$F$68,4,FALSE) -> 1.7539196e+12 | H40: =+VLOOKUP(A40,gasto!$A$4:$F$68,5,FALSE) -> 1.7539196e+12 | I40: =+VLOOKUP(A40,gasto!$A$4:$F$68,6,FALSE) -> 1.7539196e+12 | J40: =+G40+D40 -> 3.5267863e+12 | K40: =+H40+E40 -> 3.5267863e+12 | L40: =+I40+F40 -> 3.5267863e+12 | M40: =+IFERROR(K40*100/C40,0) -> 16.388123 | N40: =+IFERROR(L40*100/C40,0) -> 16.388123
A41: A-3-9-6-0-03 | B41: UPC´S R.S. USPEC | C41: =+VLOOKUP(A41,gasto!$A$4:$F$68,3,FALSE) -> 37000000000 | D41: 0 | E41: 0 | F41: 0 | G41: =+VLOOKUP(A41,gasto!$A$4:$F$68,4,FALSE) -> 0 | H41: =+VLOOKUP(A41,gasto!$A$4:$F$68,5,FALSE) -> 0 | I41: =+VLOOKUP(A41,gasto!$A$4:$F$68,6,FALSE) -> 0 | J41: =+G41+D41 -> 0 | K41: =+H41+E41 -> 0 | L41: =+I41+F41 -> 0 | M41: =+IFERROR(K41*100/C41,0) -> 0 | N41: =+IFERROR(L41*100/C41,0) -> 0
A42: A-3-9-7-0 | B42: Prestaciones Excepcionales - Recobros | C42: =+SUM(C43:C44) -> 4083854535766 | D42: 2.0671425e+11 | E42: 2.0671425e+11 | F42: 2.0671425e+11 | G42: =+SUM(G43:G44) -> 2.6810531e+11 | H42: =+SUM(H43:H44) -> 2.6810531e+11 | I42: =+SUM(I43:I44) -> 2.6810531e+11 | J42: =+SUM(J43:J44) -> 4.7481956e+11 | K42: =+SUM(K43:K44) -> 4.7481956e+11 | L42: =+SUM(L43:L44) -> 4.7481956e+11 | M42: =+IFERROR(K42*100/C42,0) -> 11.62675 | N42: =+IFERROR(L42*100/C42,0) -> 11.62675
A43: A-3-9-7-0-01 | B43: Recobros - Reembolsos Régimen Contributivo | C43: =+VLOOKUP(A43,gasto!$A$4:$F$68,3,FALSE) -> 4072663890220 | D43: 2.0644103e+11 | E43: 2.0644103e+11 | F43: 2.0644103e+11 | G43: =+VLOOKUP(A43,gasto!$A$4:$F$68,4,FALSE) -> 2.6802289e+11 | H43: =+VLOOKUP(A43,gasto!$A$4:$F$68,5,FALSE) -> 2.6802289e+11 | I43: =+VLOOKUP(A43,gasto!$A$4:$F$68,6,FALSE) -> 2.6802289e+11 | J43: =+G43+D43 -> 4.7446392e+11 | K43: =+H43+E43 -> 4.7446392e+11 | L43: =+I43+F43 -> 4.7446392e+11 | M43: =+IFERROR(K43*100/C43,0) -> 11.649965 | N43: =+IFERROR(L43*100/C43,0) -> 11.649965
...

Sheet ingresos
A1: RUBRO | B1: inicial | C1: MODIFICACIONES | D1: AFORO DEFINITIVO | E1: INGRESO MES | F1: % | G1: acum
A2: 0-0-0-0 | B2: 422831681000 | C2: 0 | D2: 422831681000 | E2: 0 | G2: 422831681000 | H2: 422831681000 | I2: =+H2-G2 -> 0
A3: 1-2-1-1 | B3: 17803782346000 | C3: 0 | D3: 17803782346000 | E3: 1241981862167 | G3: 2483963724334 | H3: 2483963724334 | I3: =+H3-G3 -> 0
A4: 1-2-1-1-01 | B4: 13686804885516 | C4: 0 | D4: 13686804885516 | E4: 9.5478383e+11 | G4: 1.9095677e+12 | H4: 1.9095677e+12 | I4: =+H4-G4 -> 0
A5: 1-2-1-1-02 | B5: 4116977460484 | C5: 0 | D5: 4116977460484 | E5: 2.8719804e+11 | G5: 5.7439607e+11 | H5: 5.7439607e+11 | I5: =+H5-G5 -> 0
A6: 1-2-1-2 | B6: 226673765000 | C6: 0 | D6: 226673765000 | E6: 113336882500 | G6: 113336882500 | H6: 113336882500 | I6: =+H6-G6 -> 0
A7: 1-2-1-3 | B7: 0 | C7: 0 | D7: 0 | E7: 0 | G7: 0 | H7: 0 | I7: =+H7-G7 -> 0
A8: 1-2-1-4 | B8: 95551523562 | C8: 0 | D8: 95551523562 | E8: 0 | G8: 0 | H8: 0 | I8: =+H8-G8 -> 0
A9: 1-2-1-5 | B9: 1640527441000 | C9: 0 | D9: 1640527441000 | E9: 96949660450 | G9: 3.4250956e+11 | H9: 3.4250956e+11 | I9: =+H9-G9 -> 0
A10: 1-2-1-5-01 | B10: 363281118360 | C10: 0 | D10: 363281118360 | E10: 0 | G10: 7.770565e+10 | H10: 7.770565e+10 | I10: =+H10-G10 -> 0
A11: 1-2-1-5-02 | B11: 1277246322640 | C11: 0 | D11: 1277246322640 | E11: 96949660450 | G11: 264803908400 | H11: 264803908400 | I11: =+H11-G11 -> 0
A12: 1-2-1-7 | B12: 6410791000 | C12: 0 | D12: 6410791000 | E12: 2248525224 | G12: 17688023264 | H12: 17688023264 | I12: =+H12-G12 -> 0
A13: 1-2-1-8 | B13: 8851770619 | C13: 0 | D13: 8851770619 | E13: 197257390 | G13: 979828837 | H13: 979828837 | I13: =+H13-G13 -> 0
... A81: 2-9-0-0-02 | B81: 0 | C81: 0 | D81: 0 | E81: 1290709 | G81: 4414618 | H81: 4414618 | I81: =+H81-G81 -> 0

Sheet gasto
D1: República de Colombia | E1: EJECUCIÓN DE EGRESOS ACUMULADOS | F1: ADRES ADMINISTRADORA DE LOS RECURSOS DEL SGSSS
A2: CÓDIGO RUBRO | B2: CONCEPTO DEL RUBRO | C2: APROPIACIÓN DEFINITIVA | D2: CDP | E2: RP | F2: PAGOS-OGAG | G2: T. CDP | H2: T. RP | I2: T. PAGOS-OGAG | J2: RP | K2: PAGOS
A3: URA
A4: A-3-2-1-0 | B4: Transferencias Entidades de Administración Pública Central | C4: 86345030430 | D4: 82805519661 | E4: 1.380092e+10 | F4: 1.380092e+10 | G4: 82805519661 | H4: 1.380092e+10 | I4: 1.380092e+10 | J4: 15.983456 | K4: 15.983456
A5: A-3-2-1-01 | B5: Contribución IVC Superintendencia Nacional de Salud | C5: 86345030430 | D5: 82805519661 | E5: 1.380092e+10 | F5: 1.380092e+10 | G5: 82805519661 | H5: 1.380092e+10 | I5: 1.380092e+10 | J5: 15.983456 | K5: 15.983456
A6: A-3-2-2-0 | B6: Empresas Públicas Nacionales no financieras -ADRES | C6: 145380000000 | D6: 0 | E6: 2.317577e+09 | F6: 2.317577e+09 | G6: 145380000000 | H6: 6.484121e+09 | I6: 6.484121e+09 | J6: 4.460119 | K6: 4.460119
A7: A-3-2-2-0-01 | B7: Aportes hasta del 0,5% recursos CSF para el desarrollo objeto ADRES | C7: 145380000000 | D7: 0 | E7: 2.317577e+09 | F7: 2.317577e+09 | G7: 145380000000 | H7: 6.484121e+09 | I7: 6.484121e+09 | J7: 4.460119 | K7: 4.460119
A8: A-3-6-1-0 | B8: Sentencias y Conciliaciones URA | C8: 20000000000 | D8: 0 | E8: 1656232 | F8: 1656232 | G8: 1656232 | H8: 1656232 | I8: 1656232 | J8: 0.00828116 | K8: 0.00828116
A9: A-3-6-1-1 | B9: Sentencias URA | C9: 20000000000 | D9: 0 | E9: 1656232 | F9: 1656232 | G9: 1656232 | H9: 1656232 | I9: 1656232 | J9: 0.00828116 | K9: 0.00828116
A10: A-3-6-1-2 | B10: Conciliaciones URA | C10: 0 | D10: 0 | E10: 0 | F10: 0 | G10: 0 | H10: 0 | I10: 0 | J10: 0 | K10: 0
A11: A-3-6-3-0 | B11: Destinatarios de otras transferencias Corrientes - Compensación Chance | C11: 160000000000 | D11: 0 | E11: 0 | F11: 0 | G11: 0 | H11: 0 | I11: 0 | J11: 0 | K11: 0
A12: A-3-6-3-0-01 | B12: Otras transferencias - Compensación del Chance Decreto 2550/12 | C12: 160000000000 | D12: 0 | E12: 0 | F12: 0 | G12: 0 | H12: 0 | I12: 0 | J12: 0 | K12: 0
A13: A-3-9-1-0 | B13: UPC Régimen Contributivo | C13: 23057892632980 | D13: 1760987462633 | E13: 1760987462633 | F13: 1760987462633 | G13: 3586588732801 | H13: 3586588732801 | I13: 3586588732801 | J13: 15.554712 | K13: 15.554712
A14: A-3-9-1-0-01 | B14: UPC Régimen Contributivo SSF | C14: 12399109660289 | D14: 1006693409199 | E14: 1006693409199 | F14: 1006693409199 | G14: 1917636082993 | H14: 1917636082993 | I14: 1917636082993 | J14: 15.465918 | K14: 15.465918
A15: A-3-9-1-0-02 | B15: UPC Régimen Contributivo CSF | C15: 10647939289644 | D15: 753812543226 | E15: 753812543226 | F15: 753812543226 | G15: 1668110496494 | H15: 1668110496494 | I15: 1668110496494 | J15: 15.666041 | K15: 15.666041
... A73: A-9-9-9-9 | B73: Disponibilidad Final | C73: 254007875000 | D73: 0 | E73: 0 | F73: 0 | G73: 0 | H73: 0 | I73: 0 | J73: 0 | K73: 0
