Workbook
Name OLE_LINK1: 'CUADRO 2-EJECUCION DE GASTOS'!#REF!

Sheet CUADRO 1-EJECUCION DE INGRESOS
H1: =+NOW() -> 43676.359 | I1: =+NOW() -> 43676.359
A3: ADMINISTRADORA DE LOS RECURSOS DEL SISTEMA GENERAL DE SEGURIDAD SOCIAL EN SALUD
A4: UNIDAD DE RECURSOS ADMINISTRADOS - URA
A5: CODIGO DE LA EMPRESA 12902 - ADMINISTRACION DE RECURSOS DEL SGSSS
A6: PRESUPUESTO DE INGRESOS DE JUNIO DE 2019
A7: CUADRO No. 1
A10: CÓDIGO RUBRO | B10: CONCEPTO DEL RUBRO | C10: AFORO INICIAL | D10: MODIFICACIÓN PRESUPUESTAL | E10: AFORO DEFINITIVO | F10: Ingresos Acumulados Desde 01/01/2019 hasta 31/05/2019 | G10: Ingresos Desde 01/06/2019 hasta 30/06/2019 | H10: Ingresos Acumulados Desde 01/01/2019 hasta 30/06/2019 | I10: EJECUCIÓN ACUMULADA (%)
A11: URA
A12: 0-0-0-0 | B12: =+VLOOKUP(A12,Ingresos!$A$2:$B$82,2,FALSE) -> Disponibilidad inicial | C12: 422831681000 | D12: =+VLOOKUP(A12,Ingresos!$A$1:$F$90,3,FALSE) -> 488101188290 | E12: =+VLOOKUP(A12,Ingresos!$A$1:$F$90,4,FALSE) -> 910932869290 | F12: 422831681000 | G12: =+VLOOKUP(A12,Ingresos!$A$1:$E$100,5,FALSE) -> 488101188290 | H12: =+G12+F12 -> 910932869290 | I12: =IFERROR(H12/E12*100,0) -> 100 | K12: =+H12/1000000 -> 910932.87
A13: 1-0-0-0 | B13: INGRESOS CORRIENTES | C13: 52054407755223 | D13: =+D14+D28 -> 0 | E13: =+E14+E28 -> 52054407755223 | F13: 2.1221951e+13 | G13: =+G14+G28 -> 3.9968027e+12 | H13: =+G13+F13 -> 2.5218754e+13 | I13: =IFERROR(H13/E13*100,0) -> 48.446913 | K13: =+H13/1000000 -> 25218754
A14: 1-2-0-0 | B14: Aportes e Impuestos | C14: 19781797637181 | D14: =+D15 -> 0 | E14: =+E15+E27 -> 19781797637181 | F14: 7.9159637e+12 | G14: =+G15+G27 -> 1293820709385 | H14: =+G14+F14 -> 9.2097844e+12 | I14: =IFERROR(H14/E14*100,0) -> 46.556863 | K14: =+H14/1000000 -> 9209784.4
A15: 1-2-1-0 | B15: Aportes de la Nación | C15: 19781797637181 | D15: =+D16+D19+D20+D21+D22+D25+D26 -> 0 | E15: =+E16+E19+E20+E21+E22+E26+E25+E27 -> 19781797637181 | F15: 7.9159637e+12 | G15: =+G16+G19+G20+G21+G22+G26+G25+G27 -> 1293820709385 | H15: =+G15+F15 -> 9.2097844e+12 | I15: =IFERROR(H15/E15*100,0) -> 46.556863 | K15: =+H15/1000000 -> 9209784.4
A16: 1-2-1-1 | B16: =+VLOOKUP(A16,Ingresos!$A$2:$B$82,2,FALSE) -> Aportes de la Nación para el Aseguramiento en Salud | C16: 17803782346000 | D16: =+D17+D18 -> 0 | E16: =+E17+E18 -> 17803782346000 | F16: 6.8543538e+12 | G16: =+SUM(G17:G18) -> 1166604084389 | H16: =+G16+F16 -> 8.0209578e+12 | I16: =IFERROR(H16/E16*100,0) -> 45.051988 | K16: =+H16/1000000 -> 8020957.8
A17: 1-2-1-1-01 | B17: =+VLOOKUP(A17,Ingresos!$A$2:$B$82,2,FALSE) -> Aportes de la Nación para el Aseguramiento en Salud Cierre | C17: 13686804885516 | D17: =+VLOOKUP(A17,Ingresos!$A$1:$F$90,3,FALSE) -> 0 | E17: =+VLOOKUP(A17,Ingresos!$A$1:$F$90,4,FALSE) -> 12507321670830 | F17: 4.8152469e+12 | G17: =+VLOOKUP(A17,Ingresos!$A$1:$E$100,5,FALSE) -> 8.1955015e+11 | H17: =+G17+F17 -> 5.634797e+12 | I17: =IFERROR(H17/E17*100,0) -> 45.051988 | K17: =+H17/1000000 -> 5634797
A18: 1-2-1-1-02 | B18: =+VLOOKUP(A18,Ingresos!$A$2:$B$82,2,FALSE) -> Imporenta | C18: 4116977460484 | D18: =+VLOOKUP(A18,Ingresos!$A$1:$F$90,3,FALSE) -> 0 | E18: =+VLOOKUP(A18,Ingresos!$A$1:$F$90,4,FALSE) -> 5296460675170 | F18: 2.0391069e+12 | G18: =+VLOOKUP(A18,Ingresos!$A$1:$E$100,5,FALSE) -> 3.4705393e+11 | H18: =+G18+F18 -> 2.3861608e+12 | I18: =IFERROR(H18/E18*100,0) -> 45.051988 | K18: =+H18/1000000 -> 2386160.8
A19: 1-2-1-2 | B19: =+VLOOKUP(A19,Ingresos!$A$2:$B$82,2,FALSE) -> Compensación Regalías para el Régimen Subsidiado | C19: 226673765000 | D19: =+VLOOKUP(A19,Ingresos!$A$1:$F$90,3,FALSE) -> 0 | E19: =+VLOOKUP(A19,Ingresos!$A$1:$F$90,4,FALSE) -> 226673765000 | F19: 226673765000 | G19: =+VLOOKUP(A19,Ingresos!$A$1:$E$100,5,FALSE) -> 0 | H19: =+G19+F19 -> 226673765000 | I19: =IFERROR(H19/E19*100,0) -> 100 | K19: =+H19/1000000 -> 226673.77
A20: 1-2-1-3 | B20: =+VLOOKUP(A20,Ingresos!$A$2:$B$82,2,FALSE) -> Impuesto sobre la renta para la equidad CREE | C20: 0 | D20: =+VLOOKUP(A20,Ingresos!$A$1:$F$90,3,FALSE) -> 0 | E20: =+VLOOKUP(A20,Ingresos!$A$1:$F$90,4,FALSE) -> 0 | F20: 0 | G20: =+VLOOKUP(A20,Ingresos!$A$1:$E$100,5,FALSE) -> 0 | H20: =+G20+F20 -> 0 | I20: =IFERROR(H20/E20*100,0) -> 0 | K20: =+H20/1000000 -> 0
A21: 1-2-1-4 | B21: =+VLOOKUP(A21,Ingresos!$A$2:$B$82,2,FALSE) -> SGP FONSAET | C21: 95551523562 | D21: =+VLOOKUP(A21,Ingresos!$A$1:$F$90,3,FALSE) -> 0 | E21: =+VLOOKUP(A21,Ingresos!$A$1:$F$90,4,FALSE) -> 95551523562 | F21: 0 | G21: =+VLOOKUP(A21,Ingresos!$A$1:$E$100,5,FALSE) -> 0 | H21: =+G21+F21 -> 0 | I21: =IFERROR(H21/E21*100,0) -> 0 | K21: =+H21/1000000 -> 0
A22: 1-2-1-5 | B22: =+VLOOKUP(A22,Ingresos!$A$2:$B$82,2,FALSE) -> PRIMA FONSAT Y CONTRIBUCION SOAT | C22: 1640527441000 | D22: =+D23+D24 -> 0 | E22: =+E23+E24 -> 1640527441000 | F22: 7.8628141e+11 | G22: =+SUM(G23:G24) -> 111862061274 | H22: =+G22+F22 -> 8.9814347e+11 | I22: =IFERROR(H22/E22*100,0) -> 54.747238 | K22: =+H22/1000000 -> 898143.47
A23: 1-2-1-5-01 | B23: =+VLOOKUP(A23,Ingresos!$A$2:$B$82,2,FALSE) -> % Prima (FONSAT) Decreto Ley 1335 de 2009 | C23: 363281118360 | D23: =+VLOOKUP(A23,Ingresos!$A$1:$F$90,3,FALSE) -> 0 | E23: =+VLOOKUP(A23,Ingresos!$A$1:$F$90,4,FALSE) -> 363281118360 | F23: 1.9749469e+11 | G23: =+VLOOKUP(A23,Ingresos!$A$1:$E$100,5,FALSE) -> 0 | H23: =+G23+F23 -> 1.9749469e+11 | I23: =IFERROR(H23/E23*100,0) -> 54.364148 | K23: =+H23/1000000 -> 197494.69
A24: 1-2-1-5-02 | B24: =+VLOOKUP(A24,Ingresos!$A$2:$B$82,2,FALSE) -> Contribución Seguro Obligatorio de Accidentes de Tránsito - SOAT- Decreto Ley 1335 de 2009 | C24: 1277246322640 | D24: =+VLOOKUP(A24,Ingresos!$A$1:$F$90,3,FALSE) -> 0 | E24: =+VLOOKUP(A24,Ingresos!$A$1:$F$90,4,FALSE) -> 1277246322640 | F24: 5.8878672e+11 | G24: =+VLOOKUP(A24,Ingresos!$A$1:$E$100,5,FALSE) -> 111862061274 | H24: =+G24+F24 -> 7.0064878e+11 | I24: =IFERROR(H24/E24*100,0) -> 54.856199 | K24: =+H24/1000000 -> 700648.78
A25: 1-2-1-7 | B25: =+VLOOKUP(A25,Ingresos!$A$2:$B$82,2,FALSE) -> Impuesto social a las municiones y explosivos | C25: 6410791000 | D25: =+VLOOKUP(A25,Ingresos!$A$1:$F$90,3,FALSE) -> 0 | E25: =+VLOOKUP(A25,Ingresos!$A$1:$F$90,4,FALSE) -> 6410791000 | F25: 44811505703 | G25: =+VLOOKUP(A25,Ingresos!$A$1:$E$100,5,FALSE) -> 14354115977 | H25: =+G25+F25 -> 59165621680 | I25: =IFERROR(H25/E25*100,0) -> 922.90673 | K25: =+H25/1000000 -> 59165.622
A26: 1-2-1-8 | B26: =+VLOOKUP(A26,Ingresos!$A$2:$B$82,2,FALSE) -> Impuesto social a las armas | C26: 8851770619 | D26: =+VLOOKUP(A26,Ingresos!$A$1:$F$90,3,FALSE) -> 0 | E26: =+VLOOKUP(A26,Ingresos!$A$1:$F$90,4,FALSE) -> 8851770619 | F26: 3843290647 | G26: =+VLOOKUP(A26,Ingresos!$A$1:$E$100,5,FALSE) -> 1000447745 | H26: =+G26+F26 -> 4843738392 | I26: =IFERROR(H26/E26*100,0) -> 54.720559 | K26: =+H26/1000000 -> 4843.7384
A27: 1-2-9-0 | B27: =+VLOOKUP(A27,Ingresos!$A$2:$B$82,2,FALSE) -> Otros aportes e impuestos de la nación | C27: 0 | D27: =+VLOOKUP(A27,Ingresos!$A$1:$F$90,3,FALSE) -> 0 | E27: =+VLOOKUP(A27,Ingresos!$A$1:$F$90,4,FALSE) -> 0 | F27: 0 | G27: =+VLOOKUP(A27,Ingresos!$A$1:$E$100,5,FALSE) -> 0 | H27: =+G27+F27 -> 0 | I27: =IFERROR(H27/E27*100,0) -> 0 | K27: =+H27/1000000 -> 0
A28: 1-3-0-0 | B28: Otros Ingresos Corrientes | C28: 32272610118042 | D28: =+D29 -> 0 | E28: =+E29+E58 -> 32272610118042 | F28: 1.3305987e+13 | G28: =+G29+G58 -> 2.702982e+12 | H28: =+G28+F28 -> 1.6008969e+13 | I28: =IFERROR(H28/E28*100,0) -> 49.605436 | K28: =+H28/1000000 -> 16008969
A29: 1-3-5-0 | B29: Ingresos Sistema General de Seguridad Social en Salud | C29: 22105255788877 | D29: =+D30+D33+D36+D41+D51+D54+D57 -> 0 | E29: =+E30+E33+E36+E41+E51+E54+E57 -> 22105255788877 | F29: 9.2160333e+12 | G29: =+G30+G33+G36+G41+G51+G54+G57 -> 1.85803e+12 | H29: =+G29+F29 -> 1.1074063e+13 | I29: =IFERROR(H29/E29*100,0) -> 50.09697 | K29: =+H29/1000000 -> 11074063
A30: 1-3-5-1 | B30: =+VLOOKUP(A30,Ingresos!$A$2:$B$82,2,FALSE) -> Cotizaciones al SGSSS | C30: 20346328129563 | D30: =+SUM(D31:D32) -> 0 | E30: =+SUM(E31:E32) -> 20346328129563 | F30: 8270654262719 | G30: =+SUM(G31:G32) -> 1621624101985 | H30: =+G30+F30 -> 9892278364704 | I30: =IFERROR(H30/E30*100,0) -> 48.619477 | K30: =+H30/1000000 -> 9892278.4
A31: 1-3-5-1-01 | B31: =+VLOOKUP(A31,Ingresos!$A$2:$B$82,2,FALSE) -> Régimen Contributivo CSF | C31: 6807438619821 | D31: =+VLOOKUP(A31,Ingresos!$A$1:$F$90,3,FALSE) -> 0 | E31: =+VLOOKUP(A31,Ingresos!$A$1:$F$90,4,FALSE) -> 6807438619821 | F31: 2849919382766 | G31: =+VLOOKUP(A31,Ingresos!$A$1:$E$100,5,FALSE) -> 522355428948 | H31: =+G31+F31 -> 3372274811714 | I31: =IFERROR(H31/E31*100,0) -> 49.538086 | K31: =+H31/1000000 -> 3372274.8
A32: 1-3-5-1-02 | B32: =+VLOOKUP(A32,Ingresos!$A$2:$B$82,2,FALSE) -> Régimen Contributivo SSF | C32: 13538889509742 | D32: =+VLOOKUP(A32,Ingresos!$A$1:$F$90,3,FALSE) -> 0 | E32: =+VLOOKUP(A32,Ingresos!$A$1:$F$90,4,FALSE) -> 13538889509742 | F32: 5420734879953 | G32: =+VLOOKUP(A32,Ingresos!$A$1:$E$100,5,FALSE) -> 1099268673037 | H32: =+G32+F32 -> 6520003552990 | I32: =IFERROR(H32/E32*100,0) -> 48.157595 | K32: =+H32/1000000 -> 6520003.6
A33: 1-3-5-2 | B33: =+VLOOKUP(A33,Ingresos!$A$2:$B$82,2,FALSE) -> Aporte Solidaridad de Regímenes de Excepcion y Especiales | C33: 1000356775894 | D33: =+SUM(D34:D35) -> 0 | E33: =+SUM(E34:E35) -> 1000356775894 | F33: 3.602431e+11 | G33: =+SUM(G34:G35) -> 7.4714521e+10 | H33: =+G33+F33 -> 4.3495762e+11 | I33: =IFERROR(H33/E33*100,0) -> 43.480249 | K33: =+H33/1000000 -> 434957.62
A34: 1-3-5-2-01 | B34: =+VLOOKUP(A34,Ingresos!$A$2:$B$82,2,FALSE) -> Cotizaciones afiliados REX con ingresos adicionales | C34: 594961177882 | D34: =+VLOOKUP(A34,Ingresos!$A$1:$F$90,3,FALSE) -> 0 | E34: =+VLOOKUP(A34,Ingresos!$A$1:$F$90,4,FALSE) -> 594961177882 | F34: 214704214534 | G34: =+VLOOKUP(A34,Ingresos!$A$1:$E$100,5,FALSE) -> 44270775588 | H34: =+G34+F34 -> 258974990122 | I34: =IFERROR(H34/E34*100,0) -> 43.528049 | K34: =+H34/1000000 -> 258974.99
A35: 1-3-5-2-02 | B35: =+VLOOKUP(A35,Ingresos!$A$2:$B$82,2,FALSE) -> Aporte Solidario entidades REX | C35: 405395598012 | D35: =+VLOOKUP(A35,Ingresos!$A$1:$F$90,3,FALSE) -> 0 | E35: =+VLOOKUP(A35,Ingresos!$A$1:$F$90,4,FALSE) -> 405395598012 | F35: 1.4553889e+11 | G35: =+VLOOKUP(A35,Ingresos!$A$1:$E$100,5,FALSE) -> 3.0443746e+10 | H35: =+G35+F35 -> 1.7598263e+11 | I35: =IFERROR(H35/E35*100,0) -> 43.410099 | K35: =+H35/1000000 -> 175982.63
A36: 1-3-5-3 | B36: =+VLOOKUP(A36,Ingresos!$A$2:$B$82,2,FALSE) -> Aportes Cajas de Compensación Familiar | C36: 499207099674 | D36: =+SUM(D37:D40) -> 0 | E36: =+SUM(E37:E40) -> 499207099674 | F36: 2.2280162e+11 | G36: =+SUM(G37:G40) -> 2.072353e+10 | H36: =+G36+F36 -> 243525149523 | I36: =IFERROR(H36/E36*100,0) -> 48.782389 | K36: =+H36/1000000 -> 243525.15
A37: 1-3-5-3-01 | B37: =+VLOOKUP(A37,Ingresos!$A$2:$B$82,2,FALSE) -> Aportes CCF Artículo 217 Ley 100 de 1993 CSF | C37: 466578060617 | D37: =+VLOOKUP(A37,Ingresos!$A$1:$F$90,3,FALSE) -> 0 | E37: =+VLOOKUP(A37,Ingresos!$A$1:$F$90,4,FALSE) -> 466578060617 | F37: 2.0588336e+11 | G37: =+VLOOKUP(A37,Ingresos!$A$1:$E$100,5,FALSE) -> 1.8239265e+10 | H37: =+G37+F37 -> 2.2412263e+11 | I37: =IFERROR(H37/E37*100,0) -> 48.035398 | K37: =+H37/1000000 -> 224122.63
A38: 1-3-5-3-02 | B38: =+VLOOKUP(A38,Ingresos!$A$2:$B$82,2,FALSE) -> Aportes CCF Artículo 217 Ley 100 de 1993 SSF | C38: 28877831435 | D38: =+VLOOKUP(A38,Ingresos!$A$1:$F$90,3,FALSE) -> 0 | E38: =+VLOOKUP(A38,Ingresos!$A$1:$F$90,4,FALSE) -> 28877831435 | F38: 1.4089319e+10 | G38: =+VLOOKUP(A38,Ingresos!$A$1:$E$100,5,FALSE) -> 2484211881 | H38: =+G38+F38 -> 1.657353e+10 | I38: =IFERROR(H38/E38*100,0) -> 57.39188 | K38: =+H38/1000000 -> 16573.53
A39: 1-3-5-3-03 | B39: =+VLOOKUP(A39,Ingresos!$A$2:$B$82,2,FALSE) -> Aportes CCF Balance | C39: 3751207622 | D39: =+VLOOKUP(A39,Ingresos!$A$1:$F$90,3,FALSE) -> 0 | E39: =+VLOOKUP(A39,Ingresos!$A$1:$F$90,4,FALSE) -> 3751207622 | F39: 2000102769 | G39: =+VLOOKUP(A39,Ingresos!$A$1:$E$100,5,FALSE) -> 0 | H39: =+G39+F39 -> 2000102769 | I39: =IFERROR(H39/E39*100,0) -> 53.318903 | K39: =+H39/1000000 -> 2000.1028
A40: 1-3-5-3-04 | B40: =+VLOOKUP(A40,Ingresos!$A$2:$B$82,2,FALSE) -> Otros Aportes CCF | C40: 0 | D40: =+VLOOKUP(A40,Ingresos!$A$1:$F$90,3,FALSE) -> 0 | E40: =+VLOOKUP(A40,Ingresos!$A$1:$F$90,4,FALSE) -> 0 | F40: 828836818 | G40: =+VLOOKUP(A40,Ingresos!$A$1:$E$100,5,FALSE) -> 52881.8 | H40: =+G40+F40 -> 8.288897e+08 | I40: =IFERROR(H40/E40*100,0) -> 0 | K40: =+H40/1000000 -> 828.8897
A41: 1-3-5-5 | B41: =+VLOOKUP(A41,Ingresos!$A$2:$B$82,2,FALSE) -> Reintegros / Recuperaciones | C41: 0 | D41: =+SUM(D42:D50) -> 0 | E41: =+SUM(E42:E50) -> 0 | F41: 2.7199956e+11 | G41: =+SUM(G42:G50) -> 1.231061e+11 | H41: =+G41+F41 -> 3.9510566e+11 | I41: =IFERROR(H41/E41*100,0) -> 0 | K41: =+H41/1000000 -> 395105.66
A42: 1-3-5-5-01 | B42: =+VLOOKUP(A42,Ingresos!$A$2:$B$82,2,FALSE) -> UPC Régimen Contributivo Vigencias anteriores | C42: 0 | D42: =+VLOOKUP(A42,Ingresos!$A$1:$F$90,3,FALSE) -> 0 | E42: =+VLOOKUP(A42,Ingresos!$A$1:$F$90,4,FALSE) -> 0 | F42: 9.0797633e+09 | G42: =+VLOOKUP(A42,Ingresos!$A$1:$E$100,5,FALSE) -> 1571081742 | H42: =+G42+F42 -> 1.0650845e+10 | I42: =IFERROR(H42/E42*100,0) -> 0 | K42: =+H42/1000000 -> 10650.845
A43: 1-3-5-5-02 | B43: =+VLOOKUP(A43,Ingresos!$A$2:$B$82,2,FALSE) -> P&P Vigencias anteriores | C43: 0 | D43: =+VLOOKUP(A43,Ingresos!$A$1:$F$90,3,FALSE) -> 0 | E43: =+VLOOKUP(A43,Ingresos!$A$1:$F$90,4,FALSE) -> 0 | F43: 0 | G43: =+VLOOKUP(A43,Ingresos!$A$1:$E$100,5,FALSE) -> 0 | H43: =+G43+F43 -> 0 | I43: =IFERROR(H43/E43*100,0) -> 0 | K43: =+H43/1000000 -> 0
...

Sheet Ingresos
A1: RUBRO | B1: inicial | C1: MODIFICACIONES | D1: AFORO DEFINITIVO | E1: INGRESO MES | F1: % | G1: acum
A2: 0-0-0-0 | B2: Disponibilidad inicial | C2: 488101188290 | D2: 910932869290 | E2: 488101188290 | F2: 100 | G2: 910932869290 | H2: =+VLOOKUP(A2,'CUADRO 1-EJECUCION DE INGRESOS'!$A$12:$I$99,8,FALSE) -> 910932869290 | I2: =+H2-G2 -> 0
A3: 1-2-1-1 | B3: Aportes de la Nación para el Aseguramiento en Salud | C3: 0 | D3: 17803782346000 | E3: 1166604084389 | F3: 45.05 | G3: 8.0209578e+12 | H3: =+VLOOKUP(A3,'CUADRO 1-EJECUCION DE INGRESOS'!$A$12:$I$99,8,FALSE) -> 8.0209578e+12 | I3: =+H3-G3 -> 0
A4: 1-2-1-1-01 | B4: Aportes de la Nación para el Aseguramiento en Salud Cierre | C4: 0 | D4: 12507321670830 | E4: 8.1955015e+11 | F4: 45.05 | G4: 5.634797e+12 | H4: =+VLOOKUP(A4,'CUADRO 1-EJECUCION DE INGRESOS'!$A$12:$I$99,8,FALSE) -> 5.634797e+12 | I4: =+H4-G4 -> 0
A5: 1-2-1-1-02 | B5: Imporenta | C5: 0 | D5: 5296460675170 | E5: 3.4705393e+11 | F5: 45.05 | G5: 2.3861608e+12 | H5: =+VLOOKUP(A5,'CUADRO 1-EJECUCION DE INGRESOS'!$A$12:$I$99,8,FALSE) -> 2.3861608e+12 | I5: =+H5-G5 -> 0
A6: 1-2-1-2 | B6: Compensación Regalías para el Régimen Subsidiado | C6: 0 | D6: 226673765000 | E6: 0 | F6: 100 | G6: 226673765000 | H6: =+VLOOKUP(A6,'CUADRO 1-EJECUCION DE INGRESOS'!$A$12:$I$99,8,FALSE) -> 226673765000 | I6: =+H6-G6 -> 0
A7: 1-2-1-3 | B7: Impuesto sobre la renta para la equidad CREE | C7: 0 | D7: 0 | E7: 0 | F7: 0 | G7: 0 | H7: =+VLOOKUP(A7,'CUADRO 1-EJECUCION DE INGRESOS'!$A$12:$I$99,8,FALSE) -> 0 | I7: =+H7-G7 -> 0
A8: 1-2-1-4 | B8: SGP FONSAET | C8: 0 | D8: 95551523562 | E8: 0 | F8: 0 | G8: 0 | H8: =+VLOOKUP(A8,'CUADRO 1-EJECUCION DE INGRESOS'!$A$12:$I$99,8,FALSE) -> 0 | I8: =+H8-G8 -> 0
A9: 1-2-1-5 | B9: PRIMA FONSAT Y CONTRIBUCION SOAT | C9: 0 | D9: 1640527441000 | E9: 111862061274 | F9: 54.75 | G9: 8.9814347e+11 | H9: =+VLOOKUP(A9,'CUADRO 1-EJECUCION DE INGRESOS'!$A$12:$I$99,8,FALSE) -> 8.9814347e+11 | I9: =+H9-G9 -> 0
A10: 1-2-1-5-01 | B10: % Prima (FONSAT) Decreto Ley 1335 de 2009 | C10: 0 | D10: 363281118360 | E10: 0 | F10: 54.36 | G10: 1.9749469e+11 | H10: =+VLOOKUP(A10,'CUADRO 1-EJECUCION DE INGRESOS'!$A$12:$I$99,8,FALSE) -> 1.9749469e+11 | I10: =+H10-G10 -> 0
A11: 1-2-1-5-02 | B11: Contribución Seguro Obligatorio de Accidentes de Tránsito - SOAT- Decreto Ley 1335 de 2009 | C11: 0 | D11: 1277246322640 | E11: 111862061274 | F11: 54.86 | G11: 7.0064878e+11 | H11: =+VLOOKUP(A11,'CUADRO 1-EJECUCION DE INGRESOS'!$A$12:$I$99,8,FALSE) -> 7.0064878e+11 | I11: =+H11-G11 -> 0
A12: 1-2-1-7 | B12: Impuesto social a las municiones y explosivos | C12: 0 | D12: 6410791000 | E12: 14354115977 | F12: 922.91 | G12: 59165621680 | H12: =+VLOOKUP(A12,'CUADRO 1-EJECUCION DE INGRESOS'!$A$12:$I$99,8,FALSE) -> 59165621680 | I12: =+H12-G12 -> 0
A13: 1-2-1-8 | B13: Impuesto social a las armas | C13: 0 | D13: 8851770619 | E13: 1000447745 | F13: 54.72 | G13: 4843738392 | H13: =+VLOOKUP(A13,'CUADRO 1-EJECUCION DE INGRESOS'!$A$12:$I$99,8,FALSE) -> 4843738392 | I13: =+H13-G13 -> 0
... A82: 2-9-0-0-02 | B82: Otros Recursos de Capital no contemplados en los anteriores | C82: 0 | D82: 0 | E82: 0 | F82: 0 | G82: 9872709.1 | H82: =+VLOOKUP(A82,'CUADRO 1-EJECUCION DE INGRESOS'!$A$12:$I$99,8,FALSE) -> 9872709.1 | I82: =+H82-G82 -> 0

Sheet CUADRO 2-EJECUCION DE GASTOS
M1: =+TODAY() -> 43676 | N1: =+NOW() -> 43676.359
A3: ADMINISTRADORA DE LOS RECURSOS DEL SISTEMA GENERAL DE SEGURIDAD SOCIAL EN SALUD
A4: UNIDAD DE RECURSOS ADMINISTRADOS - URA
A5: CODIGO DE LA EMPRESA 12902 - ADMINISTRACION DE RECURSOS DEL SGSSS
A6: PRESUPUESTO DE GASTOS JUNIO DE 2019
A7: CUADRO No. 2
A10: CÓDIGO RUBRO | B10: CONCEPTO DEL RUBRO | C10: APROPIACIÓN DEFINITIVA | D10: EJECUCION PRESUPUESTAL ACUMULADA DESDE 01/01/2019 HASTA 31/05/2019 | G10: EJECUCION PRESUPUESTAL DESDE 01/06/2019 HASTA 30/06/2019 | J10: EJECUCION PRESUPUESTAL ACUMULADA DESDE 01/01/2019 HASTA 30/06/2019 | M10: %
D11: T. CDP | E11: T. RP | F11: T. PAGOS-OG | G11: CDP | H11: RP | I11: PAGOS-OG | J11: T. CDP | K11: T. RP | L11: T. PAGOS-OG | M11: RP | N11: OG
B12: URA
A13: A-3-0-0-0 | B13: TRANSFERENCIAS | C13: =+C14+C19+C25 -> 52870917903513 | D13: 3.2327818e+13 | E13: 2.0416053e+13 | F13: 2.0416053e+13 | G13: =+G14+G19+G25 -> 1.1969033e+13 | H13: =+H14+H19+H25 -> 4.260865e+12 | I13: =+I14+I19+I25 -> 4.260865e+12 | J13: =+G13+D13 -> 4.4296851e+13 | K13: =+H13+E13 -> 2.4676918e+13 | L13: =+I13+F13 -> 2.4676918e+13 | M13: =+IFERROR(K13*100/C13,0) -> 46.673897 | N13: =+IFERROR(L13*100/C13,0) -> 46.673897
A14: A-3-2-0-0 | B14: TRANSFERENCIAS AL SECTOR PUBLICO | C14: =+C15+C17 -> 231725030430 | D14: 228185519661 | E14: 5.0402254e+10 | F14: 5.0402254e+10 | G14: =+G15+G17 -> 0 | H14: =+H15+H17 -> 1.0967286e+10 | I14: =+I15+I17 -> 1.0967286e+10 | J14: =+G14+D14 -> 228185519661 | K14: =+H14+E14 -> 6.136954e+10 | L14: =+I14+F14 -> 6.136954e+10 | M14: =+IFERROR(K14*100/C14,0) -> 26.483777 | N14: =+IFERROR(L14*100/C14,0) -> 26.483777
A15: A-3-2-1-0 | B15: =+VLOOKUP(A15,gasto!$A$4:$B$78,2,FALSE) -> Transferencias Entidades de Administración Pública Central | C15: =+C16 -> 86345030430 | D15: 82805519661 | E15: 3.4440853e+10 | F15: 3.4440853e+10 | G15: =+G16 -> 0 | H15: =+H16 -> 6.8799777e+09 | I15: =+I16 -> 6.8799777e+09 | J15: =+J16 -> 82805519661 | K15: =+K16 -> 4.1320831e+10 | L15: =+L16 -> 4.1320831e+10 | M15: =+IFERROR(K15*100/C15,0) -> 47.855482 | N15: =+IFERROR(L15*100/C15,0) -> 47.855482
A16: A-3-2-1-01 | B16: =+VLOOKUP(A16,gasto!$A$4:$B$78,2,FALSE) -> Contribución IVC Superintendencia Nacional de Salud | C16: =+VLOOKUP(A16,gasto!$A$4:$F$68,3,FALSE) -> 86345030430 | D16: 82805519661 | E16: 3.4440853e+10 | F16: 3.4440853e+10 | G16: =+VLOOKUP(A16,gasto!$A$4:$F$68,4,FALSE) -> 0 | H16: =+VLOOKUP(A16,gasto!$A$4:$F$68,5,FALSE) -> 6.8799777e+09 | I16: =+VLOOKUP(A16,gasto!$A$4:$F$68,6,FALSE) -> 6.8799777e+09 | J16: =+G16+D16 -> 82805519661 | K16: =+H16+E16 -> 4.1320831e+10 | L16: =+I16+F16 -> 4.1320831e+10 | M16: =+IFERROR(K16*100/C16,0) -> 47.855482 | N16: =+IFERROR(L16*100/C16,0) -> 47.855482
A17: A-3-2-2-0 | B17: =+VLOOKUP(A17,gasto!$A$4:$B$78,2,FALSE) -> Empresas Públicas Nacionales no financieras -ADRES | C17: =+C18 -> 145380000000 | D17: 145380000000 | E17: 1.5961401e+10 | F17: 1.5961401e+10 | G17: =+G18 -> 0 | H17: =+H18 -> 4.0873081e+09 | I17: =+I18 -> 4.0873081e+09 | J17: =+J18 -> 145380000000 | K17: =+K18 -> 20048709556 | L17: =+L18 -> 20048709556 | M17: =+IFERROR(K17*100/C17,0) -> 13.790555 | N17: =+IFERROR(L17*100/C17,0) -> 13.790555
A18: A-3-2-2-0-01 | B18: =+VLOOKUP(A18,gasto!$A$4:$B$78,2,FALSE) -> Aportes hasta del 0,5% recursos CSF para el desarrollo objeto ADRES | C18: =+VLOOKUP(A18,gasto!$A$4:$F$68,3,FALSE) -> 145380000000 | D18: 145380000000 | E18: 1.5961401e+10 | F18: 1.5961401e+10 | G18: =+VLOOKUP(A18,gasto!$A$4:$F$68,4,FALSE) -> 0 | H18: =+VLOOKUP(A18,gasto!$A$4:$F$68,5,FALSE) -> 4.0873081e+09 | I18: =+VLOOKUP(A18,gasto!$A$4:$F$68,6,FALSE) -> 4.0873081e+09 | J18: =+G18+D18 -> 145380000000 | K18: =+H18+E18 -> 20048709556 | L18: =+I18+F18 -> 20048709556 | M18: =+IFERROR(K18*100/C18,0) -> 13.790555 | N18: =+IFERROR(L18*100/C18,0) -> 13.790555
A19: A-3-6-0-0 | B19: OTRAS TRANSFERENCIAS | C19: =+C20+C23 -> 154000000000 | D19: 1.4869192e+09 | E19: 1.3283279e+09 | F19: 1.3283279e+09 | G19: =+G20+G23 -> 2.722844e+08 | H19: =+H20+H23 -> 2.722844e+08 | I19: =+I20+I23 -> 2.722844e+08 | J19: =+G19+D19 -> 1.7592036e+09 | K19: =+H19+E19 -> 1.6006123e+09 | L19: =+I19+F19 -> 1.6006123e+09 | M19: =+IFERROR(K19*100/C19,0) -> 1.0393586 | N19: =+IFERROR(L19*100/C19,0) -> 1.0393586
A20: A-3-6-1-0 | B20: =+VLOOKUP(A20,gasto!$A$4:$B$78,2,FALSE) -> Sentencias y Conciliaciones URA | C20: =+SUM(C21:C22) -> 20000000000 | D20: 1.4869192e+09 | E20: 1.3283279e+09 | F20: 1.3283279e+09 | G20: =+SUM(G21:G22) -> 2.722844e+08 | H20: =+SUM(H21:H22) -> 2.722844e+08 | I20: =+SUM(I21:I22) -> 2.722844e+08 | J20: =+SUM(J21:J22) -> 1.7592036e+09 | K20: =+SUM(K21:K22) -> 1.6006123e+09 | L20: =+SUM(L21:L22) -> 1.6006123e+09 | M20: =+IFERROR(K20*100/C20,0) -> 8.0030615 | N20: =+IFERROR(L20*100/C20,0) -> 8.0030615
A21: A-3-6-1-1 | B21: =+VLOOKUP(A21,gasto!$A$4:$B$78,2,FALSE) -> Sentencias URA | C21: =+VLOOKUP(A21,gasto!$A$4:$F$68,3,FALSE) -> 20000000000 | D21: 1.4869192e+09 | E21: 1.3283279e+09 | F21: 1.3283279e+09 | G21: =+VLOOKUP(A21,gasto!$A$4:$F$68,4,FALSE) -> 2.722844e+08 | H21: =+VLOOKUP(A21,gasto!$A$4:$F$68,5,FALSE) -> 2.722844e+08 | I21: =+VLOOKUP(A21,gasto!$A$4:$F$68,6,FALSE) -> 2.722844e+08 | J21: =+G21+D21 -> 1.7592036e+09 | K21: =+H21+E21 -> 1.6006123e+09 | L21: =+I21+F21 -> 1.6006123e+09 | M21: =+IFERROR(K21*100/C21,0) -> 8.0030615 | N21: =+IFERROR(L21*100/C21,0) -> 8.0030615
A22: A-3-6-1-2 | B22: =+VLOOKUP(A22,gasto!$A$4:$B$78,2,FALSE) -> Conciliaciones URA | C22: =+VLOOKUP(A22,gasto!$A$4:$F$68,3,FALSE) -> 0 | D22: 0 | E22: 0 | F22: 0 | G22: =+VLOOKUP(A22,gasto!$A$4:$F$68,4,FALSE) -> 0 | H22: =+VLOOKUP(A22,gasto!$A$4:$F$68,5,FALSE) -> 0 | I22: =+VLOOKUP(A22,gasto!$A$4:$F$68,6,FALSE) -> 0 | J22: =+G22+D22 -> 0 | K22: =+H22+E22 -> 0 | L22: =+I22+F22 -> 0 | M22: =+IFERROR(K22*100/C22,0) -> 0 | N22: =+IFERROR(L22*100/C22,0) -> 0
A23: A-3-6-3-0 | B23: =+VLOOKUP(A23,gasto!$A$4:$B$78,2,FALSE) -> Destinatarios de otras transferencias Corrientes - Compensación Chance | C23: =+C24 -> 134000000000 | D23: 0 | E23: 0 | F23: 0 | G23: =+G24 -> 0 | H23: =+H24 -> 0 | I23: =+I24 -> 0 | J23: =+J24 -> 0 | K23: =+K24 -> 0 | L23: =+L24 -> 0 | M23: =+IFERROR(K23*100/C23,0) -> 0 | N23: =+IFERROR(L23*100/C23,0) -> 0
A24: A-3-6-3-0-01 | B24: =+VLOOKUP(A24,gasto!$A$4:$B$78,2,FALSE) -> Otras transferencias - Compensación del Chance Decreto 2550/12 | C24: =+VLOOKUP(A24,gasto!$A$4:$F$68,3,FALSE) -> 134000000000 | D24: 0 | E24: 0 | F24: 0 | G24: =+VLOOKUP(A24,gasto!$A$4:$F$68,4,FALSE) -> 0 | H24: =+VLOOKUP(A24,gasto!$A$4:$F$68,5,FALSE) -> 0 | I24: =+VLOOKUP(A24,gasto!$A$4:$F$68,6,FALSE) -> 0 | J24: =+G24+D24 -> 0 | K24: =+H24+E24 -> 0 | L24: =+I24+F24 -> 0 | M24: =+IFERROR(K24*100/C24,0) -> 0 | N24: =+IFERROR(L24*100/C24,0) -> 0
A25: A-3-9-0-0 | B25: ADMINISTRACIÓN DE RECURSOS DEL SGSSS | C25: =+C26+C31+C34+C37+C38+C39+C43+C46+C53+C57+C67+C78+C80+C82+C86 -> 52485192873083 | D25: 3.2098145e+13 | E25: 2.0364322e+13 | F25: 2.0364322e+13 | G25: =+G26+G31+G34+G37+G38+G39+G43+G46+G53+G57+G67+G78+G80+G82+G86 -> 1.1968761e+13 | H25: =+H26+H31+H34+H37+H38+H39+H43+H46+H53+H57+H67+H78+H80+H82+H86 -> 4.2496254e+12 | I25: =+I26+I31+I34+I37+I38+I39+I43+I46+I53+I57+I67+I78+I80+I82+I86 -> 4.2496254e+12 | J25: =+J26+J31+J34+J37+J38+J39+J43+J46+J53+J57+J67+J78+J80+J82+J86 -> 4.4066906e+13 | K25: =+K26+K31+K34+K37+K38+K39+K43+K46+K53+K57+K67+K78+K80+K82+K86 -> 2.4613948e+13 | L25: =+L26+L31+L34+L37+L38+L39+L43+L46+L53+L57+L67+L78+L80+L82+L86 -> 2.4613948e+13 | M25: =+IFERROR(K25*100/C25,0) -> 46.896936 | N25: =+IFERROR(L25*100/C25,0) -> 46.896936
A26: A-3-9-1-0 | B26: =+VLOOKUP(A26,gasto!$A$4:$B$78,2,FALSE) -> UPC Régimen Contributivo | C26: =+SUM(C27:C30) -> 23048224384378 | D26: 1.9520467e+13 | E26: 9172910812472 | F26: 9172910812472 | G26: =+SUM(G27:G30) -> -1124078341 | H26: =+SUM(H27:H30) -> 1797826867199 | I26: =+SUM(I27:I30) -> 1797826867199 | J26: =+SUM(J27:J30) -> 1.9519343e+13 | K26: =+SUM(K27:K30) -> 10970737679671 | L26: =+SUM(L27:L30) -> 10970737679671 | M26: =+IFERROR(K26*100/C26,0) -> 47.599058 | N26: =+IFERROR(L26*100/C26,0) -> 47.599058
A27: A-3-9-1-0-01 | B27: =+VLOOKUP(A27,gasto!$A$4:$B$78,2,FALSE) -> UPC Régimen Contributivo SSF | C27: =+VLOOKUP(A27,gasto!$A$4:$F$68,3,FALSE) -> 12399109660289 | D27: 1.0510693e+13 | E27: 4993045161610 | F27: 4993045161610 | G27: =+VLOOKUP(A27,gasto!$A$4:$F$68,4,FALSE) -> -1124078341 | H27: =+VLOOKUP(A27,gasto!$A$4:$F$68,5,FALSE) -> 1013005546507 | I27: =+VLOOKUP(A27,gasto!$A$4:$F$68,6,FALSE) -> 1013005546507 | J27: =+G27+D27 -> 1.0509568e+13 | K27: =+H27+E27 -> 6006050708117 | L27: =+I27+F27 -> 6006050708117 | M27: =+IFERROR(K27*100/C27,0) -> 48.439371 | N27: =+IFERROR(L27*100/C27,0) -> 48.439371
A28: A-3-9-1-0-02 | B28: =+VLOOKUP(A28,gasto!$A$4:$B$78,2,FALSE) -> UPC Régimen Contributivo CSF | C28: =+VLOOKUP(A28,gasto!$A$4:$F$68,3,FALSE) -> 10647939289644 | D28: 9008599217429 | E28: 4178690216417 | F28: 4178690216417 | G28: =+VLOOKUP(A28,gasto!$A$4:$F$68,4,FALSE) -> 0 | H28: =+VLOOKUP(A28,gasto!$A$4:$F$68,5,FALSE) -> 784821320692 | I28: =+VLOOKUP(A28,gasto!$A$4:$F$68,6,FALSE) -> 784821320692 | J28: =+G28+D28 -> 9008599217429 | K28: =+H28+E28 -> 4963511537109 | L28: =+I28+F28 -> 4963511537109 | M28: =+IFERROR(K28*100/C28,0) -> 46.614762 | N28: =+IFERROR(L28*100/C28,0) -> 46.614762
A29: A-3-9-1-0-03 | B29: =+VLOOKUP(A29,gasto!$A$4:$B$78,2,FALSE) -> Devolución aportes y cotizaciones no conciliadas vigencia anterior | C29: =+VLOOKUP(A29,gasto!$A$4:$F$68,3,FALSE) -> 1175434445 | D29: 1175434445 | E29: 1175434445 | F29: 1175434445 | G29: =+VLOOKUP(A29,gasto!$A$4:$F$68,4,FALSE) -> 0 | H29: =+VLOOKUP(A29,gasto!$A$4:$F$68,5,FALSE) -> 0 | I29: =+VLOOKUP(A29,gasto!$A$4:$F$68,6,FALSE) -> 0 | J29: =+G29+D29 -> 1175434445 | K29: =+H29+E29 -> 1175434445 | L29: =+I29+F29 -> 1175434445 | M29: =+IFERROR(K29*100/C29,0) -> 100 | N29: =+IFERROR(L29*100/C29,0) -> 100
A30: A-3-9-1-0-04 | B30: =+VLOOKUP(A30,gasto!$A$4:$B$78,2,FALSE) -> Rendimientos Financieros de los Saldos no Compensados de los Aportes Patronales según Art. 12 Decreto 1636 de 2016 | C30: =+VLOOKUP(A30,gasto!$A$4:$F$68,3,FALSE) -> 0 | D30: 0 | E30: 0 | F30: 0 | G30: =+VLOOKUP(A30,gasto!$A$4:$F$68,4,FALSE) -> 0 | H30: =+VLOOKUP(A30,gasto!$A$4:$F$68,5,FALSE) -> 0 | I30: =+VLOOKUP(A30,gasto!$A$4:$F$68,6,FALSE) -> 0 | J30: =+G30+D30 -> 0 | K30: =+H30+E30 -> 0 | L30: =+I30+F30 -> 0 | M30: =+IFERROR(K30*100/C30,0) -> 0 | N30: =+IFERROR(L30*100/C30,0) -> 0
A31: A-3-9-2-0 | B31: =+VLOOKUP(A31,gasto!$A$4:$B$78,2,FALSE) -> Per capita Programas de Promoción y Prevención R.C | C31: =+SUM(C32:C33) -> 646778600953 | D31: 5.4189833e+11 | E31: 208386452767 | F31: 208386452767 | G31: =+SUM(G32:G33) -> -33698721 | H31: =+SUM(H32:H33) -> 40512450447 | I31: =+SUM(I32:I33) -> 40512450447 | J31: =+SUM(J32:J33) -> 5.4186464e+11 | K31: =+SUM(K32:K33) -> 248898903214 | L31: =+SUM(L32:L33) -> 248898903214 | M31: =+IFERROR(K31*100/C31,0) -> 38.48286 | N31: =+IFERROR(L31*100/C31,0) -> 38.48286
A32: A-3-9-2-0-01 | B32: =+VLOOKUP(A32,gasto!$A$4:$B$78,2,FALSE) -> Per capita Programas de Promoción y Prevención R.C SSF | C32: =+VLOOKUP(A32,gasto!$A$4:$F$68,3,FALSE) -> 510526042986 | D32: 4.2815967e+11 | E32: 165955167375 | F32: 165955167375 | G32: =+VLOOKUP(A32,gasto!$A$4:$F$68,4,FALSE) -> -33698721 | H32: =+VLOOKUP(A32,gasto!$A$4:$F$68,5,FALSE) -> 33181647751 | I32: =+VLOOKUP(A32,gasto!$A$4:$F$68,6,FALSE) -> 33181647751 | J32: =+G32+D32 -> 4.2812597e+11 | K32: =+H32+E32 -> 199136815126 | L32: =+I32+F32 -> 199136815126 | M32: =+IFERROR(K32*100/C32,0) -> 39.006201 | N32: =+IFERROR(L32*100/C32,0) -> 39.006201
A33: A-3-9-2-0-02 | B33: =+VLOOKUP(A33,gasto!$A$4:$B$78,2,FALSE) -> Per capita Programas de Promoción y Prevención R.C CSF | C33: =+VLOOKUP(A33,gasto!$A$4:$F$68,3,FALSE) -> 136252557967 | D33: 1.1373866e+11 | E33: 42431285392 | F33: 42431285392 | G33: =+VLOOKUP(A33,gasto!$A$4:$F$68,4,FALSE) -> 0 | H33: =+VLOOKUP(A33,gasto!$A$4:$F$68,5,FALSE) -> 7330802696 | I33: =+VLOOKUP(A33,gasto!$A$4:$F$68,6,FALSE) -> 7330802696 | J33: =+G33+D33 -> 1.1373866e+11 | K33: =+H33+E33 -> 49762088088 | L33: =+I33+F33 -> 49762088088 | M33: =+IFERROR(K33*100/C33,0) -> 36.521948 | N33: =+IFERROR(L33*100/C33,0) -> 36.521948
A34: A-3-9-3-0 | B34: =+VLOOKUP(A34,gasto!$A$4:$B$78,2,FALSE) -> Incapacidades | C34: =+SUM(C35:C36) -> 814461941941 | D34: 6.9109461e+11 | E34: 333215276968 | F34: 333215276968 | G34: =+SUM(G35:G36) -> -9930353 | H34: =+SUM(H35:H36) -> 65375823281 | I34: =+SUM(I35:I36) -> 65375823281 | J34: =+SUM(J35:J36) -> 6.9108468e+11 | K34: =+SUM(K35:K36) -> 398591100249 | L34: =+SUM(L35:L36) -> 398591100249 | M34: =+IFERROR(K34*100/C34,0) -> 48.939193 | N34: =+IFERROR(L34*100/C34,0) -> 48.939193
A35: A-3-9-3-0-01 | B35: =+VLOOKUP(A35,gasto!$A$4:$B$78,2,FALSE) -> Incapacidades SSF | C35: =+VLOOKUP(A35,gasto!$A$4:$F$68,3,FALSE) -> 629253806467 | D35: 5.3437909e+11 | E35: 261734550968 | F35: 261734550968 | G35: =+VLOOKUP(A35,gasto!$A$4:$F$68,4,FALSE) -> -9930353 | H35: =+VLOOKUP(A35,gasto!$A$4:$F$68,5,FALSE) -> 53081478779 | I35: =+VLOOKUP(A35,gasto!$A$4:$F$68,6,FALSE) -> 53081478779 | J35: =+G35+D35 -> 5.3436916e+11 | K35: =+H35+E35 -> 314816029747 | L35: =+I35+F35 -> 314816029747 | M35: =+IFERROR(K35*100/C35,0) -> 50.030056 | N35: =+IFERROR(L35*100/C35,0) -> 50.030056
A36: A-3-9-3-0-02 | B36: =+VLOOKUP(A36,gasto!$A$4:$B$78,2,FALSE) -> Incapacidades CSF | C36: =+VLOOKUP(A36,gasto!$A$4:$F$68,3,FALSE) -> 185208135474 | D36: 156715520546 | E36: 71480726000 | F36: 71480726000 | G36: =+VLOOKUP(A36,gasto!$A$4:$F$68,4,FALSE) -> 0 | H36: =+VLOOKUP(A36,gasto!$A$4:$F$68,5,FALSE) -> 12294344502 | I36: =+VLOOKUP(A36,gasto!$A$4:$F$68,6,FALSE) -> 12294344502 | J36: =+G36+D36 -> 156715520546 | K36: =+H36+E36 -> 83775070502 | L36: =+I36+F36 -> 83775070502 | M36: =+IFERROR(K36*100/C36,0) -> 45.232932 | N36: =+IFERROR(L36*100/C36,0) -> 45.232932
A37: A-3-9-4-0 | B37: =+VLOOKUP(A37,gasto!$A$4:$B$78,2,FALSE) -> Licencias de Maternidad y Paternidad | C37: =+VLOOKUP(A37,gasto!$A$4:$F$68,3,FALSE) -> 838554045453 | D37: 838554045453 | E37: 329689815814 | F37: 329689815814 | G37: =+VLOOKUP(A37,gasto!$A$4:$F$68,4,FALSE) -> 0 | H37: =+VLOOKUP(A37,gasto!$A$4:$F$68,5,FALSE) -> 59962441810 | I37: =+VLOOKUP(A37,gasto!$A$4:$F$68,6,FALSE) -> 59962441810 | J37: =+G37+D37 -> 838554045453 | K37: =+H37+E37 -> 389652257624 | L37: =+I37+F37 -> 389652257624 | M37: =+IFERROR(K37*100/C37,0) -> 46.467161 | N37: =+IFERROR(L37*100/C37,0) -> 46.467161
A38: A-3-9-5-0 | B38: =+VLOOKUP(A38,gasto!$A$4:$B$78,2,FALSE) -> Prestaciones Económicas Regímenes Especial y de Excepción | C38: =+VLOOKUP(A38,gasto!$A$4:$F$68,3,FALSE) -> 3852227236 | D38: 3852227236 | E38: 1946536083 | F38: 1946536083 | G38: =+VLOOKUP(A38,gasto!$A$4:$F$68,4,FALSE) -> 0 | H38: =+VLOOKUP(A38,gasto!$A$4:$F$68,5,FALSE) -> 298726073 | I38: =+VLOOKUP(A38,gasto!$A$4:$F$68,6,FALSE) -> 298726073 | J38: =+G38+D38 -> 3852227236 | K38: =+H38+E38 -> 2245262156 | L38: =+I38+F38 -> 2245262156 | M38: =+IFERROR(K38*100/C38,0) -> 58.28478 | N38: =+IFERROR(L38*100/C38,0) -> 58.28478
A39: A-3-9-6-0 | B39: =+VLOOKUP(A39,gasto!$A$4:$B$78,2,FALSE) -> UPC Régimen Subsidiado | C39: =+SUM(C40:C42) -> 21586257607421 | D39: 8.9133482e+12 | E39: 8.9133482e+12 | F39: 8.9133482e+12 | G39: =+SUM(G40:G42) -> 1.1407097e+13 | H39: =+SUM(H40:H42) -> 1.8766695e+12 | I39: =+SUM(I40:I42) -> 1.8766695e+12 | J39: =+SUM(J40:J42) -> 2.0320446e+13 | K39: =+SUM(K40:K42) -> 1.0790018e+13 | L39: =+SUM(L40:L42) -> 1.0790018e+13 | M39: =+IFERROR(K39*100/C39,0) -> 49.985588 | N39: =+IFERROR(L39*100/C39,0) -> 49.985588
A40: A-3-9-6-0-01 | B40: =+VLOOKUP(A40,gasto!$A$4:$B$78,2,FALSE) -> UPC´S R.S. Cajas de Compensación Familiar SSF | C40: =+VLOOKUP(A40,gasto!$A$4:$F$68,3,FALSE) -> 28877831435 | D40: 1.4089319e+10 | E40: 1.4089319e+10 | F40: 1.4089319e+10 | G40: =+VLOOKUP(A40,gasto!$A$4:$F$68,4,FALSE) -> 1.4788513e+10 | H40: =+VLOOKUP(A40,gasto!$A$4:$F$68,5,FALSE) -> 2484211881 | I40: =+VLOOKUP(A40,gasto!$A$4:$F$68,6,FALSE) -> 2484211881 | J40: =+G40+D40 -> 28877831435 | K40: =+H40+E40 -> 1.657353e+10 | L40: =+I40+F40 -> 1.657353e+10 | M40: =+IFERROR(K40*100/C40,0) -> 57.39188 | N40: =+IFERROR(L40*100/C40,0) -> 57.39188
A41: A-3-9-6-0-02 | B41: =+VLOOKUP(A41,gasto!$A$4:$B$78,2,FALSE) -> UPC´S R.S. CSF | C41: =+VLOOKUP(A41,gasto!$A$4:$F$68,3,FALSE) -> 21557379775986 | D41: 8.8992589e+12 | E41: 8.8992589e+12 | F41: 8.8992589e+12 | G41: =+VLOOKUP(A41,gasto!$A$4:$F$68,4,FALSE) -> 1.1392309e+13 | H41: =+VLOOKUP(A41,gasto!$A$4:$F$68,5,FALSE) -> 1.8741853e+12 | I41: =+VLOOKUP(A41,gasto!$A$4:$F$68,6,FALSE) -> 1.8741853e+12 | J41: =+G41+D41 -> 2.0291568e+13 | K41: =+H41+E41 -> 1.0773444e+13 | L41: =+I41+F41 -> 1.0773444e+13 | M41: =+IFERROR(K41*100/C41,0) -> 49.975666 | N41: =+IFERROR(L41*100/C41,0) -> 49.975666
A42: A-3-9-6-0-03 | B42: =+VLOOKUP(A42,gasto!$A$4:$B$78,2,FALSE) -> UPC´S R.S. USPEC | C42: =+VLOOKUP(A42,gasto!$A$4:$F$68,3,FALSE) -> 0 | D42: 0 | E42: 0 | F42: 0 | G42: =+VLOOKUP(A42,gasto!$A$4:$F$68,4,FALSE) -> 0 | H42: =+VLOOKUP(A42,gasto!$A$4:$F$68,5,FALSE) -> 0 | I42: =+VLOOKUP(A42,gasto!$A$4:$F$68,6,FALSE) -> 0 | J42: =+G42+D42 -> 0 | K42: =+H42+E42 -> 0 | L42: =+I42+F42 -> 0 | M42: =+IFERROR(K42*100/C42,0) -> 0 | N42: =+IFERROR(L42*100/C42,0) -> 0
A43: A-3-9-7-0 | B43: =+VLOOKUP(A43,gasto!$A$4:$B$78,2,FALSE) -> Prestaciones Excepcionales - Recobros | C43: =+SUM(C44:C45) -> 4612854535766 | D43: 1.3910627e+12 | E43: 1.3910627e+12 | F43: 1.3910627e+12 | G43: =+SUM(G44:G45) -> 3.4256964e+11 | H43: =+SUM(H44:H45) -> 3.4256964e+11 | I43: =+SUM(I44:I45) -> 3.4256964e+11 | J43: =+SUM(J44:J45) -> 1.7336324e+12 | K43: =+SUM(K44:K45) -> 1.7336324e+12 | L43: =+SUM(L44:L45) -> 1.7336324e+12 | M43: =+IFERROR(K43*100/C43,0) -> 37.582637 | N43: =+IFERROR(L43*100/C43,0) -> 37.582637
...

Sheet gasto
D1: República de Colombia | E1: EJECUCIÓN DE EGRESOS ACUMULADOS | F1: ADRES ADMINISTRADORA DE LOS RECURSOS DEL SGSSS
A2: CÓDIGO RUBRO | B2: CONCEPTO DEL RUBRO | C2: APROPIACIÓN DEFINITIVA | D2: CDP | E2: RP | F2: PAGOS-OGAG | G2: T. CDP | H2: T. RP | I2: T. PAGOS-OGAG | J2: RP | K2: PAGOS
A3: URA
A4: A-3-2-1-0 | B4: Transferencias Entidades de Administración Pública Central | C4: 86345030430 | D4: 0 | E4: 6.8799777e+09 | F4: 6.8799777e+09 | G4: 82805519661 | H4: 4.1320831e+10 | I4: 4.1320831e+10 | J4: 47.86 | K4: 47.86
A5: A-3-2-1-01 | B5: Contribución IVC Superintendencia Nacional de Salud | C5: 86345030430 | D5: 0 | E5: 6.8799777e+09 | F5: 6.8799777e+09 | G5: 82805519661 | H5: 4.1320831e+10 | I5: 4.1320831e+10 | J5: 47.86 | K5: 47.86
A6: A-3-2-2-0 | B6: Empresas Públicas Nacionales no financieras -ADRES | C6: 145380000000 | D6: 0 | E6: 4.0873081e+09 | F6: 4.0873081e+09 | G6: 145380000000 | H6: 20048709556 | I6: 20048709556 | J6: 13.79 | K6: 13.79
A7: A-3-2-2-0-01 | B7: Aportes hasta del 0,5% recursos CSF para el desarrollo objeto ADRES | C7: 145380000000 | D7: 0 | E7: 4.0873081e+09 | F7: 4.0873081e+09 | G7: 145380000000 | H7: 20048709556 | I7: 20048709556 | J7: 13.79 | K7: 13.79
A8: A-3-6-1-0 | B8: Sentencias y Conciliaciones URA | C8: 20000000000 | D8: 2.722844e+08 | E8: 2.722844e+08 | F8: 2.722844e+08 | G8: 1.7592036e+09 | H8: 1.6006123e+09 | I8: 1.6006123e+09 | J8: 8 | K8: 8
A9: A-3-6-1-1 | B9: Sentencias URA | C9: 20000000000 | D9: 2.722844e+08 | E9: 2.722844e+08 | F9: 2.722844e+08 | G9: 1.7592036e+09 | H9: 1.6006123e+09 | I9: 1.6006123e+09 | J9: 8 | K9: 8
A10: A-3-6-1-2 | B10: Conciliaciones URA | C10: 0 | D10: 0 | E10: 0 | F10: 0 | G10: 0 | H10: 0 | I10: 0 | J10: 0 | K10: 0
A11: A-3-6-3-0 | B11: Destinatarios de otras transferencias Corrientes - Compensación Chance | C11: 134000000000 | D11: 0 | E11: 0 | F11: 0 | G11: 0 | H11: 0 | I11: 0 | J11: 0 | K11: 0
A12: A-3-6-3-0-01 | B12: Otras transferencias - Compensación del Chance Decreto 2550/12 | C12: 134000000000 | D12: 0 | E12: 0 | F12: 0 | G12: 0 | H12: 0 | I12: 0 | J12: 0 | K12: 0
A13: A-3-9-1-0 | B13: UPC Régimen Contributivo | C13: 23048224384378 | D13: -1124078341 | E13: 1797826867199 | F13: 1797826867199 | G13: 1.9519343e+13 | H13: 10970737679671 | I13: 10970737679671 | J13: 47.6 | K13: 47.6
A14: A-3-9-1-0-01 | B14: UPC Régimen Contributivo SSF | C14: 12399109660289 | D14: -1124078341 | E14: 1013005546507 | F14: 1013005546507 | G14: 1.0509568e+13 | H14: 6006050708117 | I14: 6006050708117 | J14: 48.44 | K14: 48.44
A15: A-3-9-1-0-02 | B15: UPC Régimen Contributivo CSF | C15: 10647939289644 | D15: 0 | E15: 784821320692 | F15: 784821320692 | G15: 9008599217429 | H15: 4963511537109 | I15: 4963511537109 | J15: 46.61 | K15: 46.61
... A72: A-3-9-14-0-03 | B72: Operaciones de Fortalecimiento Patrimonial - Bocas | C72: 0 | D72: 0 | E72: 0 | F72: 0 | G72: 0 | H72: 0 | I72: 0 | J72: 0 | K72: 0
A73: A-3-9-15-0 | B73: Devoluciones | C73: 179398901661 | D73: 160101188290 | E73: 139653536 | F73: 139653536 | G73: 1.6940048e+11 | H73: 6.3930188e+08 | I73: 6.3930188e+08 | J73: 0.36 | K73: 0.36 | L73: 0
A74: A-3-9-15-0-01 | B74: Devoluciones Aportes y Cotizaciones No Conciliadas Vigencia Anterior | C74: 9047713371 | D74: 0 | E74: 138475351 | F74: 138475351 | G74: 9047713371 | H74: 636542891 | I74: 636542891 | J74: 7.04 | K74: 7.04
A75: A-3-9-15-0-02 | B75: Devoluciones de Aportes de REX | C75: 250000000 | D75: 0 | E75: 1178185 | F75: 1178185 | G75: 250000000 | H75: 1178185 | I75: 1178185 | J75: 0.47 | K75: 0.47
A76: A-3-9-15-0-03 | B76: Devoluciones Recursos Entidades Territoriales | C76: 160101188290 | D76: 160101188290 | E76: 0 | F76: 0 | G76: 160101188290 | H76: 0 | I76: 0 | J76: 0 | K76: 0
A77: A-3-9-15-0-04 | B77: Otras Devoluciones | C77: 10000000000 | D77: 0 | E77: 0 | F77: 0 | G77: 1580799.9 | H77: 1580799.9 | I77: 1580799.9 | J77: 0.02 | K77: 0.02
A78: A-9-9-9-9 | B78: Disponibilidad Final | C78: 254007875000 | D78: 0 | E78: 0 | F78: 0 | G78: 0 | H78: 0 | I78: 0 | J78: 0 | K78: 0
F84: =+'CUADRO 2-EJECUCION DE GASTOS'!I95+gasto!F21 -> 65375823281
