Workbook
Name OLE_LINK1: 'CUADRO 2-EJECUCION DE GASTOS'!#REF!

Sheet CUADRO 1-EJECUCION DE INGRESOS
A3: ADMINISTRADORA DE LOS RECURSOS DEL SISTEMA GENERAL DE SEGURIDAD SOCIAL EN SALUD
A4: PRESUPUESTO DE INGRESOS 2018
A5: UNIDAD DE RECURSOS ADMINISTRADOS - URA
A6: CUADRO No. 1
A9: CÓDIGO RUBRO | B9: CONCEPTO DEL RUBRO | C9: AFORO INICIAL Resol. 083/18 | D9: MODIFICACIÓN PRESUPUESTAL | E9: AFORO DEFINITIVO | F9: Ingresos Acumulados Desde 01/01/2018 hasta 31/03/2018 | G9: Ingresos Desde 01/04/2018 hasta 30/04/2018 | H9: Ingresos Acumulados Desde 01/01/2018 hasta 30/04/2018 | I9: EJECUCIÓN ACUMULADA (%)
A10: URA
A11: 0-0-0-0 | B11: DISPONIBILIDAD INICIAL | C11: 169607387000 | D11: =+VLOOKUP(A11,ingresos!$A$1:$C$78,2,FALSE) -> 0 | E11: =+D11+C11 -> 169607387000 | F11: 169607387000 | G11: =+VLOOKUP(A11,ingresos!$A$1:$C$78,3,FALSE) -> 0 | H11: =+G11+F11 -> 169607387000 | I11: =+IFERROR(H11*100/E11,0) -> 100
A12: 1-0-0-0 | B12: INGRESOS CORRIENTES | C12: 42417328164000 | D12: =+D13+D27 -> 0 | E12: =+D12+C12 -> 42417328164000 | F12: 1.0528979e+13 | G12: =+G13+G27 -> 4.0525692e+12 | H12: =+G12+F12 -> 1.4581549e+13 | I12: =+IFERROR(H12*100/E12,0) -> 34.376396
A13: 1-2-0-0 | B13: Aportes e Impuestos | C13: 14223313699299 | D13: =+D14+D26 -> 0 | E13: =+D13+C13 -> 14223313699299 | F13: 3.5203638e+12 | G13: =+G14+G26 -> 1528408213809 | H13: =+G13+F13 -> 5.048772e+12 | I13: =+IFERROR(H13*100/E13,0) -> 35.496454
A14: 1-2-1-0 | B14: Aportes de la Nación | C14: 14223313699299 | D14: =+D15+D18+D19+D20+D21+D24+D25 -> 0 | E14: =+D14+C14 -> 14223313699299 | F14: 3.5203638e+12 | G14: =+G15+G18+G19+G20+G21+G25+G24+G26 -> 1528408213809 | H14: =+G14+F14 -> 5.048772e+12 | I14: =+IFERROR(H14*100/E14,0) -> 35.496454
A15: 1-2-1-1 | B15: Aportes de la Nación para el Aseguramiento en Salud | C15: 12188014480000 | D15: =+SUM(D16:D17) -> 0 | E15: =+D15+C15 -> 12188014480000 | F15: 3047003619999 | G15: =+SUM(G16:G17) -> 1099892790055 | H15: =+G15+F15 -> 4146896410054 | I15: =+IFERROR(H15*100/E15,0) -> 34.02438
A16: 1-2-1-1-01 | B16: Aportes de la Nación para el Aseguramiento en Salud Cierre | C16: 8190948984384 | D16: =+VLOOKUP(A16,ingresos!$A$1:$C$78,2,FALSE) -> 0 | E16: =+D16+C16 -> 8190948984384 | F16: 2047737246096 | G16: =+VLOOKUP(A16,ingresos!$A$1:$C$78,3,FALSE) -> 682579082032 | H16: =+G16+F16 -> 2730316328128 | I16: =+IFERROR(H16*100/E16,0) -> 33.333333
A17: 1-2-1-1-02 | B17: Imporenta | C17: 3997065495616 | D17: =+VLOOKUP(A17,ingresos!$A$1:$C$78,2,FALSE) -> 0 | E17: =+D17+C17 -> 3997065495616 | F17: 999266373903 | G17: =+VLOOKUP(A17,ingresos!$A$1:$C$78,3,FALSE) -> 417313708023 | H17: =+G17+F17 -> 1416580081926 | I17: =+IFERROR(H17*100/E17,0) -> 35.440502
A18: 1-2-1-2 | B18: Compensación Regalías para el Régimen Subsidiado | C18: 220071616000 | D18: =+VLOOKUP(A18,ingresos!$A$1:$C$78,2,FALSE) -> 0 | E18: =+D18+C18 -> 220071616000 | F18: 0 | G18: =+VLOOKUP(A18,ingresos!$A$1:$C$78,3,FALSE) -> 220071616000 | H18: =+G18+F18 -> 220071616000 | I18: =+IFERROR(H18*100/E18,0) -> 100
A19: 1-2-1-3 | B19: Impuesto sobre la renta para la equidad CREE | C19: 112615883615 | D19: =+VLOOKUP(A19,ingresos!$A$1:$C$78,2,FALSE) -> 0 | E19: =+D19+C19 -> 112615883615 | F19: 0 | G19: =+VLOOKUP(A19,ingresos!$A$1:$C$78,3,FALSE) -> 100000000000 | H19: =+G19+F19 -> 100000000000 | I19: =+IFERROR(H19*100/E19,0) -> 88.797421
A20: 1-2-1-4 | B20: SGP FONSAET | C20: 51737470684 | D20: =+VLOOKUP(A20,ingresos!$A$1:$C$78,2,FALSE) -> 0 | E20: =+D20+C20 -> 51737470684 | F20: 0 | G20: =+VLOOKUP(A20,ingresos!$A$1:$C$78,3,FALSE) -> 0 | H20: =+G20+F20 -> 0 | I20: =+IFERROR(H20*100/E20,0) -> 0
A21: 1-2-1-5 | B21: PRIMA FONSAT Y CONTRIBUCION SOAT | C21: 1548964470000 | D21: =+SUM(D22:D23) -> 0 | E21: =+D21+C21 -> 1548964470000 | F21: 4.5169164e+11 | G21: =+SUM(G22:G23) -> 101451107500 | H21: =+G21+F21 -> 5.5314274e+11 | I21: =+IFERROR(H21*100/E21,0) -> 35.710486
A22: 1-2-1-5-01 | B22: % Prima (FONSAT) Decreto Ley 1335 de 2009 | C22: 344521245760 | D22: =+VLOOKUP(A22,ingresos!$A$1:$C$78,2,FALSE) -> 0 | E22: =+D22+C22 -> 344521245760 | F22: 1.2060311e+11 | G22: =+VLOOKUP(A22,ingresos!$A$1:$C$78,3,FALSE) -> 0 | H22: =+G22+F22 -> 1.2060311e+11 | I22: =+IFERROR(H22*100/E22,0) -> 35.006002
A23: 1-2-1-5-02 | B23: Contribución Seguro Obligatorio de Accidentes de Tránsito - SOAT- Decreto Ley 1335 de 2009 | C23: 1204443224240 | D23: =+VLOOKUP(A23,ingresos!$A$1:$C$78,2,FALSE) -> 0 | E23: =+D23+C23 -> 1204443224240 | F23: 331088523900 | G23: =+VLOOKUP(A23,ingresos!$A$1:$C$78,3,FALSE) -> 101451107500 | H23: =+G23+F23 -> 432539631400 | I23: =+IFERROR(H23*100/E23,0) -> 35.911998
A24: 1-2-1-7 | B24: Impuesto social a las municiones y explosivos | C24: 93173435000 | D24: =+VLOOKUP(A24,ingresos!$A$1:$C$78,2,FALSE) -> 0 | E24: =+D24+C24 -> 93173435000 | F24: 20201799317 | G24: =+VLOOKUP(A24,ingresos!$A$1:$C$78,3,FALSE) -> 6087551728 | H24: =+G24+F24 -> 26289351045 | I24: =+IFERROR(H24*100/E24,0) -> 28.215501
A25: 1-2-1-8 | B25: Impuesto social a las armas | C25: 8736344000 | D25: =+VLOOKUP(A25,ingresos!$A$1:$C$78,2,FALSE) -> 0 | E25: =+D25+C25 -> 8736344000 | F25: 1466769608 | G25: =+VLOOKUP(A25,ingresos!$A$1:$C$78,3,FALSE) -> 905148526 | H25: =+G25+F25 -> 2371918134 | I25: =+IFERROR(H25*100/E25,0) -> 27.150008
A26: 1-2-9-0 | B26: Otros aportes e impuestos de la nación | C26: 0 | D26: =+VLOOKUP(A26,ingresos!$A$1:$C$78,2,FALSE) -> 0 | E26: =+D26+C26 -> 0 | F26: 0 | G26: =+VLOOKUP(A26,ingresos!$A$1:$C$78,3,FALSE) -> 0 | H26: =+G26+F26 -> 0 | I26: =+IFERROR(H26*100/E26,0) -> 0
A27: 1-3-0-0 | B27: Otros Ingresos Corrientes | C27: 28194014464701 | D27: =+D28 -> 0 | E27: =+D27+C27 -> 28194014464701 | F27: 7.0086157e+12 | G27: =+G28+G56 -> 2.5241609e+12 | H27: =+G27+F27 -> 9.5327766e+12 | I27: =+IFERROR(H27*100/E27,0) -> 33.811349
A28: 1-3-5-0 | B28: Ingresos Sistema General de Seguridad Social en Salud | C28: 19251927507271 | D28: =+D29+D32+D35+D40+D50+D53 -> 0 | E28: =+D28+C28 -> 19251927507271 | F28: 5.0003375e+12 | G28: =+G29+G32+G35+G40+G50+G53 -> 1.8883393e+12 | H28: =+G28+F28 -> 6.8886768e+12 | I28: =+IFERROR(H28*100/E28,0) -> 35.781751
A29: 1-3-5-1 | B29: Cotizaciones al SGSSS | C29: 17803406036000 | D29: =+SUM(D30:D31) -> 0 | E29: =+D29+C29 -> 17803406036000 | F29: 4461821116988 | G29: =+SUM(G30:G31) -> 1697536849189 | H29: =+G29+F29 -> 6159357966177 | I29: =+IFERROR(H29*100/E29,0) -> 34.596515
A30: 1-3-5-1-01 | B30: Régimen Contributivo CSF | C30: 4777288159000 | D30: =+VLOOKUP(A30,ingresos!$A$1:$C$78,2,FALSE) -> 0 | E30: =+D30+C30 -> 4777288159000 | F30: 1577265182506 | G30: =+VLOOKUP(A30,ingresos!$A$1:$C$78,3,FALSE) -> 621336914647 | H30: =+G30+F30 -> 2198602097153 | I30: =+IFERROR(H30*100/E30,0) -> 46.021969
A31: 1-3-5-1-02 | B31: Régimen Contributivo SSF | C31: 13026117877000 | D31: =+VLOOKUP(A31,ingresos!$A$1:$C$78,2,FALSE) -> 0 | E31: =+D31+C31 -> 13026117877000 | F31: 2884555934482 | G31: =+VLOOKUP(A31,ingresos!$A$1:$C$78,3,FALSE) -> 1076199934542 | H31: =+G31+F31 -> 3960755869024 | I31: =+IFERROR(H31*100/E31,0) -> 30.406265
A32: 1-3-5-2 | B32: Aporte Solidaridad de Regímenes de Excepcion y Especiales | C32: 880078202271 | D32: =+SUM(D33:D34) -> 0 | E32: =+D32+C32 -> 880078202271 | F32: 1.9499165e+11 | G32: =+SUM(G33:G34) -> 7.3619476e+10 | H32: =+G32+F32 -> 2.6861112e+11 | I32: =+IFERROR(H32*100/E32,0) -> 30.521279
A33: 1-3-5-2-01 | B33: Cotizaciones afiliados REX con ingresos adicionales | C33: 440039101136 | D33: =+VLOOKUP(A33,ingresos!$A$1:$C$78,2,FALSE) -> 0 | E33: =+D33+C33 -> 440039101136 | F33: 120577454121 | G33: =+VLOOKUP(A33,ingresos!$A$1:$C$78,3,FALSE) -> 41225479079 | H33: =+G33+F33 -> 161802933200 | I33: =+IFERROR(H33*100/E33,0) -> 36.770126
A34: 1-3-5-2-02 | B34: Aporte Solidario entidades REX | C34: 440039101135 | D34: =+VLOOKUP(A34,ingresos!$A$1:$C$78,2,FALSE) -> 0 | E34: =+D34+C34 -> 440039101135 | F34: 7.4414193e+10 | G34: =+VLOOKUP(A34,ingresos!$A$1:$C$78,3,FALSE) -> 3.2393997e+10 | H34: =+G34+F34 -> 1.0680819e+11 | I34: =+IFERROR(H34*100/E34,0) -> 24.272432
A35: 1-3-5-3 | B35: Aportes Cajas de Compensación Familiar | C35: 566983320000 | D35: =+SUM(D36:D39) -> 0 | E35: =+D35+C35 -> 566983320000 | F35: 1.2205308e+11 | G35: =+SUM(G36:G39) -> 3.8891546e+10 | H35: =+G35+F35 -> 1.6094463e+11 | I35: =+IFERROR(H35*100/E35,0) -> 28.386131
A36: 1-3-5-3-01 | B36: Aportes CCF Artículo 217 Ley 100 de 1993 CSF | C36: 540507991000 | D36: =+VLOOKUP(A36,ingresos!$A$1:$C$78,2,FALSE) -> 0 | E36: =+D36+C36 -> 540507991000 | F36: 1.1196682e+11 | G36: =+VLOOKUP(A36,ingresos!$A$1:$C$78,3,FALSE) -> 3.674109e+10 | H36: =+G36+F36 -> 1.4870791e+11 | I36: =+IFERROR(H36*100/E36,0) -> 27.512621
A37: 1-3-5-3-02 | B37: Aportes CCF Artículo 217 Ley 100 de 1993 SSF | C37: 26475329000 | D37: =+VLOOKUP(A37,ingresos!$A$1:$C$78,2,FALSE) -> 0 | E37: =+D37+C37 -> 26475329000 | F37: 6451366893 | G37: =+VLOOKUP(A37,ingresos!$A$1:$C$78,3,FALSE) -> 2150455631 | H37: =+G37+F37 -> 8601822524 | I37: =+IFERROR(H37*100/E37,0) -> 32.489955
A38: 1-3-5-3-03 | B38: Aportes CCF Balance | C38: 0 | D38: =+VLOOKUP(A38,ingresos!$A$1:$C$78,2,FALSE) -> 0 | E38: =+D38+C38 -> 0 | F38: 3634891107 | G38: =+VLOOKUP(A38,ingresos!$A$1:$C$78,3,FALSE) -> 0 | H38: =+G38+F38 -> 3634891107 | I38: =+IFERROR(H38*100/E38,0) -> 0
A39: 1-3-5-3-04 | B39: Otros Aportes CCF | C39: 0 | D39: =+VLOOKUP(A39,ingresos!$A$1:$C$78,2,FALSE) -> 0 | E39: =+D39+C39 -> 0 | F39: 0 | G39: =+VLOOKUP(A39,ingresos!$A$1:$C$78,3,FALSE) -> 0 | H39: =+G39+F39 -> 0 | I39: =+IFERROR(H39*100/E39,0) -> 0
A40: 1-3-5-5 | B40: Reintegros / Recuperaciones | C40: 0 | D40: =+SUM(D41:D49) -> 0 | E40: =+D40+C40 -> 0 | F40: 1.6300235e+11 | G40: =+SUM(G41:G49) -> 6.0066611e+10 | H40: =+G40+F40 -> 223068965128 | I40: =+IFERROR(H40*100/E40,0) -> 0
A41: 1-3-5-5-01 | B41: UPC Régimen Contributivo Vigencias anteriores | C41: 0 | D41: =+VLOOKUP(A41,ingresos!$A$1:$C$78,2,FALSE) -> 0 | E41: =+D41+C41 -> 0 | F41: 1532316394 | G41: =+VLOOKUP(A41,ingresos!$A$1:$C$78,3,FALSE) -> 5.1941559e+08 | H41: =+G41+F41 -> 2.051732e+09 | I41: =+IFERROR(H41*100/E41,0) -> 0
A42: 1-3-5-5-02 | B42: P&P Vigencias anteriores | C42: 0 | D42: =+VLOOKUP(A42,ingresos!$A$1:$C$78,2,FALSE) -> 0 | E42: =+D42+C42 -> 0 | F42: 0 | G42: =+VLOOKUP(A42,ingresos!$A$1:$C$78,3,FALSE) -> 0 | H42: =+G42+F42 -> 0 | I42: =+IFERROR(H42*100/E42,0) -> 0
A43: 1-3-5-5-03 | B43: Licencias de Maternidad y Paternidad Vigencias anteriores | C43: 0 | D43: =+VLOOKUP(A43,ingresos!$A$1:$C$78,2,FALSE) -> 0 | E43: =+D43+C43 -> 0 | F43: 0 | G43: =+VLOOKUP(A43,ingresos!$A$1:$C$78,3,FALSE) -> 0 | H43: =+G43+F43 -> 0 | I43: =+IFERROR(H43*100/E43,0) -> 0
A44: 1-3-5-5-04 | B44: UPC Régimen Subsidiado Vigencias anteriores | C44: 0 | D44: =+VLOOKUP(A44,ingresos!$A$1:$C$78,2,FALSE) -> 0 | E44: =+D44+C44 -> 0 | F44: 1.521142e+11 | G44: =+VLOOKUP(A44,ingresos!$A$1:$C$78,3,FALSE) -> 5.7949606e+10 | H44: =+G44+F44 -> 2.100638e+11 | I44: =+IFERROR(H44*100/E44,0) -> 0
...

Sheet ingresos
A1: RUBRO | B1: MODIFICACIONES | C1: INGRESO MES
A2: 0-0-0-0 | B2: 0 | C2: 0
A3: 1-2-1-1 | B3: 0 | C3: 1099892790055
A4: 1-2-1-1-01 | B4: 0 | C4: 682579082032
A5: 1-2-1-1-02 | B5: 0 | C5: 417313708023
A6: 1-2-1-2 | B6: 0 | C6: 220071616000
A7: 1-2-1-3 | B7: 0 | C7: 100000000000
A8: 1-2-1-4 | B8: 0 | C8: 0
A9: 1-2-1-5 | B9: 0 | C9: 101451107500
A10: 1-2-1-5-01 | B10: 0 | C10: 0
A11: 1-2-1-5-02 | B11: 0 | C11: 101451107500
A12: 1-2-1-7 | B12: 0 | C12: 6087551728
A13: 1-2-1-8 | B13: 0 | C13: 905148526
... A78: 2-9-0-0-02 | B78: 0 | C78: 0

Sheet CUADRO 2-EJECUCION DE GASTOS
A3: ADMINISTRADORA DE LOS RECURSOS DEL SISTEMA GENERAL DE SEGURIDAD SOCIAL EN SALUD
A4: PRESUPUESTO DE GASTOS 2018
A5: UNIDAD DE RECURSOS ADMINISTRADOS - URA
A6: CUADRO No. 2
A9: CÓDIGO RUBRO | B9: CONCEPTO DEL RUBRO | C9: APROPIACIÓN DEFINITIVA | D9: EJECUCION PRESUPUESTAL ACUMULADA DESDE 01/01/2018 HASTA 31/03/2018 | G9: EJECUCION PRESUPUESTAL DESDE 01/04/2018 HASTA 30/04/2018 | J9: EJECUCION PRESUPUESTAL ACUMULADA DESDE 01/01/2018 HASTA 30/04/2018 | M9: %
D10: T. CDP | E10: T. RP | F10: T. PAGOS-OP | G10: CDP | H10: RP | I10: PAGOS-OP | J10: T. CDP | K10: T. RP | L10: T. PAGOS-OP | M10: RP | N10: OP
B11: URA
A12: A-3-0-0-0 | B12: TRANSFERENCIAS | C12: 42726949922000 | D12: 1.0884316e+13 | E12: 1.0741564e+13 | F12: 1.0741285e+13 | G12: =+G13+G18+G24 -> 4.0227721e+12 | H12: =+H13+H18+H24 -> 4.0321695e+12 | I12: =+I13+I18+I24 -> 4.0321695e+12 | J12: =+G12+D12 -> 1.4907088e+13 | K12: =+H12+E12 -> 1.4773734e+13 | L12: =+I12+F12 -> 1.4773454e+13 | M12: =+IFERROR(K12*100/C12,0) -> 34.577085 | N12: =+IFERROR(L12*100/C12,0) -> 34.576431
A13: A-3-2-0-0 | B13: TRANSFERENCIAS AL SECTOR PUBLICO | C13: 197288838698 | D13: 1.7451442e+11 | E13: 3.4082548e+10 | F13: 3.4082548e+10 | G13: =+G14+G16 -> 0 | H13: =+H14+H16 -> 9528984778 | I13: =+I14+I16 -> 9528984778 | J13: =+G13+D13 -> 1.7451442e+11 | K13: =+H13+E13 -> 4.3611533e+10 | L13: =+I13+F13 -> 4.3611533e+10 | M13: =+IFERROR(K13*100/C13,0) -> 22.105423 | N13: =+IFERROR(L13*100/C13,0) -> 22.105423
A14: A-3-2-1-0 | B14: Transferencias Entidades de Administración Pública Central | C14: 74955308000 | D14: 73566309756 | E14: 18391577439 | F14: 18391577439 | G14: =+G15 -> 0 | H14: =+H15 -> 6130525813 | I14: =+I15 -> 6130525813 | J14: =+G14+D14 -> 73566309756 | K14: =+H14+E14 -> 24522103252 | L14: =+I14+F14 -> 24522103252 | M14: =+IFERROR(K14*100/C14,0) -> 32.715633 | N14: =+IFERROR(L14*100/C14,0) -> 32.715633
A15: A-3-2-1-01 | B15: Contribución IVC Superintendencia Nacional de Salud | C15: 74955308000 | D15: 73566309756 | E15: 18391577439 | F15: 18391577439 | G15: =+VLOOKUP(A15,gasto!$A$4:$F$66,4,FALSE) -> 0 | H15: =+VLOOKUP(A15,gasto!$A$4:$F$66,5,FALSE) -> 6130525813 | I15: =+VLOOKUP(A15,gasto!$A$4:$F$66,6,FALSE) -> 6130525813 | J15: =+G15+D15 -> 73566309756 | K15: =+H15+E15 -> 24522103252 | L15: =+I15+F15 -> 24522103252 | M15: =+IFERROR(K15*100/C15,0) -> 32.715633 | N15: =+IFERROR(L15*100/C15,0) -> 32.715633
A16: A-3-2-2-0 | B16: Empresas Públicas Nacionales no financieras -ADRES | C16: 122333530698 | D16: 1.0094811e+11 | E16: 1.5690971e+10 | F16: 1.5690971e+10 | G16: =+G17 -> 0 | H16: =+H17 -> 3398458965 | I16: =+I17 -> 3398458965 | J16: =+G16+D16 -> 1.0094811e+11 | K16: =+H16+E16 -> 1.908943e+10 | L16: =+I16+F16 -> 1.908943e+10 | M16: =+IFERROR(K16*100/C16,0) -> 15.604414 | N16: =+IFERROR(L16*100/C16,0) -> 15.604414
A17: A-3-2-2-0-01 | B17: Aportes hasta del 0,5% recursos CSF para el desarrollo objeto ADRES | C17: 122333530698 | D17: 1.0094811e+11 | E17: 1.5690971e+10 | F17: 1.5690971e+10 | G17: =+VLOOKUP(A17,gasto!$A$4:$F$66,4,FALSE) -> 0 | H17: =+VLOOKUP(A17,gasto!$A$4:$F$66,5,FALSE) -> 3398458965 | I17: =+VLOOKUP(A17,gasto!$A$4:$F$66,6,FALSE) -> 3398458965 | J17: =+G17+D17 -> 1.0094811e+11 | K17: =+H17+E17 -> 1.908943e+10 | L17: =+I17+F17 -> 1.908943e+10 | M17: =+IFERROR(K17*100/C17,0) -> 15.604414 | N17: =+IFERROR(L17*100/C17,0) -> 15.604414
A18: A-3-6-0-0 | B18: OTRAS TRANSFERENCIAS | C18: 3000000000 | D18: 2.9675175e+09 | E18: 1.4416283e+09 | F18: 1.4416283e+09 | G18: =+G19+G22 -> -5.7058963e+08 | H18: =+H19+H22 -> 9.5329841e+08 | I18: =+I19+I22 -> 9.5329841e+08 | J18: =+G18+D18 -> 2.3969279e+09 | K18: =+H18+E18 -> 2.3949267e+09 | L18: =+I18+F18 -> 2.3949267e+09 | M18: =+IFERROR(K18*100/C18,0) -> 79.830889 | N18: =+IFERROR(L18*100/C18,0) -> 79.830889
A19: A-3-6-1-0 | B19: Sentencias y Conciliaciones URA | C19: 3000000000 | D19: 2.9675175e+09 | E19: 1.4416283e+09 | F19: 1.4416283e+09 | G19: =+SUM(G20:G21) -> -5.7058963e+08 | H19: =+SUM(H20:H21) -> 9.5329841e+08 | I19: =+SUM(I20:I21) -> 9.5329841e+08 | J19: =+G19+D19 -> 2.3969279e+09 | K19: =+H19+E19 -> 2.3949267e+09 | L19: =+I19+F19 -> 2.3949267e+09 | M19: =+IFERROR(K19*100/C19,0) -> 79.830889 | N19: =+IFERROR(L19*100/C19,0) -> 79.830889
A20: A-3-6-1-1 | B20: Sentencias URA | C20: 3000000000 | D20: 2.9675175e+09 | E20: 1.4416283e+09 | F20: 1.4416283e+09 | G20: =+VLOOKUP(A20,gasto!$A$4:$F$66,4,FALSE) -> -5.7058963e+08 | H20: =+VLOOKUP(A20,gasto!$A$4:$F$66,5,FALSE) -> 9.5329841e+08 | I20: =+VLOOKUP(A20,gasto!$A$4:$F$66,6,FALSE) -> 9.5329841e+08 | J20: =+G20+D20 -> 2.3969279e+09 | K20: =+H20+E20 -> 2.3949267e+09 | L20: =+I20+F20 -> 2.3949267e+09 | M20: =+IFERROR(K20*100/C20,0) -> 79.830889 | N20: =+IFERROR(L20*100/C20,0) -> 79.830889
A21: A-3-6-1-2 | B21: Conciliaciones URA | C21: 0 | D21: 0 | E21: 0 | F21: 0 | G21: =+VLOOKUP(A21,gasto!$A$4:$F$66,4,FALSE) -> 0 | H21: =+VLOOKUP(A21,gasto!$A$4:$F$66,5,FALSE) -> 0 | I21: =+VLOOKUP(A21,gasto!$A$4:$F$66,6,FALSE) -> 0 | J21: =+G21+D21 -> 0 | K21: =+H21+E21 -> 0 | L21: =+I21+F21 -> 0 | M21: =+IFERROR(K21*100/C21,0) -> 0 | N21: =+IFERROR(L21*100/C21,0) -> 0
A22: A-3-6-3-0 | B22: Destinatarios de otras transferencias Corrientes - Compensación Chance | C22: 0 | D22: 0 | E22: 0 | F22: 0 | G22: =+G23 -> 0 | H22: =+H23 -> 0 | I22: =+I23 -> 0 | J22: =+G22+D22 -> 0 | K22: =+H22+E22 -> 0 | L22: =+I22+F22 -> 0 | M22: =+IFERROR(K22*100/C22,0) -> 0 | N22: =+IFERROR(L22*100/C22,0) -> 0
A23: A-3-6-3-0-01 | B23: Otras transferencias - Compensación del Chance Decreto 2550/12 | C23: 0 | D23: 0 | E23: 0 | F23: 0 | G23: =+VLOOKUP(A23,gasto!$A$4:$F$66,4,FALSE) -> 0 | H23: =+VLOOKUP(A23,gasto!$A$4:$F$66,5,FALSE) -> 0 | I23: =+VLOOKUP(A23,gasto!$A$4:$F$66,6,FALSE) -> 0 | J23: =+G23+D23 -> 0 | K23: =+H23+E23 -> 0 | L23: =+I23+F23 -> 0 | M23: =+IFERROR(K23*100/C23,0) -> 0 | N23: =+IFERROR(L23*100/C23,0) -> 0
A24: A-3-9-0-0 | B24: ADMINISTRACIÓN DE RECURSOS DEL SGSSS | C24: 42526661083302 | D24: 1.0706834e+13 | E24: 1.070604e+13 | F24: 1.0705761e+13 | G24: =+G25+G30+G33+G36+G37+G38+G41+G44+G51+G55+G62+G70+G72+G74 -> 4.0233426e+12 | H24: =+H25+H30+H33+H36+H37+H38+H41+H44+H51+H55+H62+H70+H72+H74 -> 4.0216872e+12 | I24: =+I25+I30+I33+I36+I37+I38+I41+I44+I51+I55+I62+I70+I72+I74 -> 4.0216872e+12 | J24: =+G24+D24 -> 1.4730177e+13 | K24: =+H24+E24 -> 1.4727727e+13 | L24: =+I24+F24 -> 1.4727448e+13 | M24: =+IFERROR(K24*100/C24,0) -> 34.631751 | N24: =+IFERROR(L24*100/C24,0) -> 34.631094
A25: A-3-9-1-0 | B25: UPC Régimen Contributivo | C25: 20739780826500 | D25: 4940978828058 | E25: 4940978828058 | F25: 4940978828058 | G25: =+SUM(G26:G29) -> 1886494578012 | H25: =+SUM(H26:H29) -> 1884494578012 | I25: =+SUM(I26:I29) -> 1884494578012 | J25: =+G25+D25 -> 6827473406070 | K25: =+H25+E25 -> 6825473406070 | L25: =+I25+F25 -> 6825473406070 | M25: =+IFERROR(K25*100/C25,0) -> 32.910056 | N25: =+IFERROR(L25*100/C25,0) -> 32.910056
A26: A-3-9-1-0-01 | B26: UPC Régimen Contributivo SSF | C26: 12016226455000 | D26: 2642488107351 | E26: 2642488107351 | F26: 2642488107351 | G26: =+VLOOKUP(A26,gasto!$A$4:$F$66,4,FALSE) -> 985519768760 | H26: =+VLOOKUP(A26,gasto!$A$4:$F$66,5,FALSE) -> 985519768760 | I26: =+VLOOKUP(A26,gasto!$A$4:$F$66,6,FALSE) -> 985519768760 | J26: =+G26+D26 -> 3628007876111 | K26: =+H26+E26 -> 3628007876111 | L26: =+I26+F26 -> 3628007876111 | M26: =+IFERROR(K26*100/C26,0) -> 30.192572 | N26: =+IFERROR(L26*100/C26,0) -> 30.192572
A27: A-3-9-1-0-02 | B27: UPC Régimen Contributivo CSF | C27: 8636554371500 | D27: 2297473823349 | E27: 2297473823349 | F27: 2297473823349 | G27: =+VLOOKUP(A27,gasto!$A$4:$F$66,4,FALSE) -> 900704218739 | H27: =+VLOOKUP(A27,gasto!$A$4:$F$66,5,FALSE) -> 898704218739 | I27: =+VLOOKUP(A27,gasto!$A$4:$F$66,6,FALSE) -> 898704218739 | J27: =+G27+D27 -> 3198178042088 | K27: =+H27+E27 -> 3196178042088 | L27: =+I27+F27 -> 3196178042088 | M27: =+IFERROR(K27*100/C27,0) -> 37.00756 | N27: =+IFERROR(L27*100/C27,0) -> 37.00756
A28: A-3-9-1-0-03 | B28: Devolución aportes y cotizaciones no conciliadas vigencia anterior | C28: 80000000000 | D28: 1016897358 | E28: 1016897358 | F28: 1016897358 | G28: =+VLOOKUP(A28,gasto!$A$4:$F$66,4,FALSE) -> 270590513 | H28: =+VLOOKUP(A28,gasto!$A$4:$F$66,5,FALSE) -> 270590513 | I28: =+VLOOKUP(A28,gasto!$A$4:$F$66,6,FALSE) -> 270590513 | J28: =+G28+D28 -> 1287487871 | K28: =+H28+E28 -> 1287487871 | L28: =+I28+F28 -> 1287487871 | M28: =+IFERROR(K28*100/C28,0) -> 1.6093598 | N28: =+IFERROR(L28*100/C28,0) -> 1.6093598
A29: A-3-9-1-0-04 | B29: Rendimientos Financieros de los Saldos no Compensados de los Aportes Patronales según Art. 12 Decreto 1636 de 2016 | C29: 7000000000 | D29: 0 | E29: 0 | F29: 0 | G29: =+VLOOKUP(A29,gasto!$A$4:$F$66,4,FALSE) -> 0 | H29: =+VLOOKUP(A29,gasto!$A$4:$F$66,5,FALSE) -> 0 | I29: =+VLOOKUP(A29,gasto!$A$4:$F$66,6,FALSE) -> 0 | J29: =+G29+D29 -> 0 | K29: =+H29+E29 -> 0 | L29: =+I29+F29 -> 0 | M29: =+IFERROR(K29*100/C29,0) -> 0 | N29: =+IFERROR(L29*100/C29,0) -> 0
A30: A-3-9-2-0 | B30: Per capita Programas de Promoción y Prevención R.C | C30: 483767006000 | D30: 117943225238 | E30: 117943225238 | F30: 117943225238 | G30: =+SUM(G31:G32) -> 46037058132 | H30: =+SUM(H31:H32) -> 46037058132 | I30: =+SUM(I31:I32) -> 46037058132 | J30: =+G30+D30 -> 163980283370 | K30: =+H30+E30 -> 163980283370 | L30: =+I30+F30 -> 163980283370 | M30: =+IFERROR(K30*100/C30,0) -> 33.896541 | N30: =+IFERROR(L30*100/C30,0) -> 33.896541
A31: A-3-9-2-0-01 | B31: Per capita Programas de Promoción y Prevención R.C SSF | C31: 314169668000 | D31: 91836889458 | E31: 91836889458 | F31: 91836889458 | G31: =+VLOOKUP(A31,gasto!$A$4:$F$66,4,FALSE) -> 34019593940 | H31: =+VLOOKUP(A31,gasto!$A$4:$F$66,5,FALSE) -> 34019593940 | I31: =+VLOOKUP(A31,gasto!$A$4:$F$66,6,FALSE) -> 34019593940 | J31: =+G31+D31 -> 125856483398 | K31: =+H31+E31 -> 125856483398 | L31: =+I31+F31 -> 125856483398 | M31: =+IFERROR(K31*100/C31,0) -> 40.060036 | N31: =+IFERROR(L31*100/C31,0) -> 40.060036
A32: A-3-9-2-0-02 | B32: Per capita Programas de Promoción y Prevención R.C CSF | C32: 169597338000 | D32: 26106335780 | E32: 26106335780 | F32: 26106335780 | G32: =+VLOOKUP(A32,gasto!$A$4:$F$66,4,FALSE) -> 12017464192 | H32: =+VLOOKUP(A32,gasto!$A$4:$F$66,5,FALSE) -> 12017464192 | I32: =+VLOOKUP(A32,gasto!$A$4:$F$66,6,FALSE) -> 12017464192 | J32: =+G32+D32 -> 38123799972 | K32: =+H32+E32 -> 38123799972 | L32: =+I32+F32 -> 38123799972 | M32: =+IFERROR(K32*100/C32,0) -> 22.479008 | N32: =+IFERROR(L32*100/C32,0) -> 22.479008
A33: A-3-9-3-0 | B33: Incapacidades | C33: 799680177000 | D33: 207055092506 | E33: 207055092506 | F33: 207055092506 | G33: =+SUM(G34:G35) -> 76376825951 | H33: =+SUM(H34:H35) -> 76376825951 | I33: =+SUM(I34:I35) -> 76376825951 | J33: =+G33+D33 -> 283431918457 | K33: =+H33+E33 -> 283431918457 | L33: =+I33+F33 -> 283431918457 | M33: =+IFERROR(K33*100/C33,0) -> 35.443159 | N33: =+IFERROR(L33*100/C33,0) -> 35.443159
A34: A-3-9-3-0-01 | B34: Incapacidades SSF | C34: 695721754000 | D34: 150230937673 | E34: 150230937673 | F34: 150230937673 | G34: =+VLOOKUP(A34,gasto!$A$4:$F$66,4,FALSE) -> 56660571842 | H34: =+VLOOKUP(A34,gasto!$A$4:$F$66,5,FALSE) -> 56660571842 | I34: =+VLOOKUP(A34,gasto!$A$4:$F$66,6,FALSE) -> 56660571842 | J34: =+G34+D34 -> 206891509515 | K34: =+H34+E34 -> 206891509515 | L34: =+I34+F34 -> 206891509515 | M34: =+IFERROR(K34*100/C34,0) -> 29.73768 | N34: =+IFERROR(L34*100/C34,0) -> 29.73768
A35: A-3-9-3-0-02 | B35: Incapacidades CSF | C35: 103958423000 | D35: 56824154833 | E35: 56824154833 | F35: 56824154833 | G35: =+VLOOKUP(A35,gasto!$A$4:$F$66,4,FALSE) -> 19716254109 | H35: =+VLOOKUP(A35,gasto!$A$4:$F$66,5,FALSE) -> 19716254109 | I35: =+VLOOKUP(A35,gasto!$A$4:$F$66,6,FALSE) -> 19716254109 | J35: =+G35+D35 -> 76540408942 | K35: =+H35+E35 -> 76540408942 | L35: =+I35+F35 -> 76540408942 | M35: =+IFERROR(K35*100/C35,0) -> 73.625981 | N35: =+IFERROR(L35*100/C35,0) -> 73.625981
A36: A-3-9-4-0 | B36: Licencias de Maternidad y Paternidad | C36: 720776535000 | D36: 180521575326 | E36: 180521575326 | F36: 180521575326 | G36: =+VLOOKUP(A36,gasto!$A$4:$F$66,4,FALSE) -> 74790594108 | H36: =+VLOOKUP(A36,gasto!$A$4:$F$66,5,FALSE) -> 74790594108 | I36: =+VLOOKUP(A36,gasto!$A$4:$F$66,6,FALSE) -> 74790594108 | J36: =+G36+D36 -> 255312169434 | K36: =+H36+E36 -> 255312169434 | L36: =+I36+F36 -> 255312169434 | M36: =+IFERROR(K36*100/C36,0) -> 35.42182 | N36: =+IFERROR(L36*100/C36,0) -> 35.42182
A37: A-3-9-5-0 | B37: Prestaciones Económicas Regímenes Especial y de Excepción | C37: 1500000000 | D37: 1424453458 | E37: 630579025 | F37: 630579025 | G37: =+VLOOKUP(A37,gasto!$A$4:$F$66,4,FALSE) -> 53716025 | H37: =+VLOOKUP(A37,gasto!$A$4:$F$66,5,FALSE) -> 398252510 | I37: =+VLOOKUP(A37,gasto!$A$4:$F$66,6,FALSE) -> 398252510 | J37: =+G37+D37 -> 1478169483 | K37: =+H37+E37 -> 1028831535 | L37: =+I37+F37 -> 1028831535 | M37: =+IFERROR(K37*100/C37,0) -> 68.588769 | N37: =+IFERROR(L37*100/C37,0) -> 68.588769
A38: A-3-9-6-0 | B38: UPC Régimen Subsidiado | C38: 18322124359802 | D38: 4.6608054e+12 | E38: 4.6608054e+12 | F38: 4.6608054e+12 | G38: =+SUM(G39:G40) -> 1.6046882e+12 | H38: =+SUM(H39:H40) -> 1.6046882e+12 | I38: =+SUM(I39:I40) -> 1.6046882e+12 | J38: =+G38+D38 -> 6.2654936e+12 | K38: =+H38+E38 -> 6.2654936e+12 | L38: =+I38+F38 -> 6.2654936e+12 | M38: =+IFERROR(K38*100/C38,0) -> 34.196327 | N38: =+IFERROR(L38*100/C38,0) -> 34.196327
A39: A-3-9-6-0-01 | B39: UPC´S R.S. Cajas de Compensación Familiar SSF | C39: 26475329000 | D39: 6451366893 | E39: 6451366893 | F39: 6451366893 | G39: =+VLOOKUP(A39,gasto!$A$4:$F$66,4,FALSE) -> 2150455631 | H39: =+VLOOKUP(A39,gasto!$A$4:$F$66,5,FALSE) -> 2150455631 | I39: =+VLOOKUP(A39,gasto!$A$4:$F$66,6,FALSE) -> 2150455631 | J39: =+G39+D39 -> 8601822524 | K39: =+H39+E39 -> 8601822524 | L39: =+I39+F39 -> 8601822524 | M39: =+IFERROR(K39*100/C39,0) -> 32.489955 | N39: =+IFERROR(L39*100/C39,0) -> 32.489955
A40: A-3-9-6-0-02 | B40: UPC´S R.S. CSF | C40: 18295649030802 | D40: 4.6543541e+12 | E40: 4.6543541e+12 | F40: 4.6543541e+12 | G40: =+VLOOKUP(A40,gasto!$A$4:$F$66,4,FALSE) -> 1.6025378e+12 | H40: =+VLOOKUP(A40,gasto!$A$4:$F$66,5,FALSE) -> 1.6025378e+12 | I40: =+VLOOKUP(A40,gasto!$A$4:$F$66,6,FALSE) -> 1.6025378e+12 | J40: =+G40+D40 -> 6.2568918e+12 | K40: =+H40+E40 -> 6.2568918e+12 | L40: =+I40+F40 -> 6.2568918e+12 | M40: =+IFERROR(K40*100/C40,0) -> 34.198797 | N40: =+IFERROR(L40*100/C40,0) -> 34.198797
A41: A-3-9-7-0 | B41: Prestaciones Excepcionales - Recobros | C41: 1000000000000 | D41: 5.3399663e+11 | E41: 5.3399663e+11 | F41: 5.3399663e+11 | G41: =+SUM(G42:G43) -> 3.3096347e+11 | H41: =+SUM(H42:H43) -> 3.3096347e+11 | I41: =+SUM(I42:I43) -> 3.3096347e+11 | J41: =+G41+D41 -> 8.649601e+11 | K41: =+H41+E41 -> 8.649601e+11 | L41: =+I41+F41 -> 8.649601e+11 | M41: =+IFERROR(K41*100/C41,0) -> 86.49601 | N41: =+IFERROR(L41*100/C41,0) -> 86.49601
A42: A-3-9-7-0-01 | B42: Recobros - Reembolsos Régimen Contributivo | C42: 987504792000 | D42: 5.3087894e+11 | E42: 5.3087894e+11 | F42: 5.3087894e+11 | G42: =+VLOOKUP(A42,gasto!$A$4:$F$66,4,FALSE) -> 3.2958158e+11 | H42: =+VLOOKUP(A42,gasto!$A$4:$F$66,5,FALSE) -> 3.2958158e+11 | I42: =+VLOOKUP(A42,gasto!$A$4:$F$66,6,FALSE) -> 3.2958158e+11 | J42: =+G42+D42 -> 8.6046052e+11 | K42: =+H42+E42 -> 8.6046052e+11 | L42: =+I42+F42 -> 8.6046052e+11 | M42: =+IFERROR(K42*100/C42,0) -> 87.13482 | N42: =+IFERROR(L42*100/C42,0) -> 87.13482
A43: A-3-9-7-0-02 | B43: Recobros - Reembolsos Régimen Subsidiado - Tutelas | C43: 12495208000 | D43: 3.1176862e+09 | E43: 3.1176862e+09 | F43: 3.1176862e+09 | G43: =+VLOOKUP(A43,gasto!$A$4:$F$66,4,FALSE) -> 1.3818967e+09 | H43: =+VLOOKUP(A43,gasto!$A$4:$F$66,5,FALSE) -> 1.3818967e+09 | I43: =+VLOOKUP(A43,gasto!$A$4:$F$66,6,FALSE) -> 1.3818967e+09 | J43: =+G43+D43 -> 4.4995828e+09 | K43: =+H43+E43 -> 4.4995828e+09 | L43: =+I43+F43 -> 4.4995828e+09 | M43: =+IFERROR(K43*100/C43,0) -> 36.010468 | N43: =+IFERROR(L43*100/C43,0) -> 36.010468
A44: A-3-9-8-0 | B44: Atención en Salud, Transporte Primario, Indemnizaciones y Auxilio Funerario Víctimas | C44: 165927919000 | D44: 6.2241351e+10 | E44: 6.2241351e+10 | F44: 6.2241351e+10 | G44: =+SUM(G45:G50) -> 3.3287304e+09 | H44: =+SUM(H45:H50) -> 3.3287304e+09 | I44: =+SUM(I45:I50) -> 3.3287304e+09 | J44: =+G44+D44 -> 6.5570081e+10 | K44: =+H44+E44 -> 6.5570081e+10 | L44: =+I44+F44 -> 6.5570081e+10 | M44: =+IFERROR(K44*100/C44,0) -> 39.517208 | N44: =+IFERROR(L44*100/C44,0) -> 39.517208
...

Sheet gasto
A2: CÓDIGO RUBRO | B2: CONCEPTO DEL RUBRO | C2: APROPIACIÓN DEFINITIVA | D2: CDP | E2: RP | F2: PAGOS-OGAG | G2: T. CDP | H2: T. RP | I2: T. PAGOS-OGAG | J2: % | K2: RP
A3: URA
A4: A-3-2-1-0 | B4: Transferencias Entidades de Administración Pública Central | C4: 74955308000 | D4: 0 | E4: 6130525813 | F4: 6130525813 | G4: 73566309756 | H4: 24522103252 | I4: 24522103252 | J4: 32.72 | K4: 32.72
A5: A-3-2-1-01 | B5: Contribución IVC Superintendencia Nacional de Salud | C5: 74955308000 | D5: 0 | E5: 6130525813 | F5: 6130525813 | G5: 73566309756 | H5: 24522103252 | I5: 24522103252 | J5: 32.72 | K5: 32.72
A6: A-3-2-2-0 | B6: Empresas Públicas Nacionales no financieras -ADRES | C6: 122333530698 | D6: 0 | E6: 3398458965 | F6: 3398458965 | G6: 1.0094811e+11 | H6: 1.908943e+10 | I6: 1.908943e+10 | J6: 15.6 | K6: 15.6
A7: A-3-2-2-0-01 | B7: Aportes hasta del 0,5% recursos CSF para el desarrollo objeto ADRES | C7: 122333530698 | D7: 0 | E7: 3398458965 | F7: 3398458965 | G7: 1.0094811e+11 | H7: 1.908943e+10 | I7: 1.908943e+10 | J7: 15.6 | K7: 15.6
A8: A-3-6-1-0 | B8: Sentencias y Conciliaciones URA | C8: 3000000000 | D8: -5.7058963e+08 | E8: 9.5329841e+08 | F8: 9.5329841e+08 | G8: 2.3969279e+09 | H8: 2.3949267e+09 | I8: 2.3949267e+09 | J8: 79.83 | K8: 79.83
A9: A-3-6-1-1 | B9: Sentencias URA | C9: 3000000000 | D9: -5.7058963e+08 | E9: 9.5329841e+08 | F9: 9.5329841e+08 | G9: 2.3969279e+09 | H9: 2.3949267e+09 | I9: 2.3949267e+09 | J9: 79.83 | K9: 79.83
A10: A-3-6-1-2 | B10: Conciliaciones URA | C10: 0 | D10: 0 | E10: 0 | F10: 0 | G10: 0 | H10: 0 | I10: 0 | J10: 0 | K10: 0
A11: A-3-6-3-0 | B11: Destinatarios de otras transferencias Corrientes - Compensación Chance | C11: 0 | D11: 0 | E11: 0 | F11: 0 | G11: 0 | H11: 0 | I11: 0 | J11: 0 | K11: 0
A12: A-3-6-3-0-01 | B12: Otras transferencias - Compensación del Chance Decreto 2550/12 | C12: 0 | D12: 0 | E12: 0 | F12: 0 | G12: 0 | H12: 0 | I12: 0 | J12: 0 | K12: 0
A13: A-3-9-1-0 | B13: UPC Régimen Contributivo | C13: 20739780826500 | D13: 1886494578012 | E13: 1884494578012 | F13: 1884494578012 | G13: 6827473406070 | H13: 6825473406070 | I13: 6825473406070 | J13: 32.91 | K13: 32.91
A14: A-3-9-1-0-01 | B14: UPC Régimen Contributivo SSF | C14: 12016226455000 | D14: 985519768760 | E14: 985519768760 | F14: 985519768760 | G14: 3628007876111 | H14: 3628007876111 | I14: 3628007876111 | J14: 30.19 | K14: 30.19
A15: A-3-9-1-0-02 | B15: UPC Régimen Contributivo CSF | C15: 8636554371500 | D15: 900704218739 | E15: 898704218739 | F15: 898704218739 | G15: 3198178042088 | H15: 3196178042088 | I15: 3196178042088 | J15: 37.01 | K15: 37.01
... A66: A-9-9-9-9 | B66: Disponibilidad Final | C66: 0 | D66: 0 | E66: 0 | F66: 0 | G66: 0 | H66: 0 | I66: 0 | J66: 0 | K66: 0

Sheet Hoja1
A3: ADMINISTRADORA DE LOS RECURSOS DEL SISTEMA GENERAL DE SEGURIDAD SOCIAL EN SALUD
A4: PRESUPUESTO DE INGRESOS 2017
A5: UNIDAD DE RECURSOS ADMINISTRADOS - URA
A6: CUADRO No. 1
A8: 1 | B8: 2 | C8: 3 | D8: 4 | E8: 5 | F8: 6 | G8: 7 | H8: 8 | I8: 9 | J8: 10
A9: CÓDIGO RUBRO | B9: CONCEPTO DEL RUBRO | C9: AFORO INICIAL | D9: MODIFICACIÓN PRESUPUESTAL | E9: AFORO DEFINITIVO | F9: Ingresos Acumulados Desde 01/08/2017 hasta 30/11/2017 | G9: Ingresos Desde 01/12/2017 hasta 31/12/2017 | H9: Ingresos Acumulados Desde 01/08/2017 hasta 31/12/2017 | I9: EJECUCIÓN ACUMULADA (%) | J9: PARTICIPACIÓN %
A10: URA
A11: 0-0-0-0 | B11: DISPONIBILIDAD INICIAL | C11: 1049732777065 | D11: 1028793184133 | E11: 2078525961198 | F11: 3.7980893e+11 | G11: 1.698717e+12 | H11: 2.078526e+12 | I11: 100 | J11: 11.173515
A12: 1-2-1-1 | B12: Aportes de la Nación para el Aseguramiento en Salud | C12: 800000000000 | D12: 0 | E12: 800000000000 | F12: 800000000000 | G12: 0 | H12: 800000000000 | I12: 100 | J12: 4.3005534
A13: 1-2-1-1-01 | B13: Aportes de la Nación para el Aseguramiento en Salud Cierre | C13: 800000000000 | D13: 0 | E13: 800000000000 | F13: 800000000000 | G13: 0 | H13: 800000000000 | I13: 100 | J13: 4.3005534
A14: 1-2-1-2 | B14: Compensación Regalías para el Régimen Subsidiado | C14: 0 | D14: 0 | E14: 0 | F14: 0 | G14: 0 | H14: 0 | I14: 0 | J14: 0
A15: 1-2-1-3 | B15: Impuesto sobre la renta para la equidad CREE | C15: 3379423220743 | D15: 0 | E15: 3379423220743 | F15: 2645477901368 | G15: 661369475338 | H15: 3306847376706 | I15: 97.852419 | J15: 17.776592
A16: 1-2-1-4 | B16: SGP FONSAET | C16: 76906712050 | D16: 0 | E16: 76906712050 | F16: 76906712050 | G16: 0 | H16: 76906712050 | I16: 100 | J16: 0.41342677
A17: 1-2-1-5 | B17: PRIMA FONSAT Y CONTRIBUCION SOAT | C17: 630863569234 | D17: 0 | E17: 630863569234 | F17: 4.9668302e+11 | G17: 93551929250 | H17: 5.9023495e+11 | I17: 93.55984 | J17: 3.1729211
A18: 1-2-1-5-01 | B18: % Prima (FONSAT) Decreto Ley 1335 de 2009 | C18: 153176997329 | D18: 0 | E18: 153176997329 | F18: 1.0986192e+11 | G18: 0 | H18: 1.0986192e+11 | I18: 71.722205 | J18: 0.59058382
A19: 1-2-1-5-02 | B19: Contribución Seguro Obligatorio de Accidentes de Tránsito - SOAT- Decreto Ley 1335 de 2009 | C19: 477686571905 | D19: 0 | E19: 477686571905 | F19: 386821096950 | G19: 93551929250 | H19: 480373026200 | I19: 100.56239 | J19: 2.5823373
A20: 1-2-1-7 | B20: Impuesto social a las municiones y explosivos | C20: 31868595127 | D20: 0 | E20: 31868595127 | F20: 31727550335 | G20: 7899641418 | H20: 39627191753 | I20: 124.34559 | J20: 0.21302357
A21: 1-2-1-8 | B21: Impuesto social a las armas | C21: 3612249620 | D21: 0 | E21: 3612249620 | F21: 3452971135 | G21: 969138385 | H21: 4422109520 | I21: 122.41982 | J21: 0.023771897
A22: 1-2-9-0 | B22: Otros aportes e impuestos de la nación | C22: 0 | D22: 0 | E22: 0 | F22: 0 | G22: 0 | H22: 0 | I22: 0 | J22: 0
... A86: 2-9-1-0-06 | B86: Regalías – artículo 5 Ley 1797 de 2016 | C86: 5000000000 | D86: 0 | E86: 5000000000 | F86: 0 | G86: 0 | H86: 0 | I86: 0 | J86: 0
B88: TOTAL | C88: 16692931290975 | D88: 1405041818640 | E88: 18097973109615 | F88: 1.3761589e+13 | G88: 4.8406684e+12 | H88: 1.8602257e+13 | I88: 102.78641 | J88: 100
C90: 16692931290975 | D90: 1405041818640 | E90: 18097973109615 | F90: 1.3761589e+13 | G90: 4.8406684e+12 | H90: 1.8602257e+13 | I90: 102.78641
C91: =+C90-C88 -> 0 | D91: =+D90-D88 -> 0 | E91: =+E90-E88 -> 0 | F91: =+F90-F88 -> 0 | G91: =+G90-G88 -> 0 | H91: =+H90-H88 -> 0 | I91: =+I90-I88 -> 0

Sheet Hoja2
A3: ADMINISTRADORA DE LOS RECURSOS DEL SISTEMA GENERAL DE SEGURIDAD SOCIAL EN SALUD
A4: PRESUPUESTO DE GASTOS 2017
A5: UNIDAD DE RECURSOS ADMINISTRADOS - URA
A6: CUADRO No. 2
A8: 1 | B8: 2 | C8: 3 | D8: 4 | E8: 5 | F8: 6 | G8: 7 | H8: 8 | I8: 9 | J8: 10 | K8: 11 | L8: 12 | M8: 13 | N8: 14
A9: CÓDIGO RUBRO | B9: CONCEPTO DEL RUBRO | C9: APROPIACIÓN DEFINITIVA | D9: EJECUCIÓN PRESUPUESTAL ACUMULADA DESDE 01/08/2017 HASTA 30/11/2017 | G9: EJECUCIÓN PRESUPUESTAL 01/12/2017 HASTA 31/12/2017 | J9: EJECUCIÓN PRESUPUESTAL ACUMULADA DESDE 01/08/2017 HASTA 31/12/2017 | M9: % | O9: SALDO APROPIACIÓN | P9: COMPROMISOS POR PAGAR | Q9: %
D10: T. CDP | E10: T. RP | F10: T. PAGOS-OP | G10: CDP | H10: RP | I10: OP | J10: T. CDP | K10: T. RP | L10: T. PAGOS-OP | M10: RP | N10: OP | Q10: PARTICIPACIÓN
B11: URA
A12: A-9-9-9-9 | B12: Disponibilidad Final | C12: 169607386609 | D12: 0 | E12: 0 | F12: 0 | G12: 0 | H12: 0 | I12: 0 | J12: 0 | K12: 0 | L12: 0 | M12: 0 | N12: 0 | O12: 169607386609 | P12: 0 | Q12: 0
A13: A-3-2-1-0 | B13: Transferencias Entidades de Administración Pública Central | C13: 40479356618 | D13: 22483398888 | E13: 22483398888 | F13: 22483398888 | G13: 5620849724 | H13: 5620849724 | I13: 5620849724 | J13: 28104248612 | K13: 28104248612 | L13: 28104248612 | M13: 69.428595 | N13: 69.428595 | O13: 12375108006 | P13: 0 | Q13: 0.15813624
A14: A-3-2-1-0-01 | B14: Contribución IVC Superintendencia Nacional de Salud | C14: 40479356618 | D14: 22483398888 | E14: 22483398888 | F14: 22483398888 | G14: 5620849724 | H14: 5620849724 | I14: 5620849724 | J14: 28104248612 | K14: 28104248612 | L14: 28104248612 | M14: 69.428595 | N14: 69.428595 | O14: 12375108006 | P14: 0 | Q14: 0.15813624
A15: A-3-2-2-0 | B15: Empresas Públicas Nacionales no financieras | C15: 54432463826 | D15: 54432463826 | E15: 6219861165 | F15: 6219861165 | G15: -1.737463e+10 | H15: 3.0837973e+10 | I15: 9100000000 | J15: 3.7057834e+10 | K15: 3.7057834e+10 | L15: 15319861165 | M15: 68.08039 | N15: 28.144714 | O15: 1.737463e+10 | P15: 2.1737973e+10 | Q15: 0.086201391
A16: A-3-2-2-0-01 | B16: Aportes hasta del 0,5% recursos CSF para el desarrollo objeto ADRES | C16: 54432463826 | D16: 54432463826 | E16: 6219861165 | F16: 6219861165 | G16: -1.737463e+10 | H16: 3.0837973e+10 | I16: 9100000000 | J16: 3.7057834e+10 | K16: 3.7057834e+10 | L16: 15319861165 | M16: 68.08039 | N16: 28.144714 | O16: 1.737463e+10 | P16: 2.1737973e+10 | Q16: 0.086201391
A17: A-3-6-1-0 | B17: Sentencias y Conciliaciones URA | C17: 5059377749 | D17: 1.2391943e+08 | E17: 0 | F17: 0 | G17: 2.2315349e+09 | H17: 2.3554543e+09 | I17: 2.331944e+09 | J17: 2.3554543e+09 | K17: 2.3554543e+09 | L17: 2.331944e+09 | M17: 46.556205 | N17: 46.091518 | O17: 2.7039235e+09 | P17: 23510302 | Q17: 0.013121321
A18: A-3-6-1-1 | B18: Sentencias URA | C18: 5059377749 | D18: 1.2391943e+08 | E18: 0 | F18: 0 | G18: 2.2315349e+09 | H18: 2.3554543e+09 | I18: 2.331944e+09 | J18: 2.3554543e+09 | K18: 2.3554543e+09 | L18: 2.331944e+09 | M18: 46.556205 | N18: 46.091518 | O18: 2.7039235e+09 | P18: 23510302 | Q18: 0.013121321
A19: A-3-6-1-2 | B19: Conciliaciones URA | C19: 0 | D19: 0 | E19: 0 | F19: 0 | G19: 0 | H19: 0 | I19: 0 | J19: 0 | K19: 0 | L19: 0 | M19: 0 | N19: 0 | O19: 0 | P19: 0 | Q19: 0
A20: A-3-6-3-0 | B20: Destinatarios de otras transferencias Corrientes | C20: 30652000000 | D20: 0 | E20: 0 | F20: 0 | G20: 30652000000 | H20: 30652000000 | I20: 30652000000 | J20: 30652000000 | K20: 30652000000 | L20: 30652000000 | M20: 100 | N20: 100 | O20: 0 | P20: 0 | Q20: 0.17247187
A21: A-3-6-3-0-01 | B21: Otras trasnferencias - Compensación del Chance Decreto 2550/12 | C21: 30652000000 | D21: 0 | E21: 0 | F21: 0 | G21: 30652000000 | H21: 30652000000 | I21: 30652000000 | J21: 30652000000 | K21: 30652000000 | L21: 30652000000 | M21: 100 | N21: 100 | O21: 0 | P21: 0 | Q21: 0.17247187
A22: A-3-9-1-0 | B22: UPC Régimen Contributivo | C22: 8076746600070 | D22: 6430211471821 | E22: 6430211471821 | F22: 6424483625438 | G22: 1646200098083 | H22: 1646200098083 | I22: 1651927944466 | J22: 8076411569904 | K22: 8076411569904 | L22: 8076411569904 | M22: 99.995852 | N22: 99.995852 | O22: 335030166 | P22: 0 | Q22: 45.44414
A23: A-3-9-1-0-01 | B23: UPC Régimen Contributivo SSF | C23: 4576838798468 | D23: 3638853998008 | E23: 3638853998008 | F23: 3636391786062 | G23: 937983462711 | H23: 937983462711 | I23: 940445674657 | J23: 4576837460719 | K23: 4576837460719 | L23: 4576837460719 | M23: 99.999971 | N23: 99.999971 | O23: 1337749 | P23: 0 | Q23: 25.752828
... A74: TOTAL | B74: TOTAL | C74: 18097973109615 | D74: 1.3816938e+13 | E74: 1.3767785e+13 | F74: 1.3761589e+13 | G74: 3.9977088e+12 | H74: 4.0468615e+12 | I74: 4.0105851e+12 | J74: 1.7814647e+13 | K74: 1.7814647e+13 | L74: 1.7772174e+13 | M74: 98.434486 | N74: 98.199803 | O74: 2.8332622e+11 | P74: 4.2472859e+10 | Q74: 100
C76: 16692931290975 | D76: 1.3816938e+13 | E76: 1.3816938e+13 | F76: 1.3816938e+13 | G76: 3.9977088e+12 | H76: 4.0468615e+12 | I76: 4.0105851e+12 | J76: 1.3816938e+13 | K76: 1.3816938e+13 | L76: 1.3816938e+13 | M76: 82.771191 | N76: 82.771191
C77: =+C76-C74 -> -1405041818640 | D77: =+D76-D74 -> 0 | E77: =+E76-E74 -> 4.9152731e+10 | F77: =+F76-F74 -> 5.5349216e+10 | G77: =+G76-G74 -> 0 | H77: =+H76-H74 -> 0 | I77: =+I76-I74 -> 0 | J77: =+J76-J74 -> -3.9977088e+12 | ... N77: =+N76-N74 -> -15.428612
